<?xml version="1.0" ?>
<!-- =================================================================================== -->
<!-- |    This document was autogenerated by xacro from atlas_v5_convex_hull_open_hands.xacro | -->
<!-- |    EDITING THIS FILE BY HAND IS NOT RECOMMENDED                                 | -->
<!-- =================================================================================== -->
<robot name="hopper" xmlns:xacro="http://www.ros.org/wiki/xacro">

  <link name="base">
		<inertial>
			<origin rpy="0.00000 -0.00000 0.00000" xyz="0.00000 0.00000 0.00000"/>
			<mass value="1.00000"/>
			<inertia ixx="1.00000" ixy="0" ixz="0" iyy="1.00000" iyz="0" izz="1.00000"/>
		</inertial>
	</link>
	<link name="torso">
		<inertial>
			<origin rpy="0.00000 -0.00000 0.00000" xyz="0.00000 0.00000 0.00000"/>
			<mass value="6.36031"/>
			<inertia ixx="0.08944" ixy="0" ixz="0" iyy="0.8835" iyz="0" izz="1.0176"/>
		</inertial>
		<collision>
			<origin rpy="0.00000 1.57080 -0.00000" xyz="0.00000 0.00000 0.00000"/>
			<geometry>
				<capsule length="1.00000" radius="0.04600"/>
			</geometry>
		</collision>
		<collision>
			<origin rpy="0.00000 0.87000 0.00000" xyz="0.60000 0.00000 0.10000"/>
			<geometry>
				<capsule length="0.30000" radius="0.04600"/>
			</geometry>
		</collision>
    <visual>
      <origin rpy="0.00000 1.57080 -0.00000" xyz="0.00000 0.00000 0.00000"/>
      <geometry>
        <capsule length="1.00000" radius="0.04600"/>
      </geometry>
    </visual>
    <visual>
      <origin rpy="0.00000 0.87000 0.00000" xyz="0.60000 0.00000 0.10000"/>
      <geometry>
        <capsule length="0.30000" radius="0.04600"/>
      </geometry>
    </visual>
	</link>
	<link name="bthigh">
		<inertial>
			<origin rpy="0.00000 -0.00000 0.00000" xyz="0.00000 0.00000 -0.14500"/>
			<mass value="1.5352"/>
			<inertia ixx="0.01525" ixy="0" ixz="0" iyy="0.01525" iyz="0" izz="0.001624"/>
		</inertial>
		<collision>
			<origin rpy="3.14159 0.65841 3.14159" xyz="0.10000 0.00000 -0.13000"/>
			<geometry>
				<capsule length="0.29000" radius="0.04600"/>
			</geometry>
		</collision>
    <visual>
      <origin rpy="0.00000 0.0000 0.00000" xyz="0.00000 0.00000 -0.14500"/>
      <geometry>
        <capsule length="0.29000" radius="0.04600"/>
      </geometry>
    </visual>
	</link>
	<link name="bshin">
		<inertial>
			<origin rpy="0.00000 -0.00000 0.00000" xyz="0.00000 0.00000 -0.14500"/>
			<mass value="1.5809"/>
			<inertia ixx="0.01660" ixy="0" ixz="0" iyy="0.01660" iyz="0" izz="0.00167"/>
		</inertial>
		<collision>
			<origin rpy="3.14159 -1.11159 3.14159" xyz="-0.14000 0.00000 -0.07000"/>
			<geometry>
				<capsule length="0.30000" radius="0.04600"/>
			</geometry>
		</collision>
    <visual>
      <origin rpy="0.0000 0.0000 0.0000" xyz="-0.000 0.00000 -0.14500"/>
      <geometry>
        <capsule length="0.29000" radius="0.04600"/>
      </geometry>
    </visual>
	</link>
	<link name="bfoot">
		<inertial>
			<origin rpy="0.00000 -0.00000 0.00000" xyz="0.00000 0.00000 -0.09400"/>
			<mass value="1.069"/>
			<inertia ixx="0.005444" ixy="0" ixz="0" iyy="0.005444" iyz="0" izz="0.001131"/>
		</inertial>
		<collision>
			<origin rpy="0.00000 0.00000 0.00000" xyz="0.00000 0.00000 -0.09400"/>
			<geometry>
				<capsule length="0.18800" radius="0.04600"/>
			</geometry>
		</collision>
    <visual>
      <origin rpy="0.00000 0.00000 0.00000" xyz="0.00000 0.00000 -0.09400"/>
      <geometry>
        <capsule length="0.18800" radius="0.04600"/>
      </geometry>
    </visual>
	</link>

	<joint name="floating_joint" type="planaraxis">
		<parent link="base"/>
		<child link="torso"/>
		<origin rpy="0.00000 -0.00000 0.00000" xyz="0.00000 0.00000 0.00000"/>
		<axis xyz="0.00000 1.00000 0.00000"/>
	</joint>
	<joint name="bthigh" type="revolute">
		<parent link="torso"/>
		<child link="bthigh"/>
		<dynamics damping="1.0" friction="0.0001"/>
		<!-- <origin rpy="0.00000 -0.00 0.00000" xyz="-0.50000 0.00000 0.00000"/> -->
		<origin rpy="0.00000 -0.65800 0.00000" xyz="-0.50000 0.00000 0.00000"/>
		<axis xyz="0.00000 1.00000 0.00000"/>
	</joint>
	<joint name="bshin" type="revolute">
		<parent link="bthigh"/>
		<child link="bshin"/>
		<dynamics damping="1.0" friction="0.0001"/>
		<!-- <origin rpy="0.00000 0.0 0.00000" xyz="0.0000 0.00000 -0.29000"/> -->
		<origin rpy="0.00000 1.7 0.00000" xyz="0.0000 0.00000 -0.29000"/>
		<axis xyz="0.00000 1.00000 0.00000"/>
	</joint>
	<joint name="bfoot" type="revolute">
		<parent link="bshin"/>
		<child link="bfoot"/>
		<dynamics damping="1.0" friction="0.0001"/>
		<!-- <origin rpy="0.00000 0.000 0.00000" xyz="-0.00000 0.00000 -0.29000"/> -->
		<origin rpy="0.00000 -1.5 0.00000" xyz="-0.00000 0.00000 -0.29000"/>
		<axis xyz="0.00000 1.00000 0.00000"/>
	</joint>

</robot>
