<?xml version="1.0" ?>
<!-- =================================================================================== -->
<!-- |    This document was autogenerated by xacro from atlas_v5_convex_hull_open_hands.xacro | -->
<!-- |    EDITING THIS FILE BY HAND IS NOT RECOMMENDED                                 | -->
<!-- =================================================================================== -->
<robot name="atlas" xmlns:xacro="http://www.ros.org/wiki/xacro">
	<link name="torso">
		<inertial>
			<origin rpy="0.00000 -0.00000 0.00000" xyz="-0.01000 0.00000 -0.12000"/>
			<mass value="8.90746"/>
			<inertia ixx="0.21526" ixy="0" ixz="0" iyy="0.18112" iyz="0" izz="0.08225"/>
		</inertial>
		<collision>
			<origin rpy="-1.57080 0.00000 0.00000" xyz="0.00000 0.00000 0.00000"/>
			<geometry>
				<capsule length="0.14000" radius="0.07000"/>
			</geometry>
		</collision>
		<collision>
			<origin rpy="0.00000 -0.00000 0.00000" xyz="0.00000 0.00000 0.19000"/>
			<geometry>
				<sphere radius="0.09000"/>
			</geometry>
		</collision>
		<collision>
			<origin rpy="-1.57080 0.00000 0.00000" xyz="-0.01000 0.00000 -0.12000"/>
			<geometry>
				<capsule length="0.12000" radius="0.06000"/>
			</geometry>
		</collision>
		<visual>
			<origin rpy="-1.57080 0.00000 0.00000" xyz="0.00000 0.00000 0.00000"/>
			<geometry>
				<capsule length="0.14000" radius="0.07000"/>
			</geometry>
		</visual>
		<visual>
			<origin rpy="0.00000 -0.00000 0.00000" xyz="0.00000 0.00000 0.19000"/>
			<geometry>
				<sphere radius="0.09000"/>
			</geometry>
		</visual>
		<visual>
			<origin rpy="-1.57080 0.00000 0.00000" xyz="-0.01000 0.00000 -0.12000"/>
			<geometry>
				<capsule length="0.12000" radius="0.06000"/>
			</geometry>
		</visual>
	</link>
	<link name="lwaist">
		<inertial>
			<origin rpy="0.00000 -0.00000 0.00000" xyz="0.00000 0.00000 0.00000"/>
			<mass value="2.26195"/>
			<inertia ixx="0.01357" ixy="0" ixz="0" iyy="0.00543" iyz="0" izz="0.01357"/>
		</inertial>
		<collision>
			<origin rpy="-1.57080 0.00000 0.00000" xyz="0.00000 0.00000 0.00000"/>
			<geometry>
				<capsule length="0.12000" radius="0.06000"/>
			</geometry>
		</collision>
		<visual>
			<origin rpy="-1.57080 0.00000 0.00000" xyz="0.00000 0.00000 0.00000"/>
			<geometry>
				<capsule length="0.12000" radius="0.06000"/>
			</geometry>
		</visual>
	</link>
	<link name="pelvis">
		<inertial>
			<origin rpy="0.00000 -0.00000 0.00000" xyz="-0.02000 0.00000 0.00000"/>
			<mass value="6.61619"/>
			<inertia ixx="0.07432" ixy="0" ixz="0" iyy="0.03573" iyz="0" izz="0.07432"/>
		</inertial>
		<collision>
			<origin rpy="-1.57080 0.00000 0.00000" xyz="-0.02000 0.00000 0.00000"/>
			<geometry>
				<capsule length="0.14000" radius="0.09000"/>
			</geometry>
		</collision>
		<visual>
			<origin rpy="-1.57080 0.00000 0.00000" xyz="-0.02000 0.00000 0.00000"/>
			<geometry>
				<capsule length="0.14000" radius="0.09000"/>
			</geometry>
		</visual>
	</link>

	<link name="right_thigh">
		<inertial>
			<origin rpy="0.00000 -0.00000 0.00000" xyz="0.00000 0.00500 -0.17000"/>
			<mass value="4.75175"/>
			<inertia ixx="0.09212" ixy="0" ixz="0" iyy="0.09076" iyz="0" izz="0.01276"/>
		</inertial>
		<collision>
			<origin rpy="-3.11219 -0.00000 0.00000" xyz="0.00000 0.00500 -0.17000"/>
			<geometry>
				<capsule length="0.34015" radius="0.06000"/>
			</geometry>
		</collision>
		<visual>
			<origin rpy="-3.11219 -0.00000 0.00000" xyz="0.00000 0.00500 -0.17000"/>
			<geometry>
				<capsule length="0.34015" radius="0.06000"/>
			</geometry>
		</visual>
	</link>
	<link name="right_shin">
		<inertial>
			<origin rpy="0.00000 -0.00000 0.00000" xyz="0.00000 0.00000 -0.15000"/>
			<mass value="2.75570"/>
			<inertia ixx="0.03858" ixy="0" ixz="0" iyy="0.03858" iyz="0" izz="0.00441"/>
		</inertial>
		<collision>
			<origin rpy="3.14159 -0.00000 3.14159" xyz="0.00000 0.00000 -0.15000"/>
			<geometry>
				<capsule length="0.30000" radius="0.04900"/>
			</geometry>
		</collision>
		<visual>
			<origin rpy="3.14159 -0.00000 3.14159" xyz="0.00000 0.00000 -0.15000"/>
			<geometry>
				<capsule length="0.30000" radius="0.04900"/>
			</geometry>
		</visual>
	</link>
	<link name="right_foot">
		<inertial>
			<origin rpy="0.00000 -0.00000 0.00000" xyz="0.03500 0.01000 0.00000"/>
			<mass value="1.13114"/>
			<inertia ixx="0.00177" ixy="0" ixz="0" iyy="0.00716" iyz="0" izz="0.00828"/>
		</inertial>
		<collision>
			<origin rpy="1.57080 1.47585 1.47585" xyz="0.03500 -0.03000 0.00000"/>
			<geometry>
				<capsule length="0.21095" radius="0.02700"/>
			</geometry>
		</collision>
		<collision>
			<origin rpy="-1.57080 1.47585 -1.47585" xyz="0.03500 0.01000 0.00000"/>
			<geometry>
				<capsule length="0.21095" radius="0.02700"/>
			</geometry>
		</collision>
		<visual>
			<origin rpy="1.57080 1.47585 1.47585" xyz="0.03500 -0.03000 0.00000"/>
			<geometry>
				<capsule length="0.21095" radius="0.02700"/>
			</geometry>
		</visual>
		<visual>
			<origin rpy="-1.57080 1.47585 -1.47585" xyz="0.03500 0.01000 0.00000"/>
			<geometry>
				<capsule length="0.21095" radius="0.02700"/>
			</geometry>
		</visual>
	</link>

	<link name="left_thigh">
		<inertial>
			<origin rpy="0.00000 -0.00000 0.00000" xyz="0.00000 -0.00500 -0.17000"/>
			<mass value="4.75175"/>
			<inertia ixx="0.09212" ixy="0" ixz="0" iyy="0.09076" iyz="0" izz="0.01276"/>
		</inertial>
		<collision>
			<origin rpy="3.11219 -0.00000 0.00000" xyz="0.00000 -0.00500 -0.17000"/>
			<geometry>
				<capsule length="0.34015" radius="0.06000"/>
			</geometry>
		</collision>
		<visual>
			<origin rpy="3.11219 -0.00000 0.00000" xyz="0.00000 -0.00500 -0.17000"/>
			<geometry>
				<capsule length="0.34015" radius="0.06000"/>
			</geometry>
		</visual>
	</link>
	<link name="left_shin">
		<inertial>
			<origin rpy="0.00000 -0.00000 0.00000" xyz="0.00000 0.00000 -0.15000"/>
			<mass value="2.75570"/>
			<inertia ixx="0.03858" ixy="0" ixz="0" iyy="0.03858" iyz="0" izz="0.00441"/>
		</inertial>
		<collision>
			<origin rpy="3.14159 -0.00000 3.14159" xyz="0.00000 0.00000 -0.15000"/>
			<geometry>
				<capsule length="0.30000" radius="0.04900"/>
			</geometry>
		</collision>
		<visual>
			<origin rpy="3.14159 -0.00000 3.14159" xyz="0.00000 0.00000 -0.15000"/>
			<geometry>
				<capsule length="0.30000" radius="0.04900"/>
			</geometry>
		</visual>
	</link>
	<link name="left_foot">
		<inertial>
			<origin rpy="0.00000 -0.00000 0.00000" xyz="0.03500 -0.01000 0.00000"/>
			<mass value="1.13114"/>
			<inertia ixx="0.00177" ixy="0" ixz="0" iyy="0.00716" iyz="0" izz="0.00828"/>
		</inertial>
		<collision>
			<origin rpy="-1.57080 1.47585 -1.47585" xyz="0.03500 0.03000 0.00000"/>
			<geometry>
				<capsule length="0.21095" radius="0.02700"/>
			</geometry>
		</collision>
		<collision>
			<origin rpy="1.57080 1.47585 1.47585" xyz="0.03500 -0.01000 0.00000"/>
			<geometry>
				<capsule length="0.21095" radius="0.02700"/>
			</geometry>
		</collision>
		<visual>
			<origin rpy="-1.57080 1.47585 -1.47585" xyz="0.03500 0.03000 0.00000"/>
			<geometry>
				<capsule length="0.21095" radius="0.02700"/>
				<!-- <capsule length="0.000005" radius="0.02700"/> -->
			</geometry>
		</visual>
		<visual>
			<origin rpy="1.57080 1.47585 1.47585" xyz="0.03500 -0.01000 0.00000"/>
			<geometry>
				<capsule length="0.21095" radius="0.02700"/>
				<!-- <capsule length="0.000005" radius="0.02700"/> -->
			</geometry>
		</visual>
	</link>

	<link name="right_upper_arm">
		<inertial>
			<origin rpy="0.00000 -0.00000 0.00000" xyz="0.08000 -0.08000 -0.08000"/>
			<mass value="1.66108"/>
			<inertia ixx="0.02368" ixy="0" ixz="0" iyy="0.02368" iyz="0" izz="0.02267"/>
		</inertial>
		<collision>
			<origin rpy="2.35619 0.61548 1.30900" xyz="0.08000 -0.08000 -0.08000"/>
			<geometry>
				<capsule length="0.27713" radius="0.04000"/>
			</geometry>
		</collision>
		<visual>
			<origin rpy="2.35619 0.61548 1.30900" xyz="0.08000 -0.08000 -0.08000"/>
			<geometry>
				<capsule length="0.27713" radius="0.04000"/>
			</geometry>
		</visual>
	</link>
	<link name="right_lower_arm">
		<inertial>
			<origin rpy="0.00000 -0.00000 0.00000" xyz="0.00000 0.00000 0.00000"/>
			<mass value="1.22954"/>
			<inertia ixx="0.01419" ixy="0" ixz="0" iyy="0.01419" iyz="0" izz="0.01374"/>
		</inertial>
		<collision>
			<origin rpy="-0.78540 0.61548 -0.26180" xyz="0.09000 0.09000 0.09000"/>
			<geometry>
				<capsule length="0.27713" radius="0.03100"/>
			</geometry>
		</collision>
		<collision>
			<origin rpy="0.00000 -0.00000 0.00000" xyz="0.18000 0.18000 0.18000"/>
			<geometry>
				<sphere radius="0.04000"/>
			</geometry>
		</collision>
		<visual>
			<origin rpy="-0.78540 0.61548 -0.26180" xyz="0.09000 0.09000 0.09000"/>
			<geometry>
				<capsule length="0.27713" radius="0.03100"/>
			</geometry>
		</visual>
		<visual>
			<origin rpy="0.00000 -0.00000 0.00000" xyz="0.18000 0.18000 0.18000"/>
			<geometry>
				<sphere radius="0.04000"/>
			</geometry>
		</visual>
	</link>

	<link name="left_upper_arm">
		<inertial>
			<origin rpy="0.00000 -0.00000 0.00000" xyz="0.08000 0.08000 -0.08000"/>
			<mass value="1.66108"/>
			<inertia ixx="0.02368" ixy="0" ixz="0" iyy="0.02368" iyz="0" izz="0.02267"/>
		</inertial>
		<collision>
			<origin rpy="-2.35619 0.61548 -1.30900" xyz="0.08000 0.08000 -0.08000"/>
			<geometry>
				<capsule length="0.27713" radius="0.04000"/>
			</geometry>
		</collision>
		<visual>
			<origin rpy="-2.35619 0.61548 -1.30900" xyz="0.08000 0.08000 -0.08000"/>
			<geometry>
				<capsule length="0.27713" radius="0.04000"/>
			</geometry>
		</visual>
	</link>
	<link name="left_lower_arm">
		<inertial>
			<origin rpy="0.00000 -0.00000 0.00000" xyz="0.00000 0.00000 0.00000"/>
			<mass value="1.22954"/>
			<inertia ixx="0.01419" ixy="0" ixz="0" iyy="0.01419" iyz="0" izz="0.01374"/>
		</inertial>
		<collision>
			<origin rpy="0.78540 0.61548 0.26180" xyz="0.09000 -0.09000 0.09000"/>
			<geometry>
				<capsule length="0.27713" radius="0.03100"/>
			</geometry>
		</collision>
		<collision>
			<origin rpy="0.00000 -0.00000 0.00000" xyz="0.18000 -0.18000 0.18000"/>
			<geometry>
				<sphere radius="0.04000"/>
			</geometry>
		</collision>
		<visual>
			<origin rpy="0.78540 0.61548 0.26180" xyz="0.09000 -0.09000 0.09000"/>
			<geometry>
				<capsule length="0.27713" radius="0.03100"/>
			</geometry>
		</visual>
		<visual>
			<origin rpy="0.00000 -0.00000 0.00000" xyz="0.18000 -0.18000 0.18000"/>
			<geometry>
				<sphere radius="0.04000"/>
			</geometry>
		</visual>
	</link>


	<joint name="abdomen_yz" type="orbital">
		<parent link="torso"/>
		<child link="lwaist"/>
		<dynamics damping="0.0" friction="0.0001"/>
		<origin rpy="0.00000 -0.00400 0.00000" xyz="-0.01026 0.00000 -0.25500"/>
		<axis xyz="1.00000 0.00000 0.00000"/>
	</joint>
	<joint name="abdomen_x" type="continuous">
		<parent link="lwaist"/>
		<child link="pelvis"/>
		<dynamics damping="0.0" friction="0.0001"/>
		<origin rpy="0.00000 -0.00400 0.00000" xyz="-0.00040 0.00000 -0.16500"/>
		<axis xyz="1.00000 0.00000 0.00000"/>
	</joint>

	<joint name="right_hip_xyz" type="ball">
		<parent link="pelvis"/>
		<child link="right_thigh"/>
		<dynamics damping="0.0" friction="0.0001"/>
		<origin rpy="0.00000 -0.00000 0.00000" xyz="0.00000 -0.10000 -0.04000"/>
		<axis xyz="1.00000 0.00000 0.00000"/>
	</joint>
	<joint name="right_knee" type="continuous">
		<parent link="right_thigh"/>
		<child link="right_shin"/>
		<dynamics damping="0.0" friction="0.0001"/>
		<origin rpy="0.00000 -0.00000 0.00000" xyz="0.00000 0.01000 -0.40300"/>
		<axis xyz="0.00000 -1.00000 0.00000"/>
	</joint>
	<joint name="right_ankle_y" type="continuous">
		<parent link="right_shin"/>
		<child link="right_foot"/>
		<dynamics damping="0.0" friction="0.0001"/>
		<origin rpy="0.00000 -0.00000 0.00000" xyz="0.00000 0.00000 -0.43000"/>
		<axis xyz="-0.44721 0.00000 0.89442"/>
	</joint>

	<joint name="left_hip_xyz" type="ball">
		<parent link="pelvis"/>
		<child link="left_thigh"/>
		<dynamics damping="0.0" friction="0.0001"/>
		<origin rpy="0.00000 -0.00000 0.00000" xyz="0.00000 0.10000 -0.04000"/>
		<axis xyz="-1.00000 0.00000 0.00000"/>
	</joint>
	<joint name="left_knee" type="continuous">
		<parent link="left_thigh"/>
		<child link="left_shin"/>
		<dynamics damping="0.0" friction="0.0001"/>
		<origin rpy="0.00000 -0.00000 0.00000" xyz="0.00000 -0.01000 -0.40300"/>
		<axis xyz="0.00000 -1.00000 0.00000"/>
	</joint>
	<joint name="left_ankle_y" type="continuous">
		<parent link="left_shin"/>
		<child link="left_foot"/>
		<dynamics damping="0.0" friction="0.0001"/>
		<origin rpy="0.00000 -0.00000 0.00000" xyz="0.00000 0.00000 -0.43000"/>
		<axis xyz="-0.44721 0.00000 0.89442"/>
	</joint>

	<joint name="right_shoulder1" type="orbital">
		<parent link="torso"/>
		<child link="right_upper_arm"/>
		<dynamics damping="0.0" friction="0.0001"/>
		<origin rpy="0.00000 -0.00000 0.00000" xyz="0.00000 -0.17000 0.06000"/>
		<axis xyz="-0.57735 0.57735 0.57735"/>
	</joint>
	<joint name="right_elbow" type="continuous">
		<parent link="right_upper_arm"/>
		<child link="right_lower_arm"/>
		<dynamics damping="0.0" friction="0.0001"/>
		<origin rpy="0.00000 -0.00000 0.00000" xyz="0.18000 -0.18000 -0.18000"/>
		<axis xyz="0.00000 -1.00000 1.00000"/>
	</joint>

	<joint name="left_shoulder1" type="orbital">
		<parent link="torso"/>
		<child link="left_upper_arm"/>
		<dynamics damping="0.0" friction="0.0001"/>
		<origin rpy="0.00000 -0.00000 0.00000" xyz="0.00000 0.17000 0.06000"/>
		<axis xyz="0.57735 0.57735 -0.57735"/>
	</joint>
	<joint name="left_elbow" type="continuous">
		<parent link="left_upper_arm"/>
		<child link="left_lower_arm"/>
		<dynamics damping="0.0" friction="0.0001"/>
		<origin rpy="0.00000 -0.00000 0.00000" xyz="0.18000 0.18000 -0.18000"/>
		<axis xyz="0.00000 -1.00000 -1.00000"/>
	</joint>

</robot>
