<mujoco model="hopper">
  <compiler angle="degree" coordinate="global" inertiafromgeom="true"/>
  <default>
    <joint armature="1" damping="1" limited="false"/>
    <geom conaffinity="1" condim="1" contype="1" margin="0.001" material="geom" rgba="1.0 0.0 0.0 1"/>
    <motor ctrllimited="false" ctrlrange="-100.0 100.0"/>
  </default>

  <option integrator="RK4" timestep="0.01"/>

	<size nkey='5'/>
  <visual>
    <map znear="0.02"/>
  </visual>
  <worldbody>
    <light cutoff="100" diffuse="1 1 1" dir="-0 0 -1.3" directional="true" exponent="1" pos="0 0 1.3" specular=".1 .1 .1"/>
    <geom conaffinity="1" condim="3" name="floor" pos="0 0 0" rgba="0.8 0.9 0.8 1" size="20 20 .125" type="plane" material="MatPlane"/>
    <body name="torso" pos="0 0 0.55">
      <camera name="track" mode="trackcom" pos="0 -3 1" xyaxes="1 0 0 0 0 1"/>
      <joint armature="0" axis="1 0 0" damping="0" limited="false" name="rootx" pos="0 0 0" stiffness="0" type="slide"/>
      <joint armature="0" axis="0 1 0" damping="0" limited="false" name="rooty" pos="0 0 0" stiffness="0" type="slide"/>
      <joint armature="0" axis="0 0 1" damping="0" limited="false" name="rootz" pos="0 0 0" ref="0.55" stiffness="0" type="slide"/>

      <joint armature="0" axis="1 0 0" damping="0" limited="false" name="rotx" pos="0 0 0.55" stiffness="0" type="hinge"/>
      <joint armature="0" axis="0 1 0" damping="0" limited="false" name="roty" pos="0 0 0.55" stiffness="0" type="hinge"/>
      <joint armature="0" axis="0 0 1" damping="0" limited="false" name="rotz" pos="0 0 0.55" stiffness="0" type="hinge"/>

      <geom friction="0.5" fromto="-0.1 0 0.55 0.1 0 0.55" name="torso_geom" size="0.1 0.1 0.1" type="ellipsoid"/>
      <!-- <inertial pos="0 0 0" mass="1" diaginertia="0.1 0.1 0.1"/> -->
      <body name="foot" pos="0 0 0.05">
        <joint axis="0 0 -1" name="foot_slider" pos="0 0 0.55" range="0.25 1.0" ref="0.5" type="slide"/>
        <geom friction="0.5" fromto="-0.05 0 0.05 0.05 0 0.05" name="thigh_geom" size="0.05 0.05 0.05" type="ellipsoid"/>
        <!-- <inertial pos="0 0 0" mass="0.1" diaginertia="0.00001 0.00001 0.00001"/> -->
      </body>
    </body>
  </worldbody>
  <actuator>    
    <motor ctrllimited="false" gear="200.0" joint="rotx"/>
    <motor ctrllimited="false" gear="200.0" joint="roty"/>
    <motor ctrllimited="false" gear="200.0" joint="foot_slider"/>
    <motor ctrllimited="false" gear="200.0" joint="rootx"/>
    <motor ctrllimited="false" gear="200.0" joint="rooty"/>
    <motor ctrllimited="false" gear="200.0" joint="rootz"/>
    <motor ctrllimited="false" gear="200.0" joint="rotz"/>
  </actuator>
    <asset>
        <texture type="skybox" builtin="gradient" rgb1=".4 .5 .6" rgb2="0 0 0"
            width="100" height="100"/>
        <texture builtin="flat" height="1278" mark="cross" markrgb="1 1 1" name="texgeom" random="0.01" rgb1="0.8 0.6 0.4" rgb2="0.8 0.6 0.4" type="cube" width="127"/>
        <texture builtin="checker" height="100" name="texplane" rgb1="0 0 0" rgb2="0.8 0.8 0.8" type="2d" width="100"/>
        <material name="MatPlane" reflectance="0.5" shininess="1" specular="1" texrepeat="60 60" texture="texplane"/>
        <material name="geom" texture="texgeom" texuniform="true"/>
    </asset>
</mujoco>
