<?xml version="1.0" ?>
<!-- =================================================================================== -->
<!-- |    This document was autogenerated by xacro from atlas_v5_convex_hull_open_hands.xacro | -->
<!-- |    EDITING THIS FILE BY HAND IS NOT RECOMMENDED                                 | -->
<!-- =================================================================================== -->
<robot name="hopper" xmlns:xacro="http://www.ros.org/wiki/xacro">

  <link name="base">
		<inertial>
			<origin rpy="0.00000 -0.00000 0.00000" xyz="0.00000 0.00000 0.00000"/>
			<mass value="1.00000"/>
			<inertia ixx="1.00000" ixy="0" ixz="0" iyy="1.00000" iyz="0" izz="1.00000"/>
		</inertial>
	</link>
	<link name="torso">
		<inertial>
			<origin rpy="0.00000 -0.00000 0.00000" xyz="0.00000 0.00000 0.00000"/>
			<mass value="3.53429"/>
			<inertia ixx="0.06185" ixy="0" ixz="0" iyy="0.06185" iyz="0" izz="0.00441"/>
		</inertial>
		<collision>
			<origin rpy="0.00000 0.00000 0.00000" xyz="0.00000 0.00000 0.00000"/>
			<geometry>
				<capsule length="0.40000" radius="0.05"/>
			</geometry>
		</collision>
    <visual>
			<origin rpy="0.00000 0.00000 0.00000" xyz="0.00000 0.00000 0.00000"/>
			<geometry>
				<capsule length="0.40000" radius="0.05"/>
			</geometry>
    </visual>
	</link>
	<link name="thigh">
		<inertial>
			<origin rpy="0.00000 0.00000 0.00000" xyz="0.00000 0.00000 -0.225"/>
			<mass value="3.92699"/>
			<inertia ixx="0.08426" ixy="0" ixz="0" iyy="0.08426" iyz="0" izz="0.00490"/>
		</inertial>
		<collision>
			<origin rpy="0.00000 0.00000 0.00000" xyz="0.00000 0.00000 -0.225"/>
			<geometry>
				<capsule length="0.45" radius="0.05"/>
			</geometry>
		</collision>
    <visual>
      <origin rpy="0.00000 0.0000 0.00000" xyz="0.00000 0.00000 -0.225"/>
      <geometry>
        <capsule length="0.45" radius="0.05"/>
      </geometry>
    </visual>
	</link>

	<joint name="floating_joint" type="planaraxis">
		<parent link="base"/>
		<child link="torso"/>
		<origin rpy="0.00000 0.00000 0.00000" xyz="0.00000 0.00000 0.00000"/>
		<axis xyz="0.00000 1.00000 0.00000"/>
	</joint>
	<joint name="thigh" type="revolute">
		<parent link="torso"/>
		<child link="thigh"/>
		<dynamics damping="1.0" friction="0.0001"/>
		<origin rpy="0.00000 0.00000 0.00000" xyz="0.00000 0.00000 -0.20000"/>
		<axis xyz="0.00000 1.00000 0.00000"/>
	</joint>
</robot>
