<?xml version="1.0" ?>
<!-- =================================================================================== -->
<!-- |    This document was autogenerated by xacro                                     | -->
<!-- |    EDITING THIS FILE BY HAND IS NOT RECOMMENDED                                 | -->
<!-- =================================================================================== -->
<robot name="youbot" xmlns:controller="http://playerstage.sourceforge.net/gazebo/xmlschema/#controller" xmlns:interface="http://playerstage.sourceforge.net/gazebo/xmlschema/#interface" xmlns:sensor="http://playerstage.sourceforge.net/gazebo/xmlschema/#sensor">
	<material name="youBot/Orange">
		<color rgba="1.0 0.4 0.0 1.0"/>
	</material>
	<material name="youBot/Grey">
		<color rgba="0.7 0.7 0.7 1.0"/>
	</material>
	<material name="youBot/DarkGrey">
		<color rgba="0.3 0.3 0.3 1.0"/>
	</material>
	<material name="youBot/White">
		<color rgba="1.0 1.0 1.0 1.0"/>
	</material>
	<material name="youBot/Black">
		<color rgba="0.0 0.0 0.0 1.0"/>
	</material>
	<material name="youBot/Red">
		<color rgba="1.0 0.0 0.0 1.0"/>
	</material>
	<material name="youBot/Green">
		<color rgba="0.0 1.0 0.0 1.0"/>
	</material>
	<material name="youBot/Blue">
		<color rgba="0.0 0.0 0.8 1.0"/>
	</material>
	<material name="youBot/LightGrey">
		<color rgba="0.82 0.82 0.82 1.0"/>
	</material>
	&gt;

	<gazebo>
		<plugin filename="libgazebo_ros_control.so" name="gazebo_ros_controller">
			<robotSimType>gazebo_ros_control/DefaultRobotHWSim</robotSimType>
			<legacyModeNS>true</legacyModeNS>
		</plugin>
	</gazebo>

	<!-- foot for arm-->
	<link name="arm_link_0">
		<inertial>
			<origin rpy="0 0 0" xyz="-0.024 0 0.032"/>
			<mass value="0.961"/>
			<inertia ixx="0.01" ixy="0" ixz="0" iyy="0.01" iyz="0" izz="0.01"/>
		</inertial>
		<visual>
			<origin rpy="0 0 0" xyz="-0.024 0 0.032"/>
			<geometry>
				<mesh filename="meshes/youbot_arm/arm0.dae"/>
			</geometry>
			<material name="youBot/DarkGrey"/>
		</visual>
		<collision>
			<origin rpy="0 0 0" xyz="-0.024 0 0.032"/>
			<geometry>
				<mesh filename="meshes/youbot_arm/arm0_convex.dae"/>
				<!--<cylinder length="0.078" radius="0.093"/>-->
			</geometry>
		</collision>
	</link>
	<!-- joint between arm_0_link and arm_1_link -->
	<joint name="arm_joint_1" type="revolute">
		<origin rpy="0 0 0" xyz="0 0 0.128"/>
		<parent link="arm_link_0"/>
		<child link="arm_link_1"/>
		<axis xyz="0 0 -1"/>
		<!--<calibration rising="${arm_1_ref}" falling="${arm_1_ref}"/>-->
		<dynamics damping="1" friction="0.5"/>
		<!-- damping - N*s/m, N*s*m/rad -->
		<!-- friction - N, N*m -->
		<limit effort="9.5" lower="0" upper="5.899212871740834" velocity="1.5707963267948966"/>
		<!--effort - N, N*m-->
		<!--velocity - m/s, rad/s-->
		<!--safety_controller k_position="20" k_velocity="${9.5/M_PI / 2.0}" soft_lower_limit="${threshold}" soft_upper_limit="${joint_1_limit_soft}" /-->
		<!--k_position N/m, N/rad-->
		<!--k_velocity N*s/m, N*s*m/rad-->
		<!--for details: http://www.ros.org/wiki/pr2_controller_manager/safety_limits-->
	</joint>
	<link name="arm_link_1">
		<inertial>
			<mass value="1.39"/>
			<origin rpy="0 0 0" xyz="0.01489 0.00213 0.00213"/>
			<inertia ixx="0.0029525" ixy="0.0" ixz="0.0" iyy="0.0060091" iyz="0.0" izz="0.0058821"/>
		</inertial>
		<visual>
			<origin rpy="0 0 0" xyz="0 0 0"/>
			<geometry>
				<mesh filename="meshes/youbot_arm/arm1.dae"/>
			</geometry>
			<material name="youBot/Orange"/>
		</visual>
		<collision>
			<origin rpy="0 0 0" xyz="0 0 0"/>
			<geometry>
				<mesh filename="meshes/youbot_arm/arm1_convex.dae"/>
				<!--<cylinder length="0.102" radius="0.080"/>-->
			</geometry>
		</collision>
	</link>
	<!-- joint between arm_1_link and arm_2_link -->
	<joint name="arm_joint_2" type="revolute">
		<origin rpy="0 0 0" xyz="0.033 0 0.019"/>
		<parent link="arm_link_1"/>
		<child link="arm_link_2"/>
		<axis xyz="0 1 0"/>
		<!--<calibration rising="${arm_2_ref}" falling="${arm_2_ref}"/>-->
		<dynamics damping="1" friction="0.5"/>
		<limit effort="9.5" lower="0" upper="2.705260340591211" velocity="1.5707963267948966"/>
		<!--safety_controller k_position="20" k_velocity="${2*9.5/M_PI}" soft_lower_limit="${threshold}" soft_upper_limit="${joint_2_limit_soft}" /-->
	</joint>
	<link name="arm_link_2">
		<inertial>
			<mass value="1.318"/>
			<origin rpy="0 0 0" xyz="0.01053 -0.030699999999999998 0.08597"/>
			<inertia ixx="0.0031145" ixy="0.0" ixz="0.0" iyy="0.0005843" iyz="0.0" izz="0.0031631"/>
		</inertial>
		<visual>
			<origin rpy="0 0 0" xyz="0 -0.032 0.078"/>
			<geometry>
				<mesh filename="meshes/youbot_arm/arm2.dae"/>
			</geometry>
		</visual>
		<collision>
			<!--<origin xyz="0.001 -0.041 0.074" rpy="0 0 0" />-->
			<origin rpy="0 0 0" xyz="0 -0.032 0.078"/>
			<geometry>
				<mesh filename="meshes/youbot_arm/arm2_convex.dae"/>
				<!--<box size="0.074 0.082 0.222"/>-->
			</geometry>
		</collision>
	</link>
	<!-- joint between arm_2_link and arm_3_link -->
	<joint name="arm_joint_3" type="revolute">
		<origin rpy="0 0 0" xyz="0.000 0.000 0.155"/>
		<parent link="arm_link_2"/>
		<child link="arm_link_3"/>
		<axis xyz="0 1 0"/>
		<dynamics damping="1" friction="0.5"/>
		<limit effort="6.0" lower="-5.183627878423159" upper="0" velocity="1.5707963267948966"/>
		<!--safety_controller k_position="20" k_velocity="50" soft_lower_limit="-${joint_3_limit_soft}" soft_upper_limit="-${threshold}" /-->
	</joint>
	<link name="arm_link_3">
		<inertial>
			<mass value="0.821"/>
			<origin rpy="0 0 0" xyz="0.0001 0.0207 0.07107"/>
			<inertia ixx="0.00172767" ixy="0.0" ixz="0.0" iyy="0.00041967" iyz="0.0" izz="0.0018468"/>
		</inertial>
		<visual>
			<origin rpy="0 0 0" xyz="0.000 0.028 0.079"/>
			<geometry>
				<mesh filename="meshes/youbot_arm/arm3.dae"/>
			</geometry>
			<material name="youBot/Orange"/>
		</visual>
		<collision>
			<!--<origin xyz="0.000 0.025 0.067" rpy="0 0 0" />-->
			<origin rpy="0 0 0" xyz="0.000 0.028 0.079"/>
			<geometry>
				<mesh filename="meshes/youbot_arm/arm3_convex.dae"/>
				<!--<box size="0.064 0.054 0.192"/>-->
			</geometry>
		</collision>
	</link>
	<!-- joint between arm_3_link and arm_4_link -->
	<joint name="arm_joint_4" type="revolute">
		<origin rpy="0 0 0" xyz="0.000 0.000 0.135"/>
		<parent link="arm_link_3"/>
		<child link="arm_link_4"/>
		<axis xyz="0 1 0"/>
		<!--<calibration rising="${arm_4_ref}" falling="${arm_4_ref}"/>-->
		<dynamics damping="1" friction="0.5"/>
		<limit effort="2.0" lower="0" upper="3.5779249665883754" velocity="1.5707963267948966"/>
		<!--safety_controller k_position="20" k_velocity="100" soft_lower_limit="0" soft_upper_limit="${joint_4_limit_soft}" /-->
	</joint>
	<link name="arm_link_4">
		<inertial>
			<mass value="0.769"/>
			<origin rpy="0 0 0" xyz="0.00011 -0.02 0.05019"/>
			<inertia ixx="0.0006764" ixy="0.0" ixz="0.0" iyy="0.0010573" iyz="0.0" izz="0.0006610"/>
		</inertial>
		<visual>
			<origin rpy="0 0 0" xyz="0 -0.010 0.029"/>
			<geometry>
				<mesh filename="meshes/youbot_arm/arm4.dae"/>
			</geometry>
			<material name="youBot/Orange"/>
		</visual>
		<collision>
			<!--<origin xyz="0 0 0.026" rpy="0 0 0" />-->
			<origin rpy="0 0 0" xyz="0 -0.010 0.029"/>
			<geometry>
				<mesh filename="meshes/youbot_arm/arm4_convex.dae"/>
				<!--<box size="0.058 0.100 0.118"/>-->
			</geometry>
		</collision>
	</link>
	<!-- joint between arm_4_link and arm_5_link -->
	<joint name="arm_joint_5" type="revolute">
		<origin rpy="0 0 0" xyz="-0.002 0 0.130"/>
		<parent link="arm_link_4"/>
		<child link="arm_link_5"/>
		<axis xyz="0 0 -1"/>
		<!--<calibration rising="${arm_5_ref}" falling="${arm_5_ref}"/>-->
		<dynamics damping="0.5" friction="0.5"/>
		<limit effort="1.0" lower="0" upper="5.8468529941810035" velocity="1.5707963267948966"/>
		<!--safety_controller k_position="20" k_velocity="100" soft_lower_limit="0" soft_upper_limit="${joint_5_limit_soft}" /-->
	</joint>
	<link name="arm_link_5">
		<inertial>
			<mass value="0.687"/>
			<origin rpy="0 0 0" xyz="0.0 0.00115 -0.016829999999999998"/>
			<inertia ixx="0.0001934" ixy="0.0" ixz="0.0" iyy="0.0001602" iyz="0.0" izz="0.0000689"/>
		</inertial>
		<visual>
			<origin rpy="0 0 0" xyz="0.003 0 -0.034"/>
			<geometry>
				<mesh filename="meshes/youbot_arm/arm5.dae"/>
			</geometry>
			<material name="youBot/DarkGrey"/>
		</visual>
		<collision>
			<origin rpy="0 0 0" xyz="0.003 0 -0.034"/>
			<geometry>
				<mesh filename="meshes/youbot_arm/arm5_convex.dae"/>
				<!--<box size="0.054 0.096 0.030"/>-->
			</geometry>
		</collision>
	</link>
	<gazebo reference="arm_link_0">
		<turnGravityOff>false</turnGravityOff>
	</gazebo>
	<gazebo reference="arm_link_1">
		<turnGravityOff>false</turnGravityOff>
	</gazebo>
	<gazebo reference="arm_link_2">
		<turnGravityOff>false</turnGravityOff>
	</gazebo>
	<gazebo reference="arm_link_3">
		<turnGravityOff>false</turnGravityOff>
	</gazebo>
	<gazebo reference="arm_link_4">
		<turnGravityOff>false</turnGravityOff>
	</gazebo>
	<gazebo reference="arm_link_5">
		<turnGravityOff>false</turnGravityOff>
	</gazebo>
	<transmission name="arm_trans_1">
		<type>transmission_interface/SimpleTransmission</type>
		<actuator name="arm_motor_1">
			<mechanicalReduction>1</mechanicalReduction>
		</actuator>
		<joint name="arm_joint_1">
			<hardwareInterface>hardware_interface/EffortJointInterface</hardwareInterface>
		</joint>
	</transmission>
	<transmission name="arm_trans_2">
		<type>transmission_interface/SimpleTransmission</type>
		<actuator name="arm_motor_2">
			<mechanicalReduction>1</mechanicalReduction>
		</actuator>
		<joint name="arm_joint_2">
			<hardwareInterface>hardware_interface/EffortJointInterface</hardwareInterface>
		</joint>
	</transmission>
	<transmission name="arm_trans_3">
		<type>transmission_interface/SimpleTransmission</type>
		<actuator name="arm_motor_3">
			<mechanicalReduction>1</mechanicalReduction>
		</actuator>
		<joint name="arm_joint_3">
			<hardwareInterface>hardware_interface/EffortJointInterface</hardwareInterface>
		</joint>
	</transmission>
	<transmission name="arm_trans_4">
		<type>transmission_interface/SimpleTransmission</type>
		<actuator name="arm_motor_4">
			<mechanicalReduction>1</mechanicalReduction>
		</actuator>
		<joint name="arm_joint_4">
			<hardwareInterface>hardware_interface/EffortJointInterface</hardwareInterface>
		</joint>
	</transmission>
	<transmission name="arm_trans_5">
		<type>transmission_interface/SimpleTransmission</type>
		<actuator name="arm_motor_5">
			<mechanicalReduction>1</mechanicalReduction>
		</actuator>
		<joint name="arm_joint_5">
			<hardwareInterface>hardware_interface/EffortJointInterface</hardwareInterface>
		</joint>
	</transmission>
	<!-- joint between arm_7_link and sdh_palm_link -->
	<joint name="gripper_palm_joint" type="fixed">
		<origin rpy="0 0 0" xyz="0 0 0"/>
		<parent link="arm_link_5"/>
		<child link="gripper_palm_link"/>
	</joint>
	<link name="gripper_palm_link">
		<inertial>
			<origin rpy="0 0 0" xyz="0 0 0"/>
			<mass value="0.1"/>
			<inertia ixx="0.01" ixy="0" ixz="0" iyy="0.01" iyz="0" izz="0.01"/>
		</inertial>
		<visual>
			<origin rpy="0 0 0" xyz="0 0 0"/>
			<geometry>
				<mesh filename="meshes/youbot_gripper/palm.dae"/>
			</geometry>
			<material name="Black"/>
		</visual>
		<collision>
			<origin rpy="0 0 0" xyz="0 0 0"/>
			<geometry>
				<!--<box size="0.050 0.094 0.054"/>-->
				<mesh filename="meshes/youbot_gripper/palm_convex.dae"/>
			</geometry>
		</collision>
	</link>
	<joint name="gripper_finger_joint_l" type="prismatic">
		<origin rpy="0 0 3.141592653589793" xyz="0.004 0.008 0.046"/>
		<parent link="gripper_palm_link"/>
		<child link="gripper_finger_link_l"/>
		<axis xyz="0 -1 0"/>
		<dynamics damping="1.0" friction="1.0"/>
		<limit effort="1" lower="0" upper="0.0115" velocity="0.1"/>
		<safety_controller k_position="20" k_velocity="25" soft_lower_limit="0.001" soft_upper_limit="0.011"/>
	</joint>
	<link name="gripper_finger_link_l">
		<inertial>
			<origin rpy="0 0 0" xyz="0 -0.001 0"/>
			<mass value="0.01"/>
			<inertia ixx="0.01" ixy="0" ixz="0" iyy="0.01" iyz="0" izz="0.01"/>
		</inertial>
		<visual>
			<origin rpy="0 0 0" xyz="0 0 0"/>
			<geometry>
				<mesh filename="meshes/youbot_gripper/finger.dae"/>
			</geometry>
			<material name="Black"/>
		</visual>
		<collision>
			<origin rpy="0 0 0" xyz="0 0 0"/>
			<geometry>
				<!--<box size="0.014 0.020 0.046"/>-->
				<mesh filename="meshes/youbot_gripper/finger_convex.dae"/>
			</geometry>
		</collision>
	</link>
	<joint name="gripper_finger_joint_r" type="prismatic">
		<origin rpy="0 0 0" xyz="0.004 -0.008 0.046"/>
		<parent link="gripper_palm_link"/>
		<child link="gripper_finger_link_r"/>
		<axis xyz="0 -1 0"/>
		<dynamics damping="1.0" friction="1.0"/>
		<limit effort="1" lower="0" upper="0.0115" velocity="0.1"/>
		<safety_controller k_position="20" k_velocity="25" soft_lower_limit="0.001" soft_upper_limit="0.011"/>
	</joint>
	<link name="gripper_finger_link_r">
		<inertial>
			<origin rpy="0 0 0" xyz="0.000 -0.001 0"/>
			<mass value="0.01"/>
			<inertia ixx="0.01" ixy="0" ixz="0" iyy="0.01" iyz="0" izz="0.01"/>
		</inertial>
		<visual>
			<origin rpy="0 0 0" xyz="0 0 0"/>
			<geometry>
				<mesh filename="meshes/youbot_gripper/finger.dae"/>
			</geometry>
			<material name="Black"/>
		</visual>
		<collision>
			<origin rpy="0 0 0" xyz="0.000 0 0"/>
			<geometry>
				<!--<box size="0.014 0.020 0.046"/>-->
				<mesh filename="meshes/youbot_gripper/finger_convex.dae"/>
			</geometry>
		</collision>
	</link>
	<gazebo reference="gripper_palm_link">
		<material>Gazebo/Black</material>
		<turnGravityOff>false</turnGravityOff>
		<selfCollide>true</selfCollide>
	</gazebo>
	<gazebo reference="gripper_finger_l_link">
		<material>Gazebo/Black</material>
		<turnGravityOff>false</turnGravityOff>
		<selfCollide>true</selfCollide>
	</gazebo>
	<gazebo reference="gripper_finger_r_link">
		<material>Gazebo/Black</material>
		<turnGravityOff>false</turnGravityOff>
		<selfCollide>true</selfCollide>
	</gazebo>
	<transmission name="gripper_finger_l_trans">
		<type>transmission_interface/SimpleTransmission</type>
		<actuator name="gripper_finger_l_motor">
			<mechanicalReduction>1</mechanicalReduction>
		</actuator>
		<joint name="gripper_finger_joint_l">
			<hardwareInterface>hardware_interface/EffortJointInterface</hardwareInterface>
		</joint>
	</transmission>
	<transmission name="gripper_finger_r_trans">
		<type>transmission_interface/SimpleTransmission</type>
		<actuator name="gripper_finger_r_motor">
			<mechanicalReduction>1</mechanicalReduction>
		</actuator>
		<joint name="gripper_finger_joint_r">
			<hardwareInterface>hardware_interface/EffortJointInterface</hardwareInterface>
		</joint>
	</transmission>
</robot>
