<?xml version="1.0"?>

<robot name="DoublePendulum">
	<link name="origin">
	</link>

  <link name="link1">
    <inertial>
      <origin xyz="0 0 -0.5" rpy="0 0 0" />
      <mass value="1" />
      <inertia ixx=".0841667" ixy="0" ixz="0" iyy=".0841667" iyz="0" izz=".00166667" />
    </inertial>
    <visual>
      <origin xyz="0 0 -0.5" rpy="0 0 0" />
      <geometry>
         <box size="0.1 0.1 1" />
      </geometry>
      <material name="gray">
	       <color rgba="0.75 0.75 0.75 1" />
      </material>
    </visual>
  </link>

  <link name="link2">
    <inertial>
      <origin xyz="0 0.5 0." rpy="1.5707963268 0. 0." />
      <mass value="1" />
      <inertia ixx=".0841667" ixy="0" ixz="0" iyy=".0841667" iyz="0" izz=".00166667" />
    </inertial>
    <visual>
      <origin xyz="0 0.5 0." rpy="1.57 0 0." />
      <geometry>
         <box size="0.1 0.1 1" />
      </geometry>
      <material name="gray">
	       <color rgba="0.75 0.75 0.75 1" />
      </material>
    </visual>
  </link>

	

	<joint name="joint01" type="continuous">
		<parent link="origin" />
		<child link="link1" />
		<origin rpy="0 0 0" xyz="0 0 0" />
		<axis xyz="1 0 0" />
	</joint>

  <joint name="joint12" type="continuous">
		<parent link="link1" />
		<child link="link2" />
		<origin rpy="0 0 0" xyz="0 0 -1" />
		<axis xyz="1 0 0" />
	</joint>

	

</robot>
