<?xml version="1.0" ?>
<!-- =================================================================================== -->
<!-- |    This document was autogenerated by xacro from atlas_v5_convex_hull_open_hands.xacro | -->
<!-- |    EDITING THIS FILE BY HAND IS NOT RECOMMENDED                                 | -->
<!-- =================================================================================== -->
<robot name="atlas" xmlns:xacro="http://www.ros.org/wiki/xacro">
  <link name="l_clav">
    <inertial>
      <mass value="1.0"/>
      <origin rpy="0 0 0" xyz="0 0 -0.084"/>
      <inertia ixx="0.1" ixy="0.0" ixz="0.0" iyy="0.1" iyz="0.0" izz="0.1"/>
    </inertial>
    <visual>
      <geometry>
        <mesh filename="examples/examples_files/atlas_mesh/r_clav.obj"/>
      </geometry>
    </visual>
  </link>
  <link name="l_foot">
    <inertial>
      <mass value="1.0"/>
      <origin rpy="0 0 0" xyz="0.027 0 -0.067"/>
      <inertia ixx="0.1" ixy="0.0" ixz="0.0" iyy="0.1" iyz="0.0" izz="0.1"/>
    </inertial>
    <visual>
      <geometry>
        <mesh filename="examples/examples_files/atlas_mesh/l_foot.obj"/>
      </geometry>
    </visual>
    <visual group="heel">
      <origin rpy="0 0 0" xyz="-0.0876 0.066 -0.07645"/>
      <geometry>
        <sphere radius="0.01"/>
      </geometry>
    </visual>
    <visual group="heel">
      <origin rpy="0 0 0" xyz="-0.0876 -0.0626 -0.07645"/>
      <geometry>
        <sphere radius="0.01"/>
      </geometry>
    </visual>
    <visual group="toe">
      <origin rpy="0 0 0" xyz="0.1728 0.066 -0.07645"/>
      <geometry>
        <sphere radius="0.01"/>
      </geometry>
    </visual>
    <visual group="toe">
      <origin rpy="0 0 0" xyz="0.1728 -0.0626 -0.07645"/>
      <geometry>
        <sphere radius="0.01"/>
      </geometry>
    </visual>
    <visual group="midfoot">
      <origin rpy="0 0 0" xyz="-0.0426 0.066 -0.07645"/>
      <geometry>
        <sphere radius="0.01"/>
      </geometry>
    </visual>
    <visual group="midfoot">
      <origin rpy="0 0 0" xyz="-0.0426 -0.0626 -0.07645"/>
      <geometry>
        <sphere radius="0.01"/>
      </geometry>
    </visual>
  </link>
  <link name="l_hand">
    <inertial>
      <mass value="1.0"/>
      <origin rpy="0 0 0" xyz="0.00016 -0.08159 0.00002"/>
      <inertia ixx="0.1" ixy="0.0" ixz="0.0" iyy="0.1" iyz="0.0" izz="0.1"/>
    </inertial>
  </link>
  <link name="l_larm">
    <inertial>
      <mass value="1.0"/>
      <origin rpy="0 0 0" xyz="0 0 0"/>
      <inertia ixx="0.1" ixy="0.0" ixz="0.0" iyy="0.1" iyz="0.0" izz="0.1"/>
    </inertial>
    <visual>
      <geometry>
        <mesh filename="examples/examples_files/atlas_mesh/r_larm.obj"/>
      </geometry>
    </visual>
  </link>
  <link name="l_lfarm">
    <inertial>
      <mass value="1.0"/>
      <origin rpy="0 0 0" xyz="0.00017 -0.02515 0.00163"/>
      <inertia ixx="0.1" ixy="0.0" ixz="0.0" iyy="0.1" iyz="0.0" izz="0.1"/>
    </inertial>
    <visual>
      <geometry>
        <mesh filename="examples/examples_files/atlas_mesh/r_hand.obj"/>
      </geometry>
    </visual>
  </link>
  <link name="l_lglut">
    <inertial>
      <mass value="1.0"/>
      <origin rpy="0 0 0" xyz="0.0133341 0.0170484 -0.0312052"/>
      <inertia ixx="0.1" ixy="0.0" ixz="0.0" iyy="0.1" iyz="0.0" izz="0.1"/>
    </inertial>
    <visual>
      <geometry>
        <mesh filename="examples/examples_files/atlas_mesh/l_lglut.obj"/>
      </geometry>
    </visual>
  </link>
  <link name="l_lleg">
    <inertial>
      <mass value="1.0"/>
      <origin rpy="0 0 0" xyz="0.001 0 -0.187"/>
      <inertia ixx="0.1" ixy="0.0" ixz="0.0" iyy="0.1" iyz="0.0" izz="0.1"/>
    </inertial>
    <visual>
      <geometry>
        <mesh filename="examples/examples_files/atlas_mesh/l_lleg.obj"/>
      </geometry>
    </visual>
  </link>
  <link name="l_scap">
    <inertial>
      <mass value="1.0"/>
      <origin rpy="0 0 0" xyz="0 0 0"/>
      <inertia ixx="0.1" ixy="0.0" ixz="0.0" iyy="0.1" iyz="0.0" izz="0.1"/>
    </inertial>
    <visual>
      <geometry>
        <mesh filename="examples/examples_files/atlas_mesh/r_scap.obj"/>
      </geometry>
    </visual>
  </link>
  <link name="l_talus">
    <inertial>
      <mass value="1.0"/>
      <origin rpy="0 0 0" xyz="0 0 0"/>
      <inertia ixx="0.1" ixy="0.0" ixz="0.0" iyy="0.1" iyz="0.0" izz="0.1"/>
    </inertial>
    <visual>
      <geometry>
        <mesh filename="examples/examples_files/atlas_mesh/l_talus.obj"/>
      </geometry>
    </visual>
  </link>
  <link name="l_uarm">
    <inertial>
      <mass value="1.0"/>
      <origin rpy="0 0 0" xyz="0 0.065 0"/>
      <inertia ixx="0.1" ixy="0.0" ixz="0.0" iyy="0.1" iyz="0.0" izz="0.1"/>
    </inertial>
    <visual>
      <geometry>
        <mesh filename="examples/examples_files/atlas_mesh/r_uarm.obj"/>
      </geometry>
    </visual>
  </link>
  <link name="l_ufarm">
    <inertial>
      <mass value="1.0"/>
      <origin rpy="0 0 0" xyz="0.00015 0.08296 0.00037"/>
      <inertia ixx="0.1" ixy="0.0" ixz="0.0" iyy="0.1" iyz="0.0" izz="0.1"/>
    </inertial>
    <visual>
      <geometry>
        <mesh filename="examples/examples_files/atlas_mesh/r_farm.obj"/>
      </geometry>
    </visual>
  </link>
  <link name="l_uglut">
    <inertial>
      <mass value="1.0"/>
      <origin rpy="0 0 0" xyz="0.00529262 -0.00344732 0.00313046"/>
      <inertia ixx="0.1" ixy="0.0" ixz="0.0" iyy="0.1" iyz="0.0" izz="0.1"/>
    </inertial>
    <visual>
      <geometry>
        <mesh filename="examples/examples_files/atlas_mesh/l_uglut.obj"/>
      </geometry>
    </visual>
  </link>
  <link name="l_uleg">
    <inertial>
      <mass value="1.0"/>
      <origin rpy="0 0 0" xyz="0 0 -0.21"/>
      <inertia ixx="0.1" ixy="0.0" ixz="0.0" iyy="0.1" iyz="0.0" izz="0.1"/>
    </inertial>
    <visual>
      <geometry>
        <mesh filename="examples/examples_files/atlas_mesh/l_uleg.obj"/>
      </geometry>
    </visual>
  </link>
  <link name="ltorso">
    <inertial>
      <mass value="1.0"/>
      <origin rpy="0 0 0" xyz="-0.0112984 -3.15366e-06 0.0746835"/>
      <inertia ixx="0.1" ixy="0.0" ixz="0.0" iyy="0.1" iyz="0.0" izz="0.1"/>
    </inertial>
    <visual>
      <geometry>
        <mesh filename="examples/examples_files/atlas_mesh/ltorso.obj"/>
      </geometry>
    </visual>
  </link>
  <link name="mtorso">
    <inertial>
      <mass value="1.0"/>
      <origin rpy="0 0 0" xyz="-0.00816266 -0.0131245 0.0305974"/>
      <inertia ixx="0.1" ixy="0.0" ixz="0.0" iyy="0.1" iyz="0.0" izz="0.1"/>
    </inertial>
    <visual>
      <geometry>
        <mesh filename="examples/examples_files/atlas_mesh/mtorso.obj"/>
      </geometry>
    </visual>
  </link>
  <link name="pelvis">
    <inertial>
      <mass value="1.0"/>
      <origin rpy="0 0 0" xyz="0.0111 0 0.0271"/>
      <inertia ixx="0.1" ixy="0.0" ixz="0.0" iyy="0.1" iyz="0.0" izz="0.1"/>
    </inertial>
    <visual>
      <geometry>
        <mesh filename="examples/examples_files/atlas_mesh/pelvis.obj"/>
      </geometry>
    </visual>
  </link>
  <link name="r_clav">
    <inertial>
      <mass value="1.0"/>
      <origin rpy="0 0 0" xyz="0 0 -0.084"/>
      <inertia ixx="0.1" ixy="0.0" ixz="0.0" iyy="0.1" iyz="0.0" izz="0.1"/>
    </inertial>
    <visual>
      <geometry>
        <mesh filename="examples/examples_files/atlas_mesh/r_clav.obj"/>
      </geometry>
    </visual>
  </link>
  <link name="r_foot">
    <inertial>
      <mass value="1.0"/>
      <origin rpy="0 0 0" xyz="0.027 0 -0.067"/>
      <inertia ixx="0.1" ixy="0.0" ixz="0.0" iyy="0.1" iyz="0.0" izz="0.1"/>
    </inertial>
    <visual>
      <geometry>
        <mesh filename="examples/examples_files/atlas_mesh/r_foot.obj"/>
      </geometry>
    </visual>
    <visual group="heel">
      <origin rpy="0 0 0" xyz="-0.0876 0.0626 -0.07645"/>
      <geometry>
        <sphere radius="0.01"/>
      </geometry>
    </visual>
    <visual group="heel">
      <origin rpy="0 0 0" xyz="-0.0876 -0.066 -0.07645"/>
      <geometry>
        <sphere radius="0.01"/>
      </geometry>
    </visual>
    <visual group="toe">
      <origin rpy="0 0 0" xyz="0.1728 0.0626 -0.07645"/>
      <geometry>
        <sphere radius="0.01"/>
      </geometry>
    </visual>
    <visual group="toe">
      <origin rpy="0 0 0" xyz="0.1728 -0.066 -0.07645"/>
      <geometry>
        <sphere radius="0.01"/>
      </geometry>
    </visual>
    <visual group="midfoot">
      <origin rpy="0 0 0" xyz="0.0426 0.0626 -0.07645"/>
      <geometry>
        <sphere radius="0.01"/>
      </geometry>
    </visual>
    <visual group="midfoot">
      <origin rpy="0 0 0" xyz="0.0426 -0.066 -0.07645"/>
      <geometry>
        <sphere radius="0.01"/>
      </geometry>
    </visual>
  </link>
  <link name="r_hand">
    <inertial>
      <mass value="1.0"/>
      <origin rpy="0 0 0" xyz="0.00016 -0.08159 0.00002"/>
      <inertia ixx="0.1" ixy="0.0" ixz="0.0" iyy="0.1" iyz="0.0" izz="0.1"/>
    </inertial>
  </link>
  <link name="r_larm">
    <inertial>
      <mass value="1.0"/>
      <origin rpy="0 0 0" xyz="0 0 0"/>
      <inertia ixx="0.1" ixy="0.0" ixz="0.0" iyy="0.1" iyz="0.0" izz="0.1"/>
    </inertial>
    <visual>
      <geometry>
        <mesh filename="examples/examples_files/atlas_mesh/r_larm.obj"/>
      </geometry>
    </visual>
  </link>
  <link name="r_lfarm">
    <inertial>
      <mass value="1.0"/>
      <origin rpy="0 0 0" xyz="0.00017 -0.02515 0.00163"/>
      <inertia ixx="0.1" ixy="0.0" ixz="0.0" iyy="0.1" iyz="0.0" izz="0.1"/>
    </inertial>
    <visual>
      <geometry>
        <mesh filename="examples/examples_files/atlas_mesh/r_hand.obj"/>
      </geometry>
    </visual>
  </link>
  <link name="r_lglut">
    <inertial>
      <mass value="1.0"/>
      <origin rpy="0 0 0" xyz="0.0133341 -0.0170484 -0.0312052"/>
      <inertia ixx="0.1" ixy="0.0" ixz="0.0" iyy="0.1" iyz="0.0" izz="0.1"/>
    </inertial>
    <visual>
      <geometry>
        <mesh filename="examples/examples_files/atlas_mesh/r_lglut.obj"/>
      </geometry>
    </visual>
  </link>
  <link name="r_lleg">
    <inertial>
      <mass value="1.0"/>
      <origin rpy="0 0 0" xyz="0.001 0 -0.187"/>
      <inertia ixx="0.1" ixy="0.0" ixz="0.0" iyy="0.1" iyz="0.0" izz="0.1"/>
    </inertial>
    <visual>
      <geometry>
        <mesh filename="examples/examples_files/atlas_mesh/r_lleg.obj"/>
      </geometry>
    </visual>
  </link>
  <link name="r_scap">
    <inertial>
      <mass value="1.0"/>
      <origin rpy="0 0 0" xyz="0 0 0"/>
      <inertia ixx="0.1" ixy="0.0" ixz="0.0" iyy="0.1" iyz="0.0" izz="0.1"/>
    </inertial>
    <visual>
      <geometry>
        <mesh filename="examples/examples_files/atlas_mesh/r_scap.obj"/>
      </geometry>
    </visual>
  </link>
  <link name="r_talus">
    <inertial>
      <mass value="1.0"/>
      <origin rpy="0 0 0" xyz="0 0 0"/>
      <inertia ixx="0.1" ixy="0.0" ixz="0.0" iyy="0.1" iyz="0.0" izz="0.1"/>
    </inertial>
    <visual>
      <geometry>
        <mesh filename="examples/examples_files/atlas_mesh/r_talus.obj"/>
      </geometry>
    </visual>
  </link>
  <link name="r_uarm">
    <inertial>
      <mass value="1.0"/>
      <origin rpy="0 0 0" xyz="0 0.065 0"/>
      <inertia ixx="0.1" ixy="0.0" ixz="0.0" iyy="0.1" iyz="0.0" izz="0.1"/>
    </inertial>
    <visual>
      <geometry>
        <mesh filename="examples/examples_files/atlas_mesh/r_uarm.obj"/>
      </geometry>
    </visual>
  </link>
  <link name="r_ufarm">
    <inertial>
      <mass value="1.0"/>
      <origin rpy="0 0 0" xyz="0.00015 0.08296 0.00037"/>
      <inertia ixx="0.1" ixy="0.0" ixz="0.0" iyy="0.1" iyz="0.0" izz="0.1"/>
    </inertial>
    <visual>
      <geometry>
        <mesh filename="examples/examples_files/atlas_mesh/r_farm.obj"/>
      </geometry>
    </visual>
  </link>
  <link name="r_uglut">
    <inertial>
      <mass value="1.0"/>
      <origin rpy="0 0 0" xyz="0.00529262 0.00344732 0.00313046"/>
      <inertia ixx="0.1" ixy="0.0" ixz="0.0" iyy="0.1" iyz="0.0" izz="0.1"/>
    </inertial>
    <visual>
      <geometry>
        <mesh filename="examples/examples_files/atlas_mesh/r_uglut.obj"/>
      </geometry>
    </visual>
  </link>
  <link name="r_uleg">
    <inertial>
      <mass value="1.0"/>
      <origin rpy="0 0 0" xyz="0 0 -0.21"/>
      <inertia ixx="0.1" ixy="0.0" ixz="0.0" iyy="0.1" iyz="0.0" izz="0.1"/>
    </inertial>
    <visual>
      <geometry>
        <mesh filename="examples/examples_files/atlas_mesh/r_uleg.obj"/>
      </geometry>
    </visual>
  </link>
  <link name="utorso">
    <inertial>
      <mass value="1.0"/>
      <origin rpy="0 0 0" xyz="-0.0622 0.0023 0.3157"/>
      <inertia ixx="0.1" ixy="0.0" ixz="0.0" iyy="0.1" iyz="0.0" izz="0.1"/>
    </inertial>
    <visual>
      <geometry>
        <mesh filename="examples/examples_files/atlas_mesh/utorso.obj"/>
      </geometry>
    </visual>
  </link>
  <joint name="back_bkx" type="revolute">
    <origin rpy="0 0 0" xyz="0 0 0.05"/>
    <axis xyz="1 0 0"/>
    <parent link="mtorso"/>
    <child link="utorso"/>
    <dynamics damping="0.1" friction="0"/>
    <limit effort="300" lower="-0.523599" upper="0.523599" velocity="12"/>
    <safety_controller k_position="100" k_velocity="100" soft_lower_limit="-10.5236" soft_upper_limit="10.5236"/>
  </joint>
  <joint name="back_bky" type="revolute">
    <origin rpy="0 0 0" xyz="0 0 0.162"/>
    <axis xyz="0 1 0"/>
    <parent link="ltorso"/>
    <child link="mtorso"/>
    <dynamics damping="0.1" friction="0"/>
    <limit effort="445" lower="-0.219388" upper="0.538783" velocity="9"/>
    <safety_controller k_position="100" k_velocity="100" soft_lower_limit="-10.2194" soft_upper_limit="10.5388"/>
  </joint>
  <joint name="back_bkz" type="revolute">
    <origin rpy="0 0 0" xyz="-0.0125 0 0"/>
    <axis xyz="0 0 1"/>
    <parent link="pelvis"/>
    <child link="ltorso"/>
    <dynamics damping="0.1" friction="0"/>
    <limit effort="106" lower="-0.663225" upper="0.663225" velocity="12"/>
    <safety_controller k_position="100" k_velocity="100" soft_lower_limit="-10.6632" soft_upper_limit="10.6632"/>
  </joint>
  <joint name="l_arm_elx" type="revolute">
    <origin rpy="0 0 0" xyz="0 -0.119 0.0092"/>
    <axis xyz="-1.0 -0.0 -0.0"/>
    <parent link="l_uarm"/>
    <child link="l_larm"/>
    <dynamics damping="0.1" friction="0"/>
    <limit effort="112" lower="0" upper="2.35619" velocity="12"/>
    <safety_controller k_position="100" k_velocity="100" soft_lower_limit="-10" soft_upper_limit="12.3562"/>
  </joint>
  <joint name="l_arm_ely" type="revolute">
    <origin rpy="0 0 0" xyz="0 -0.187 -0.016"/>
    <axis xyz="-0.0 -1.0 -0.0"/>
    <parent link="l_scap"/>
    <child link="l_uarm"/>
    <dynamics damping="0.1" friction="0"/>
    <limit effort="63" lower="0" upper="3.14159" velocity="12"/>
    <safety_controller k_position="100" k_velocity="100" soft_lower_limit="-10" soft_upper_limit="13.1416"/>
  </joint>
  <joint name="l_arm_shx" type="revolute">
    <origin rpy="0 0 0" xyz="0 -0.11 -0.245"/>
    <axis xyz="-1.0 -0.0 -0.0"/>
    <parent link="l_clav"/>
    <child link="l_scap"/>
    <dynamics damping="0.1" friction="0"/>
    <limit effort="99" lower="-1.5708" upper="1.5708" velocity="12"/>
    <safety_controller k_position="100" k_velocity="100" soft_lower_limit="-11.5708" soft_upper_limit="11.5708"/>
  </joint>
  <joint name="l_arm_shz" type="revolute">
    <origin rpy="0 0 3.14159265359" xyz="0.1406 0.2256 0.4776"/>
    <axis xyz="0 0 1"/>
    <parent link="utorso"/>
    <child link="l_clav"/>
    <dynamics damping="0.1" friction="0"/>
    <limit effort="87" lower="-1.5708" upper="0.785398" velocity="12"/>
    <safety_controller k_position="100" k_velocity="100" soft_lower_limit="-11.5708" soft_upper_limit="10.7854"/>
  </joint>
  <joint name="l_arm_mwx" type="revolute">
    <origin rpy="0 0 0" xyz="0 0 0"/>
    <axis xyz="1 0 0"/>
    <parent link="l_ufarm"/>
    <child link="l_lfarm"/>
    <dynamics damping="0.1" friction="0"/>
    <limit effort="25" lower="-1.7628" upper="1.7628" velocity="10"/>
    <safety_controller k_position="100" k_velocity="100" soft_lower_limit="-11.7628" soft_upper_limit="11.7628"/>
  </joint>
  <joint name="l_arm_uwy" type="revolute">
    <origin rpy="0 3.14159265359 0" xyz="0 -0.29955 -0.00921"/>
    <axis xyz="-0.0 -1.0 -0.0"/>
    <parent link="l_larm"/>
    <child link="l_ufarm"/>
    <dynamics damping="0.1" friction="0"/>
    <limit effort="25" lower="-3.011" upper="3.011" velocity="10"/>
    <safety_controller k_position="100" k_velocity="100" soft_lower_limit="-13.011" soft_upper_limit="13.011"/>
  </joint>
  <joint name="l_arm_lwy" type="revolute">
    <origin rpy="0 3.14159265359 0" xyz="0 0 0"/>
    <axis xyz="-0.0 -1.0 -0.0"/>
    <parent link="l_lfarm"/>
    <child link="l_hand"/>
    <dynamics damping="0.1" friction="0"/>
    <limit effort="25" lower="-2.9671" upper="2.9671" velocity="10"/>
    <safety_controller k_position="100" k_velocity="100" soft_lower_limit="-12.9671" soft_upper_limit="12.9671"/>
  </joint>
  <joint name="l_leg_akx" type="revolute">
    <origin rpy="0 0 0" xyz="0 0 0"/>
    <axis xyz="1 0 0"/>
    <parent link="l_talus"/>
    <child link="l_foot"/>
    <dynamics damping="0.1" friction="0"/>
    <limit effort="360" lower="-0.8" upper="0.8" velocity="12"/>
    <safety_controller k_position="100" k_velocity="100" soft_lower_limit="-10.8" soft_upper_limit="10.8"/>
  </joint>
  <joint name="l_leg_aky" type="revolute">
    <origin rpy="0 0 0" xyz="0 0 -0.422"/>
    <axis xyz="0 1 0"/>
    <parent link="l_lleg"/>
    <child link="l_talus"/>
    <dynamics damping="0.1" friction="0"/>
    <limit effort="740" lower="-1" upper="0.7" velocity="12"/>
    <safety_controller k_position="100" k_velocity="100" soft_lower_limit="-11" soft_upper_limit="10.7"/>
  </joint>
  <joint name="l_leg_hpx" type="revolute">
    <origin rpy="0 0 0" xyz="0 0 0"/>
    <axis xyz="1 0 0"/>
    <parent link="l_uglut"/>
    <child link="l_lglut"/>
    <dynamics damping="0.1" friction="0"/>
    <limit effort="530" lower="-0.523599" upper="0.523599" velocity="12"/>
    <safety_controller k_position="100" k_velocity="100" soft_lower_limit="-10.5236" soft_upper_limit="10.5236"/>
  </joint>
  <joint name="l_leg_hpy" type="revolute">
    <origin rpy="0 0 0" xyz="0.05 0.0225 -0.066"/>
    <axis xyz="0 1 0"/>
    <parent link="l_lglut"/>
    <child link="l_uleg"/>
    <dynamics damping="0.1" friction="0"/>
    <limit effort="840" lower="-1.61234" upper="0.65764" velocity="12"/>
    <safety_controller k_position="100" k_velocity="100" soft_lower_limit="-11.6123" soft_upper_limit="10.6576"/>
  </joint>
  <joint name="l_leg_hpz" type="revolute">
    <origin rpy="0 0 0" xyz="0 0.089 0"/>
    <axis xyz="0 0 1"/>
    <parent link="pelvis"/>
    <child link="l_uglut"/>
    <dynamics damping="0.1" friction="0"/>
    <limit effort="275" lower="-0.174358" upper="0.786794" velocity="12"/>
    <safety_controller k_position="100" k_velocity="100" soft_lower_limit="-10.1744" soft_upper_limit="10.7868"/>
  </joint>
  <joint name="l_leg_kny" type="revolute">
    <origin rpy="0 0 0" xyz="-0.05 0 -0.374"/>
    <axis xyz="0 1 0"/>
    <parent link="l_uleg"/>
    <child link="l_lleg"/>
    <dynamics damping="0.1" friction="0"/>
    <limit effort="890" lower="0" upper="2.35637" velocity="12"/>
    <safety_controller k_position="100" k_velocity="100" soft_lower_limit="-10" soft_upper_limit="12.3564"/>
  </joint>
  <joint name="neck_ay" type="revolute">
    <origin rpy="0 0 0" xyz="0.2546 0 0.6215"/>
    <axis xyz="0 1 0"/>
    <parent link="utorso"/>
    <child link="head"/>
    <dynamics damping="0.1" friction="0"/>
    <limit effort="25" lower="-0.602139" upper="1.14319" velocity="6.28"/>
    <safety_controller k_position="100" k_velocity="100" soft_lower_limit="-10.6021" soft_upper_limit="11.1432"/>
  </joint>
  <joint name="r_arm_elx" type="revolute">
    <origin rpy="0 0 0" xyz="0 -0.119 0.0092"/>
    <axis xyz="1 0 0"/>
    <parent link="r_uarm"/>
    <child link="r_larm"/>
    <dynamics damping="0.1" friction="0"/>
    <limit effort="112" lower="-2.35619" upper="0" velocity="12"/>
    <safety_controller k_position="100" k_velocity="100" soft_lower_limit="-12.3562" soft_upper_limit="10"/>
  </joint>
  <joint name="r_arm_ely" type="revolute">
    <origin rpy="0 0 0" xyz="0 -0.187 -0.016"/>
    <axis xyz="0 1 0"/>
    <parent link="r_scap"/>
    <child link="r_uarm"/>
    <dynamics damping="0.1" friction="0"/>
    <limit effort="63" lower="0" upper="3.14159" velocity="12"/>
    <safety_controller k_position="100" k_velocity="100" soft_lower_limit="-10" soft_upper_limit="13.1416"/>
  </joint>
  <joint name="r_arm_shx" type="revolute">
    <origin rpy="0 0 0" xyz="0 -0.11 -0.245"/>
    <axis xyz="1 0 0"/>
    <parent link="r_clav"/>
    <child link="r_scap"/>
    <dynamics damping="0.1" friction="0"/>
    <limit effort="99" lower="-1.5708" upper="1.5708" velocity="12"/>
    <safety_controller k_position="100" k_velocity="100" soft_lower_limit="-11.5708" soft_upper_limit="11.5708"/>
  </joint>
  <joint name="r_arm_shz" type="revolute">
    <origin rpy="0 0 0" xyz="0.1406 -0.2256 0.4776"/>
    <axis xyz="0 0 1"/>
    <parent link="utorso"/>
    <child link="r_clav"/>
    <dynamics damping="0.1" friction="0"/>
    <limit effort="87" lower="-0.785398" upper="1.5708" velocity="12"/>
    <safety_controller k_position="100" k_velocity="100" soft_lower_limit="-10.7854" soft_upper_limit="11.5708"/>
  </joint>
  <joint name="r_arm_mwx" type="revolute">
    <origin rpy="0 0 0" xyz="0 0 0"/>
    <axis xyz="1 0 0"/>
    <parent link="r_ufarm"/>
    <child link="r_lfarm"/>
    <dynamics damping="0.1" friction="0"/>
    <limit effort="25" lower="-1.7628" upper="1.7628" velocity="10"/>
    <safety_controller k_position="100" k_velocity="100" soft_lower_limit="-11.7628" soft_upper_limit="11.7628"/>
  </joint>
  <joint name="r_arm_uwy" type="revolute">
    <origin rpy="0 0 0" xyz="0 -0.29955 -0.00921"/>
    <axis xyz="0 1 0"/>
    <parent link="r_larm"/>
    <child link="r_ufarm"/>
    <dynamics damping="0.1" friction="0"/>
    <limit effort="25" lower="-3.011" upper="3.011" velocity="10"/>
    <safety_controller k_position="100" k_velocity="100" soft_lower_limit="-13.011" soft_upper_limit="13.011"/>
  </joint>
  <joint name="r_arm_lwy" type="revolute">
    <origin rpy="0 0 0" xyz="0 0 0"/>
    <axis xyz="0 1 0"/>
    <parent link="r_lfarm"/>
    <child link="r_hand"/>
    <dynamics damping="0.1" friction="0"/>
    <limit effort="25" lower="-2.9671" upper="2.9671" velocity="10"/>
    <safety_controller k_position="100" k_velocity="100" soft_lower_limit="-12.9671" soft_upper_limit="12.9671"/>
  </joint>
  <joint name="r_leg_akx" type="revolute">
    <origin rpy="0 0 0" xyz="0 0 0"/>
    <axis xyz="1 0 0"/>
    <parent link="r_talus"/>
    <child link="r_foot"/>
    <dynamics damping="0.1" friction="0"/>
    <limit effort="360" lower="-0.8" upper="0.8" velocity="12"/>
    <safety_controller k_position="100" k_velocity="100" soft_lower_limit="-10.8" soft_upper_limit="10.8"/>
  </joint>
  <joint name="r_leg_aky" type="revolute">
    <origin rpy="0 0 0" xyz="0 0 -0.422"/>
    <axis xyz="0 1 0"/>
    <parent link="r_lleg"/>
    <child link="r_talus"/>
    <dynamics damping="0.1" friction="0"/>
    <limit effort="740" lower="-1" upper="0.7" velocity="12"/>
    <safety_controller k_position="100" k_velocity="100" soft_lower_limit="-11" soft_upper_limit="10.7"/>
  </joint>
  <joint name="r_leg_hpx" type="revolute">
    <origin rpy="0 0 0" xyz="0 0 0"/>
    <axis xyz="1 0 0"/>
    <parent link="r_uglut"/>
    <child link="r_lglut"/>
    <dynamics damping="0.1" friction="0"/>
    <limit effort="530" lower="-0.523599" upper="0.523599" velocity="12"/>
    <safety_controller k_position="100" k_velocity="100" soft_lower_limit="-10.5236" soft_upper_limit="10.5236"/>
  </joint>
  <joint name="r_leg_hpy" type="revolute">
    <origin rpy="0 0 0" xyz="0.05 -0.0225 -0.066"/>
    <axis xyz="0 1 0"/>
    <parent link="r_lglut"/>
    <child link="r_uleg"/>
    <dynamics damping="0.1" friction="0"/>
    <limit effort="840" lower="-1.61234" upper="0.65764" velocity="12"/>
    <safety_controller k_position="100" k_velocity="100" soft_lower_limit="-11.6123" soft_upper_limit="10.6576"/>
  </joint> 
  <joint name="r_leg_hpz" type="revolute">
    <origin rpy="0 0 0" xyz="0 -0.089 0"/>
    <axis xyz="0 0 1"/>
    <parent link="pelvis"/>
    <child link="r_uglut"/>
    <dynamics damping="0.1" friction="0"/>
    <limit effort="275" lower="-0.786794" upper="0.174358" velocity="12"/>
    <safety_controller k_position="100" k_velocity="100" soft_lower_limit="-10.7868" soft_upper_limit="10.1744"/>
  </joint>
  <joint name="r_leg_kny" type="revolute">
    <origin rpy="0 0 0" xyz="-0.05 0 -0.374"/>
    <axis xyz="0 1 0"/>
    <parent link="r_uleg"/>
    <child link="r_lleg"/>
    <dynamics damping="0.1" friction="0"/>
    <limit effort="890" lower="0" upper="2.35637" velocity="12"/>
    <safety_controller k_position="100" k_velocity="100" soft_lower_limit="-10" soft_upper_limit="12.3564"/>
  </joint>
  <link name="head">
    <inertial>
      <origin rpy="0 0 0" xyz="-0.075493 3.3383E-05 0.02774"/>
      <mass value="1.0"/>
      <inertia ixx="0.1" ixy="0.0" ixz="0.0" iyy="0.1" iyz="0.0" izz="0.1"/>
    </inertial>
    <visual>
      <origin rpy="0 0 0" xyz="0 0 0"/>
      <geometry>
        <mesh filename="examples/examples_files/atlas_mesh/head_chull.obj"/>
      </geometry>
      <material name="">
        <color rgba="0.9098 0.44314 0.031373 1"/>
      </material>
    </visual>
  </link>

  <!-- Own origin addition -->
  <!-- <link name="base_link">	</link>
  <joint name="toOrigin" type="fixed">
    <origin rpy="0 0 0" xyz="0 0 0"/>
    <parent link="base_link"/>
    <child link="pelvis"/>
  </joint> -->
</robot>
