<?xml version="1.0"?>

<robot name="DoublePendulum">
	<link name="base_link">
	</link>

  <link name="link1">
    <inertial>
      <origin xyz="0 0 -0.5" rpy="1.5707963268 0. 0." />
      <mass value="1" />
      <inertia ixx=".0841667" ixy="0" ixz="0" iyy=".0841667" iyz="0" izz=".00166667" />
    </inertial>
    <visual>
      <origin xyz="0 0 -0.5" rpy="1.5707963268 0. 0." />
      <geometry>
         <!-- <cylinder length="1" radius=".05" /> -->
         <box size=".1 1 .1" />
      </geometry>
      <material name="green">
	       <color rgba="1 0 1 1" />
      </material>
    </visual>
  </link>

  <link name="link2">
    <inertial>
      <origin xyz="0 0.5 0." rpy="1.5707963268 0. 0." />
      <mass value="1" />
      <inertia ixx=".0841667" ixy="0" ixz="0" iyy=".0841667" iyz="0" izz=".00166667" />
    </inertial>
    <visual>
      <origin xyz="0 0.5 0." rpy="1.57 0 0." />
      <geometry>
         <box size="0.1 0.1 1" />
      </geometry>
      <material name="green">
	       <color rgba="1 0 0 1" />
      </material>
    </visual>
  </link>

	

	<joint name="joint1" type="continuous">
		<parent link="base_link" />
		<child link="link1" />
		<origin rpy="0.4 0 1.5707963268" xyz="0 1 0" />
		<axis xyz="1 0 0" />
	</joint>

  <joint name="joint2" type="continuous">
		<parent link="link1" />
		<child link="link2" />
		<origin rpy="0 0 1.5707963268" xyz="0 0 -1" />
		<axis xyz="1 0 0" />
	</joint>

	

</robot>
