<?xml version="0.0" ?>
<robot name="walker2d">
	<link name="link0_1">
		<inertial>
			<origin rpy="0.00000 -0.00000 0.00000" xyz="0.00000 0.00000 0.00000"/>
			<mass value="0.00000"/>
			<inertia ixx="0.00000" ixy="0" ixz="0" iyy="0.00000" iyz="0" izz="0.00000"/>
		</inertial>
	</link>
	<link name="link0_2">
		<inertial>
			<origin rpy="0.00000 -0.00000 0.00000" xyz="0.00000 0.00000 0.00000"/>
			<mass value="0.00000"/>
			<inertia ixx="0.00000" ixy="0" ixz="0" iyy="0.00000" iyz="0" izz="0.00000"/>
		</inertial>
	</link>
	<link name="link0_3">
		<inertial>
			<origin rpy="0.00000 -0.00000 0.00000" xyz="0.00000 0.00000 0.00000"/>
			<mass value="0.00000"/>
			<inertia ixx="0.00000" ixy="0" ixz="0" iyy="0.00000" iyz="0" izz="0.00000"/>
		</inertial>
	</link>
	<link name="link0_4">
		<inertial>
			<origin rpy="0.00000 -0.00000 0.00000" xyz="0.00000 0.00000 0.00000"/>
			<mass value="0.00000"/>
			<inertia ixx="0.00000" ixy="0" ixz="0" iyy="0.00000" iyz="0" izz="0.00000"/>
		</inertial>
	</link>
	<link name="torso">
		<inertial>
			<origin rpy="0.00000 -0.00000 0.00000" xyz="0.00000 0.00000 1.25000"/>
			<mass value="3.66519"/>
			<inertia ixx="0.07941" ixy="0" ixz="0" iyy="0.07941" iyz="0" izz="0.00611"/>
		</inertial>
		<collision>
			<origin rpy="3.14159 -0.00000 3.14159" xyz="0.00000 0.00000 1.25000"/>
			<geometry>
				<capsule length="0.40000" radius="0.05000"/>
			</geometry>
		</collision>
	</link>
	<link name="link0_6">
		<inertial>
			<origin rpy="0.00000 -0.00000 0.00000" xyz="0.00000 0.00000 0.00000"/>
			<mass value="0.00000"/>
			<inertia ixx="0.00000" ixy="0" ixz="0" iyy="0.00000" iyz="0" izz="0.00000"/>
		</inertial>
	</link>
	<link name="thigh">
		<inertial>
			<origin rpy="0.00000 -0.00000 0.00000" xyz="0.00000 0.00000 0.82500"/>
			<mass value="4.05789"/>
			<inertia ixx="0.10567" ixy="0" ixz="0" iyy="0.10567" iyz="0" izz="0.00676"/>
		</inertial>
		<collision>
			<origin rpy="3.14159 -0.00000 3.14159" xyz="0.00000 0.00000 0.82500"/>
			<geometry>
				<capsule length="0.45000" radius="0.05000"/>
			</geometry>
		</collision>
	</link>
	<link name="link0_8">
		<inertial>
			<origin rpy="0.00000 -0.00000 0.00000" xyz="0.00000 0.00000 0.00000"/>
			<mass value="0.00000"/>
			<inertia ixx="0.00000" ixy="0" ixz="0" iyy="0.00000" iyz="0" izz="0.00000"/>
		</inertial>
	</link>
	<link name="leg">
		<inertial>
			<origin rpy="0.00000 -0.00000 0.00000" xyz="0.00000 0.00000 0.35000"/>
			<mass value="2.78136"/>
			<inertia ixx="0.07945" ixy="0" ixz="0" iyy="0.07945" iyz="0" izz="0.00297"/>
		</inertial>
		<collision>
			<origin rpy="3.14159 -0.00000 3.14159" xyz="0.00000 0.00000 0.35000"/>
			<geometry>
				<capsule length="0.50000" radius="0.04000"/>
			</geometry>
		</collision>
	</link>
	<link name="link0_10">
		<inertial>
			<origin rpy="0.00000 -0.00000 0.00000" xyz="0.00000 0.00000 0.00000"/>
			<mass value="0.00000"/>
			<inertia ixx="0.00000" ixy="0" ixz="0" iyy="0.00000" iyz="0" izz="0.00000"/>
		</inertial>
	</link>
	<link name="foot">
		<inertial>
			<origin rpy="0.00000 -0.00000 0.00000" xyz="0.10000 0.00000 0.10000"/>
			<mass value="3.16673"/>
			<inertia ixx="0.00760" ixy="0" ixz="0" iyy="0.03082" iyz="0" izz="0.03082"/>
		</inertial>
		<collision>
			<origin rpy="0.00000 1.57080 -0.00000" xyz="0.10000 0.00000 0.10000"/>
			<geometry>
				<capsule length="0.20000" radius="0.06000"/>
			</geometry>
		</collision>
	</link>
	<link name="link0_12">
		<inertial>
			<origin rpy="0.00000 -0.00000 0.00000" xyz="0.00000 0.00000 0.00000"/>
			<mass value="0.00000"/>
			<inertia ixx="0.00000" ixy="0" ixz="0" iyy="0.00000" iyz="0" izz="0.00000"/>
		</inertial>
	</link>
	<link name="thigh_left">
		<inertial>
			<origin rpy="0.00000 -0.00000 0.00000" xyz="0.00000 0.00000 0.82500"/>
			<mass value="4.05789"/>
			<inertia ixx="0.10567" ixy="0" ixz="0" iyy="0.10567" iyz="0" izz="0.00676"/>
		</inertial>
		<collision>
			<origin rpy="3.14159 -0.00000 3.14159" xyz="0.00000 0.00000 0.82500"/>
			<geometry>
				<capsule length="0.45000" radius="0.05000"/>
			</geometry>
		</collision>
	</link>
	<link name="link0_14">
		<inertial>
			<origin rpy="0.00000 -0.00000 0.00000" xyz="0.00000 0.00000 0.00000"/>
			<mass value="0.00000"/>
			<inertia ixx="0.00000" ixy="0" ixz="0" iyy="0.00000" iyz="0" izz="0.00000"/>
		</inertial>
	</link>
	<link name="leg_left">
		<inertial>
			<origin rpy="0.00000 -0.00000 0.00000" xyz="0.00000 0.00000 0.35000"/>
			<mass value="2.78136"/>
			<inertia ixx="0.07945" ixy="0" ixz="0" iyy="0.07945" iyz="0" izz="0.00297"/>
		</inertial>
		<collision>
			<origin rpy="3.14159 -0.00000 3.14159" xyz="0.00000 0.00000 0.35000"/>
			<geometry>
				<capsule length="0.50000" radius="0.04000"/>
			</geometry>
		</collision>
	</link>
	<link name="link0_16">
		<inertial>
			<origin rpy="0.00000 -0.00000 0.00000" xyz="0.00000 0.00000 0.00000"/>
			<mass value="0.00000"/>
			<inertia ixx="0.00000" ixy="0" ixz="0" iyy="0.00000" iyz="0" izz="0.00000"/>
		</inertial>
	</link>
	<link name="foot_left">
		<inertial>
			<origin rpy="0.00000 -0.00000 0.00000" xyz="0.10000 0.00000 0.10000"/>
			<mass value="3.16673"/>
			<inertia ixx="0.00760" ixy="0" ixz="0" iyy="0.03082" iyz="0" izz="0.03082"/>
		</inertial>
		<collision>
			<origin rpy="0.00000 1.57080 -0.00000" xyz="0.10000 0.00000 0.10000"/>
			<geometry>
				<capsule length="0.20000" radius="0.06000"/>
			</geometry>
		</collision>
	</link>
	<joint name="ignorex" type="prismatic">
		<parent link="link0_1"/>
		<child link="link0_2"/>
<limit effort="1000.0" lower="-0.50000" upper="0.50000" velocity="0.5"/>		<dynamics damping="1.0" friction="0.0001"/>
		<origin rpy="0.00000 -0.00000 0.00000" xyz="0.00000 0.00000 0.00000"/>
		<axis xyz="1.00000 0.00000 0.00000"/>
	</joint>
	<joint name="ignorez" type="prismatic">
		<parent link="link0_2"/>
		<child link="link0_3"/>
<limit effort="1000.0" lower="-0.50000" upper="0.50000" velocity="0.5"/>		<dynamics damping="1.0" friction="0.0001"/>
		<origin rpy="0.00000 -0.00000 0.00000" xyz="0.00000 0.00000 0.00000"/>
		<axis xyz="0.00000 0.00000 1.00000"/>
	</joint>
	<joint name="ignorey" type="continuous">
		<parent link="link0_3"/>
		<child link="link0_4"/>
		<dynamics damping="1.0" friction="0.0001"/>
		<origin rpy="0.00000 -0.00000 0.00000" xyz="0.00000 0.00000 0.00000"/>
		<axis xyz="0.00000 1.00000 0.00000"/>
	</joint>
	<joint name="jointfix_6_4" type="fixed">
		<parent link="link0_4"/>
		<child link="torso"/>
		<dynamics damping="1.0" friction="0.0001"/>
		<origin rpy="0.00000 -0.00000 0.00000" xyz="0.00000 0.00000 0.00000"/>
		<axis xyz="0.00000 0.00000 0.00000"/>
	</joint>
	<joint name="thigh_joint" type="revolute">
		<parent link="torso"/>
		<child link="link0_6"/>
		<dynamics damping="1.0" friction="0.0001"/>
		<origin rpy="0.00000 -0.00000 0.00000" xyz="0.00000 0.00000 1.05000"/>
		<axis xyz="0.00000 -1.00000 0.00000"/>
	</joint>
	<joint name="jointfix_2_6" type="fixed">
		<parent link="link0_6"/>
		<child link="thigh"/>
		<dynamics damping="1.0" friction="0.0001"/>
		<origin rpy="0.00000 -0.00000 0.00000" xyz="0.00000 0.00000 -1.05000"/>
		<axis xyz="0.00000 0.00000 0.00000"/>
	</joint>
	<joint name="leg_joint" type="revolute">
		<parent link="thigh"/>
		<child link="link0_8"/>
		<dynamics damping="1.0" friction="0.0001"/>
		<origin rpy="0.00000 -0.00000 0.00000" xyz="0.00000 0.00000 0.60000"/>
		<axis xyz="0.00000 -1.00000 0.00000"/>
	</joint>
	<joint name="jointfix_1_8" type="fixed">
		<parent link="link0_8"/>
		<child link="leg"/>
		<dynamics damping="1.0" friction="0.0001"/>
		<origin rpy="0.00000 -0.00000 0.00000" xyz="0.00000 0.00000 -0.60000"/>
		<axis xyz="0.00000 0.00000 0.00000"/>
	</joint>
	<joint name="foot_joint" type="revolute">
		<parent link="leg"/>
		<child link="link0_10"/>
		<dynamics damping="1.0" friction="0.0001"/>
		<origin rpy="0.00000 -0.00000 0.00000" xyz="0.00000 0.00000 0.10000"/>
		<axis xyz="0.00000 -1.00000 0.00000"/>
	</joint>
	<joint name="jointfix_0_10" type="fixed">
		<parent link="link0_10"/>
		<child link="foot"/>
		<dynamics damping="1.0" friction="0.0001"/>
		<origin rpy="0.00000 -0.00000 0.00000" xyz="0.00000 0.00000 -0.10000"/>
		<axis xyz="0.00000 0.00000 0.00000"/>
	</joint>
	<joint name="thigh_left_joint" type="revolute">
		<parent link="torso"/>
		<child link="link0_12"/>
		<dynamics damping="1.0" friction="0.0001"/>
		<origin rpy="0.00000 -0.00000 0.00000" xyz="0.00000 0.00000 1.05000"/>
		<axis xyz="0.00000 -1.00000 0.00000"/>
	</joint>
	<joint name="jointfix_5_12" type="fixed">
		<parent link="link0_12"/>
		<child link="thigh_left"/>
		<dynamics damping="1.0" friction="0.0001"/>
		<origin rpy="0.00000 -0.00000 0.00000" xyz="0.00000 0.00000 -1.05000"/>
		<axis xyz="0.00000 0.00000 0.00000"/>
	</joint>
	<joint name="leg_left_joint" type="revolute">
		<parent link="thigh_left"/>
		<child link="link0_14"/>
		<dynamics damping="1.0" friction="0.0001"/>
		<origin rpy="0.00000 -0.00000 0.00000" xyz="0.00000 0.00000 0.60000"/>
		<axis xyz="0.00000 -1.00000 0.00000"/>
	</joint>
	<joint name="jointfix_4_14" type="fixed">
		<parent link="link0_14"/>
		<child link="leg_left"/>
		<dynamics damping="1.0" friction="0.0001"/>
		<origin rpy="0.00000 -0.00000 0.00000" xyz="0.00000 0.00000 -0.60000"/>
		<axis xyz="0.00000 0.00000 0.00000"/>
	</joint>
	<joint name="foot_left_joint" type="revolute">
		<parent link="leg_left"/>
		<child link="link0_16"/>
		<dynamics damping="1.0" friction="0.0001"/>
		<origin rpy="0.00000 -0.00000 0.00000" xyz="0.00000 0.00000 0.10000"/>
		<axis xyz="0.00000 -1.00000 0.00000"/>
	</joint>
	<joint name="jointfix_3_16" type="fixed">
		<parent link="link0_16"/>
		<child link="foot_left"/>
		<dynamics damping="1.0" friction="0.0001"/>
		<origin rpy="0.00000 -0.00000 0.00000" xyz="0.00000 0.00000 -0.10000"/>
		<axis xyz="0.00000 0.00000 0.00000"/>
	</joint>
</robot>
