<?xml version="1.0" ?>
<!-- =================================================================================== -->
<!-- |    This document was autogenerated by xacro from                                | -->
<!-- |    EDITING THIS FILE BY HAND IS NOT RECOMMENDED                                 | -->
<!-- =================================================================================== -->
<robot name="Exoskeleton">
	 
# output dir

	<!-- Human body -->
	<link name="base">
		<inertial>
			<origin rpy="0 0 0" xyz="0 0 1.15"/>
			<mass value="1"/>
			<inertia ixx="1" ixy="0" ixz="0" iyy="1" iyz="0" izz="1"/>
		</inertial>
		<visual>
			<origin rpy="0 0 1.5707963267948966" xyz="0.33 0.22 0.0"/>
			<geometry>
				<mesh filename="mesh/torso.obj" scale="0.027 0.027 0.027"/>
			</geometry>
			<material name="color_human">
				<color rgba="0.8 0.8 0.8 1.0"/>
			</material>
		</visual>
	</link>
	<!-- 3% of 75kg = 2.25 -->
	<link name="upper_arm">
		<inertial>
			<origin rpy="0 0 0" xyz="0 0 -0.155"/>
			<inertia ixx="0.01875" ixy="0" ixz="0" iyy="0.01875" iyz="0" izz="0.00375"/>
			<mass value="2.25"/>
		</inertial>
		<visual>
			<!-- x=up/down, y=side in/out, z=back/forward -->
			<origin rpy="0 3.1415926535897  1.5707963267948966" xyz="0.08499999999999999 -0.21999999999999986 0.8412999999999999"/>
			<geometry>
				<mesh filename="mesh/upperarm.obj" scale="0.027 0.027 0.027"/>
			</geometry>
			<material name="color_human">
				<color rgba="0.8 0.8 0.8 1.0"/>
			</material>
		</visual>
	</link>
	<!-- 2% of 75kg = 1.5 -->
	<link name="lower_arm">
		<inertial>
			<origin rpy="0 0 0" xyz="0 0.125 0"/>
			<inertia ixx="0.008515625" ixy="0" ixz="0" iyy="0.00140625" iyz="0" izz="0.008515625"/>
			<mass value="1.5"/>
		</inertial>
		<visual>
			<!-- x=up/down, y=side in/out, z=back/forward -->
			<origin rpy="0 -1.5707963267948966  1.5707963267948966" xyz="0.08499999999999999 0.8412999999999999 0.21999999999999986"/>
			<geometry>
				<mesh filename="mesh/lowerarm.obj" scale="0.027 0.027 0.027"/>
			</geometry>
			<material name="color_human">
				<color rgba="0.8 0.8 0.8 1.0"/>
			</material>
		</visual>
	</link>
	<link name="sAA_Unit">
		<inertial>
			<origin rpy="0 0 0" xyz="0 0.1301 -0.1279"/>
			<mass value="6.712"/>
			<inertia ixx="0.3787893" ixy="-0.0006556" ixz="-0.0006709" iyy="0.192833" iyz="0.0540633" izz="0.1956839"/>
		</inertial>
		<visual>
			<origin rpy="0 1.5707963267948966 0" xyz="0 0 -0.2"/>
			<geometry>
				<mesh filename="mesh/sAA_simple.obj" scale="0.001 0.001 0.001"/>
			</geometry>
			<material name="color_exo">
				<color rgba="0.4 0.4 0.4 1.0"/>
			</material>
		</visual>
	</link>
	<link name="sFE_Unit">
		<inertial>
			<origin rpy="0 0 0" xyz="0.0001 0.1051 -0.1201"/>
			<mass value="3.487"/>
			<inertia ixx="0.1108677" ixy="-0.0000977" ixz="0.0000399" iyy="0.0689688" iyz="0.0384741" izz="0.0569634"/>
		</inertial>
		<visual>
			<origin rpy="1.5707963267948966 3.1415926535897 1.5707963267948966" xyz="0 -0.215 0"/>
			<geometry>
				<mesh filename="mesh/sFE_simple.obj" scale="0.001 0.001 0.001"/>
			</geometry>
			<material name="color_exo">
				<color rgba="0.4 0.4 0.4 1.0"/>
			</material>
		</visual>
	</link>
	<link name="sIE_Unit">
		<inertial>
			<origin rpy="0 0 0" xyz="-0.0006 0.1079 -0.03"/>
			<mass value="1.663"/>
			<inertia ixx="0.0266938" ixy="0.0001282" ixz="-0.0000556" iyy="0.007941" iyz="0.0038772" izz="0.0235228"/>
		</inertial>
		<visual>
			<origin rpy="0 1.5707963267948966 0" xyz="0 0 -0.512"/>
			<geometry>
				<mesh filename="mesh/sIE_simple.obj" scale="0.001 0.001 0.001"/>
			</geometry>
			<material name="color_exo">
				<color rgba="0.4 0.4 0.4 1.0"/>
			</material>
		</visual>
	</link>
	<link name="eFE_Unit">
		<inertial>
			<origin rpy="0 0 0" xyz="0 0.0557 -0.0803"/>
			<mass value="0.494"/>
			<inertia ixx="0.0069974" ixy="-0.0000009" ixz="-0.0000004" iyy="0.0035498" iyz="0.001812" izz="0.0037622"/>
		</inertial>
		<visual>
			<origin rpy="-1.05 1.5707963267948966 0" xyz="0 0 -0.12"/>
			<geometry>
				<mesh filename="mesh/eFE_simple.obj" scale="0.001 0.001 0.001"/>
			</geometry>
			<material name="color_exo">
				<color rgba="0.4 0.4 0.4 1.0"/>
			</material>
		</visual>
	</link>
	<joint name="sAA" type="continuous">
		<parent link="base"/>
		<child link="sAA_Unit"/>
		<origin rpy="1.5707963267948966 0 1.5707963267948966" xyz="0.2483 0 1.15"/>
		<axis xyz="0 0 1"/>
	</joint>
	<joint name="sFE" type="continuous">
		<parent link="sAA_Unit"/>
		<child link="sFE_Unit"/>
		<origin rpy="1.5707963267948966 0 0" xyz="0 0 0"/>
		<axis xyz="0 0 1"/>
	</joint>
	<joint name="sIE" type="continuous">
		<parent link="sFE_Unit"/>
		<child link="sIE_Unit"/>
		<origin rpy="-1.5707963267948966 0 0" xyz="0 0.3087 0"/>
		<axis xyz="0 0 1"/>
	</joint>
	<joint name="eFE" type="continuous">
		<parent link="sIE_Unit"/>
		<child link="eFE_Unit"/>
		<origin rpy="1.5707963267948966 0 0" xyz="0 0 0"/>
		<axis xyz="0 0 1"/>
	</joint>
	<joint name="sIE_to_upper" type="fixed">
		<parent link="sIE_Unit"/>
		<child link="upper_arm"/>
		<origin rpy="0 0 0" xyz="0 0 0"/>
	</joint>
	<joint name="eFe_to_lower" type="fixed">
		<parent link="eFE_Unit"/>
		<child link="lower_arm"/>
		<origin rpy="0 0 0" xyz="0 0 0"/>
	</joint>
</robot>
