<?xml version="0.0" ?>
<robot name="swimmer">
	<link name="link1_1">
		<inertial>
			<origin rpy="0.00000 -0.00000 0.00000" xyz="0.00000 0.00000 0.00000"/>
			<mass value="0.00000"/>
			<inertia ixx="0.00000" ixy="0" ixz="0" iyy="0.00000" iyz="0" izz="0.00000"/>
		</inertial>
	</link>
	<link name="link1_2">
		<inertial>
			<origin rpy="0.00000 -0.00000 0.00000" xyz="0.00000 0.00000 0.00000"/>
			<mass value="0.00000"/>
			<inertia ixx="0.00000" ixy="0" ixz="0" iyy="0.00000" iyz="0" izz="0.00000"/>
		</inertial>
	</link>
	<link name="link1_3">
		<inertial>
			<origin rpy="0.00000 -0.00000 0.00000" xyz="0.00000 0.00000 0.00000"/>
			<mass value="0.00000"/>
			<inertia ixx="0.00000" ixy="0" ixz="0" iyy="0.00000" iyz="0" izz="0.00000"/>
		</inertial>
	</link>
	<link name="link1_4">
		<inertial>
			<origin rpy="0.00000 -0.00000 0.00000" xyz="0.00000 0.00000 0.00000"/>
			<mass value="0.00000"/>
			<inertia ixx="0.00000" ixy="0" ixz="0" iyy="0.00000" iyz="0" izz="0.00000"/>
		</inertial>
	</link>
	<link name="torso">
		<inertial>
			<origin rpy="0.00000 -0.00000 0.00000" xyz="1.00000 0.00000 0.00000"/>
			<mass value="35.60472"/>
			<inertia ixx="0.23736" ixy="0" ixz="0" iyy="4.39125" iyz="0" izz="4.39125"/>
		</inertial>
		<collision>
			<origin rpy="0.00000 -1.57080 0.00000" xyz="1.00000 0.00000 0.00000"/>
			<geometry>
				<capsule length="1.00000" radius="0.10000"/>
			</geometry>
		</collision>
	</link>
	<link name="link1_6">
		<inertial>
			<origin rpy="0.00000 -0.00000 0.00000" xyz="0.00000 0.00000 0.00000"/>
			<mass value="0.00000"/>
			<inertia ixx="0.00000" ixy="0" ixz="0" iyy="0.00000" iyz="0" izz="0.00000"/>
		</inertial>
	</link>
	<link name="mid">
		<inertial>
			<origin rpy="0.00000 -0.00000 0.00000" xyz="-0.50000 0.00000 0.00000"/>
			<mass value="35.60472"/>
			<inertia ixx="0.23736" ixy="0" ixz="0" iyy="4.39125" iyz="0" izz="4.39125"/>
		</inertial>
		<collision>
			<origin rpy="0.00000 -1.57080 0.00000" xyz="-0.50000 0.00000 0.00000"/>
			<geometry>
				<capsule length="1.00000" radius="0.10000"/>
			</geometry>
		</collision>
	</link>
	<link name="link1_8">
		<inertial>
			<origin rpy="0.00000 -0.00000 0.00000" xyz="0.00000 0.00000 0.00000"/>
			<mass value="0.00000"/>
			<inertia ixx="0.00000" ixy="0" ixz="0" iyy="0.00000" iyz="0" izz="0.00000"/>
		</inertial>
	</link>
	<link name="back">
		<inertial>
			<origin rpy="0.00000 -0.00000 0.00000" xyz="-0.50000 0.00000 0.00000"/>
			<mass value="35.60472"/>
			<inertia ixx="0.23736" ixy="0" ixz="0" iyy="4.39125" iyz="0" izz="4.39125"/>
		</inertial>
		<collision>
			<origin rpy="0.00000 -1.57080 0.00000" xyz="-0.50000 0.00000 0.00000"/>
			<geometry>
				<capsule length="1.00000" radius="0.10000"/>
			</geometry>
		</collision>
	</link>
	<joint name="slider1" type="prismatic">
		<parent link="link1_1"/>
		<child link="link1_2"/>
<limit effort="1000.0" lower="-0.50000" upper="0.50000" velocity="0.5"/>		<dynamics damping="1.0" friction="0.0001"/>
		<origin rpy="0.00000 -0.00000 0.00000" xyz="0.00000 0.00000 0.00000"/>
		<axis xyz="1.00000 0.00000 0.00000"/>
	</joint>
	<joint name="slider2" type="prismatic">
		<parent link="link1_2"/>
		<child link="link1_3"/>
<limit effort="1000.0" lower="-0.50000" upper="0.50000" velocity="0.5"/>		<dynamics damping="1.0" friction="0.0001"/>
		<origin rpy="0.00000 -0.00000 0.00000" xyz="0.00000 0.00000 0.00000"/>
		<axis xyz="0.00000 1.00000 0.00000"/>
	</joint>
	<joint name="rot" type="continuous">
		<parent link="link1_3"/>
		<child link="link1_4"/>
		<dynamics damping="1.0" friction="0.0001"/>
		<origin rpy="0.00000 -0.00000 0.00000" xyz="0.00000 0.00000 0.00000"/>
		<axis xyz="0.00000 0.00000 1.00000"/>
	</joint>
	<joint name="jointfix_2_4" type="fixed">
		<parent link="link1_4"/>
		<child link="torso"/>
		<dynamics damping="1.0" friction="0.0001"/>
		<origin rpy="0.00000 -0.00000 0.00000" xyz="0.00000 0.00000 0.00000"/>
		<axis xyz="0.00000 0.00000 0.00000"/>
	</joint>
	<joint name="rot2" type="revolute">
		<parent link="torso"/>
		<child link="link1_6"/>
		<dynamics damping="1.0" friction="0.0001"/>
		<origin rpy="0.00000 -0.00000 0.00000" xyz="0.50000 0.00000 0.00000"/>
		<axis xyz="0.00000 0.00000 1.00000"/>
	</joint>
	<joint name="jointfix_1_6" type="fixed">
		<parent link="link1_6"/>
		<child link="mid"/>
		<dynamics damping="1.0" friction="0.0001"/>
		<origin rpy="0.00000 -0.00000 0.00000" xyz="0.00000 0.00000 0.00000"/>
		<axis xyz="0.00000 0.00000 0.00000"/>
	</joint>
	<joint name="rot3" type="revolute">
		<parent link="mid"/>
		<child link="link1_8"/>
		<dynamics damping="1.0" friction="0.0001"/>
		<origin rpy="0.00000 -0.00000 0.00000" xyz="-1.00000 0.00000 0.00000"/>
		<axis xyz="0.00000 0.00000 1.00000"/>
	</joint>
	<joint name="jointfix_0_8" type="fixed">
		<parent link="link1_8"/>
		<child link="back"/>
		<dynamics damping="1.0" friction="0.0001"/>
		<origin rpy="0.00000 -0.00000 0.00000" xyz="0.00000 0.00000 0.00000"/>
		<axis xyz="0.00000 0.00000 0.00000"/>
	</joint>
</robot>
