<?xml version="1.0" encoding="utf-8"?>
<!-- =================================================================================== -->
<!-- |    This document was autogenerated by xacro from pelican.xacro                  | -->
<!-- |    EDITING THIS FILE BY HAND IS NOT RECOMMENDED                                 | -->
<!-- =================================================================================== -->
<!--
  Copyright 2015 Fadri Furrer, ASL, ETH Zurich, Switzerland
  Copyright 2015 Michael Burri, ASL, ETH Zurich, Switzerland
  Copyright 2015 Mina Kamel, ASL, ETH Zurich, Switzerland
  Copyright 2015 Janosch Nikolic, ASL, ETH Zurich, Switzerland
  Copyright 2015 Markus Achtelik, ASL, ETH Zurich, Switzerland

  Licensed under the Apache License, Version 2.0 (the "License");
  you may not use this file except in compliance with the License.
  You may obtain a copy of the License at

  http://www.apache.org/licenses/LICENSE-2.0

  Unless required by applicable law or agreed to in writing, software
  distributed under the License is distributed on an "AS IS" BASIS,
  WITHOUT WARRANTIES OR CONDITIONS OF ANY KIND, either express or implied.
  See the License for the specific language governing permissions and
  limitations under the License.
-->
<robot name="pelican">
  <material name="black">
    <color rgba="0.2 0.2 0.2 1"/>
  </material>
  <material name="white">
    <color rgba="0.90 0.90 0.90 1.0"/>
  </material>

  <link name="base_link">
    <inertial>
      <mass value="1.0"/>
      <!-- [kg] -->
      <origin xyz="0 0 0"/>
      <inertia ixx="0.01" ixy="0.0" ixz="0.0" iyy="0.01" iyz="0.0" izz="0.02"/>
    </inertial>
    <visual>
      <origin rpy="0 0 0" xyz="0 0 0"/>
      <geometry>
        <mesh filename="mesh/pelican.obj" scale="1 1 1"/>
      </geometry>
      <material name="black"/>
    </visual>
    <collision>
      <origin rpy="0 0 0" xyz="0 0 0"/>
      <geometry>
        <box size="0.1 0.1 0.2"/>
        <!-- [m] [m] [m] -->
      </geometry>
    </collision>
  </link>
  <joint name="rotor_0_joint" type="continuous">
    <origin rpy="0 0 0" xyz="0.21 0 0.05"/>
    <axis xyz="0 0 1"/>
    <!-- TODO(ff): not currently set because it's not yet supported -->
    <!-- <limit effort="2000" velocity="${max_rot_velocity}" /> -->
    <parent link="base_link"/>
    <child link="rotor_0"/>
  </joint>
  <link name="rotor_0">
    <inertial>
      <mass value="0.01"/>
      <!-- [kg] -->
      <inertia ixx="1.94999922e-06" ixy="0.0" ixz="0.0" iyy="0.00013660827869" iyz="0.0" izz="0.00013840827797"/>
    </inertial>
    <visual>
      <geometry>
        <mesh filename="mesh/propeller_cw.obj" scale="0.128 0.128 0.128"/>
        <!-- The propeller meshes have a radius of 1m -->
        <!-- <box size="${2*radius_rotor} 0.01 0.005"/> -->
      </geometry>
      <material name="white"/>
    </visual>
    <collision>
      <geometry>
        <cylinder length="0.005" radius="0.128"/>
        <!-- [m] -->
      </geometry>
    </collision>
  </link>
  <joint name="rotor_1_joint" type="continuous">
    <origin rpy="0 0 0" xyz="0 0.21 0.05"/>
    <axis xyz="0 0 1"/>
    <!-- TODO(ff): not currently set because it's not yet supported -->
    <!-- <limit effort="2000" velocity="${max_rot_velocity}" /> -->
    <parent link="base_link"/>
    <child link="rotor_1"/>
  </joint>
  <link name="rotor_1">
    <inertial>
      <mass value="0.01"/>
      <!-- [kg] -->
      <inertia ixx="1.94999922e-06" ixy="0.0" ixz="0.0" iyy="0.00013660827869" iyz="0.0" izz="0.00013840827797"/>
    </inertial>
    <visual>
      <geometry>
        <mesh filename="mesh/propeller_ccw.obj" scale="0.128 0.128 0.128"/>
        <!-- The propeller meshes have a radius of 1m -->
        <!-- <box size="${2*radius_rotor} 0.01 0.005"/> -->
      </geometry>
      <material name="white"/>
    </visual>
    <collision>
      <geometry>
        <cylinder length="0.005" radius="0.128"/>
        <!-- [m] -->
      </geometry>
    </collision>
  </link>
  <joint name="rotor_2_joint" type="continuous">
    <origin rpy="0 0 0" xyz="-0.21 0 0.05"/>
    <axis xyz="0 0 1"/>
    <!-- TODO(ff): not currently set because it's not yet supported -->
    <!-- <limit effort="2000" velocity="${max_rot_velocity}" /> -->
    <parent link="base_link"/>
    <child link="rotor_2"/>
  </joint>
  <link name="rotor_2">
    <inertial>
      <mass value="0.01"/>
      <!-- [kg] -->
      <inertia ixx="1.94999922e-06" ixy="0.0" ixz="0.0" iyy="0.00013660827869" iyz="0.0" izz="0.00013840827797"/>
    </inertial>
    <visual>
      <geometry>
        <mesh filename="mesh/propeller_cw.obj" scale="0.128 0.128 0.128"/>
        <!-- The propeller meshes have a radius of 1m -->
        <!-- <box size="${2*radius_rotor} 0.01 0.005"/> -->
      </geometry>
      <material name="white"/>
    </visual>
    <collision>
      <geometry>
        <cylinder length="0.005" radius="0.128"/>
        <!-- [m] -->
      </geometry>
    </collision>
  </link>
  <joint name="rotor_3_joint" type="continuous">
    <origin rpy="0 0 0" xyz="0 -0.21 0.05"/>
    <axis xyz="0 0 1"/>
    <!-- TODO(ff): not currently set because it's not yet supported -->
    <!-- <limit effort="2000" velocity="${max_rot_velocity}" /> -->
    <parent link="base_link"/>
    <child link="rotor_3"/>
  </joint>
  <link name="rotor_3">
    <inertial>
      <mass value="0.01"/>
      <!-- [kg] -->
      <inertia ixx="1.94999922e-06" ixy="0.0" ixz="0.0" iyy="0.00013660827869" iyz="0.0" izz="0.00013840827797"/>
    </inertial>
    <visual>
      <geometry>
        <mesh filename="mesh/propeller_ccw.obj" scale="0.128 0.128 0.128"/>
        <!-- The propeller meshes have a radius of 1m -->
        <!-- <box size="${2*radius_rotor} 0.01 0.005"/> -->
      </geometry>
      <material name="white"/>
    </visual>
    <collision>
      <geometry>
        <cylinder length="0.005" radius="0.128"/>
        <!-- [m] -->
      </geometry>
    </collision>
  </link>
</robot>

