<?xml version="1.0" ?>
<robot name="ant">
	<link name="torso">
		<inertial>
			<origin rpy="0.00000 -0.00000 0.00000" xyz="0.00000 0.00000 0.00000"/>
			<mass value="0.32724923474893675"/>
			<inertia ixx="0.00818123" ixy="0" ixz="0" iyy="0.00818123" iyz="0" izz="0.00818123"/>
		</inertial>
		<collision>
			<origin rpy="0.00000 -0.00000 0.00000" xyz="0.00000 0.00000 0.00000"/>
			<geometry>
				<sphere radius="0.25000"/>
			</geometry>
		</collision>
		<visual>
			<origin rpy="0.00000 -0.00000 0.00000" xyz="0.00000 0.00000 0.00000"/>
			<geometry>
				<sphere radius="0.25000"/>
			</geometry>
		</visual>
	</link>
	<link name="front_left_leg">
		<inertial>
			<origin rpy="0.00000 -0.00000 0.00000" xyz="0.10000 0.10000 0.00000"/>
			<mass value="0.03647692799740343"/>
			<inertia ixx="0.00045856" ixy="0" ixz="0" iyy="0.00045856" iyz="0" izz="0.000116726"/>
		</inertial>
		<collision>
			<origin rpy="-1.57080 0.78540 -0.78540" xyz="0.10000 0.10000 0.00000"/>
			<geometry>
				<capsule length="0.28284" radius="0.08000"/>
			</geometry>
		</collision>
		<visual>
			<origin rpy="-1.57080 0.78540 -0.78540" xyz="0.10000 0.10000 0.00000"/>
			<geometry>
				<capsule length="0.28284" radius="0.08000"/>
			</geometry>
		</visual>
	</link>
	<link name="aux_1">
		<inertial>
			<origin rpy="0.00000 -0.00000 0.00000" xyz="0.10000 0.10000 0.00000"/>
			<mass value="0.03647692799740343"/>
			<inertia ixx="0.00045856" ixy="0" ixz="0" iyy="0.00045856" iyz="0" izz="0.000116726"/>
		</inertial>
		<collision>
			<origin rpy="-1.57080 0.78540 -0.78540" xyz="0.10000 0.10000 0.00000"/>
			<geometry>
				<capsule length="0.28284" radius="0.08000"/>
			</geometry>
		</collision>
		<visual>
			<origin rpy="-1.57080 0.78540 -0.78540" xyz="0.10000 0.10000 0.00000"/>
			<geometry>
				<capsule length="0.28284" radius="0.08000"/>
			</geometry>
		</visual>
	</link>
	<link name="front_left_foot">
		<inertial>
			<origin rpy="0.00000 -0.00000 0.00000" xyz="0.20000 0.20000 0.00000"/>
			<mass value="0.06491137880161697"/>
			<inertia ixx="0.00235904" ixy="0" ixz="0" iyy="0.00235904" iyz="0" izz="0.000207716"/>
		</inertial>
		<collision>
			<origin rpy="-1.57080 0.78540 -0.78540" xyz="0.20000 0.20000 0.00000"/>
			<geometry>
				<capsule length="0.56569" radius="0.08000"/>
			</geometry>
		</collision>
		<visual>
			<origin rpy="-1.57080 0.78540 -0.78540" xyz="0.20000 0.20000 0.00000"/>
			<geometry>
				<capsule length="0.56569" radius="0.08000"/>
			</geometry>
		</visual>
	</link>
	<link name="front_right_leg">
		<inertial>
			<origin rpy="0.00000 -0.00000 0.00000" xyz="-0.10000 0.10000 0.00000"/>
			<mass value="0.03647692799740343"/>
			<inertia ixx="0.00045856" ixy="0" ixz="0" iyy="0.00045856" iyz="0" izz="0.000116726"/>
		</inertial>
		<collision>
			<origin rpy="-1.57080 -0.78540 0.78540" xyz="-0.10000 0.10000 0.00000"/>
			<geometry>
				<capsule length="0.28284" radius="0.08000"/>
			</geometry>
		</collision>
		<visual>
			<origin rpy="-1.57080 -0.78540 0.78540" xyz="-0.10000 0.10000 0.00000"/>
			<geometry>
				<capsule length="0.28284" radius="0.08000"/>
			</geometry>
		</visual>
	</link>
	<link name="aux_2">
		<inertial>
			<origin rpy="0.00000 -0.00000 0.00000" xyz="-0.10000 0.10000 0.00000"/>
			<mass value="0.03647692799740343"/>
			<inertia ixx="0.00045856" ixy="0" ixz="0" iyy="0.00045856" iyz="0" izz="0.000116726"/>
		</inertial>
		<collision>
			<origin rpy="-1.57080 -0.78540 0.78540" xyz="-0.10000 0.10000 0.00000"/>
			<geometry>
				<capsule length="0.28284" radius="0.08000"/>
			</geometry>
		</collision>
		<visual>
			<origin rpy="-1.57080 -0.78540 0.78540" xyz="-0.10000 0.10000 0.00000"/>
			<geometry>
				<capsule length="0.28284" radius="0.08000"/>
			</geometry>
		</visual>
	</link>
	<link name="front_right_foot">
		<inertial>
			<origin rpy="0.00000 -0.00000 0.00000" xyz="-0.20000 0.20000 0.00000"/>
			<mass value="0.06491137880161697"/>
			<inertia ixx="0.00235904" ixy="0" ixz="0" iyy="0.00235904" iyz="0" izz="0.000207716"/>
		</inertial>
		<collision>
			<origin rpy="-1.57080 -0.78540 0.78540" xyz="-0.20000 0.20000 0.00000"/>
			<geometry>
				<capsule length="0.56569" radius="0.08000"/>
			</geometry>
		</collision>
		<visual>
			<origin rpy="-1.57080 -0.78540 0.78540" xyz="-0.20000 0.20000 0.00000"/>
			<geometry>
				<capsule length="0.56569" radius="0.08000"/>
			</geometry>
		</visual>
	</link>
	<link name="left_back_leg">
		<inertial>
			<origin rpy="0.00000 -0.00000 0.00000" xyz="-0.10000 -0.10000 0.00000"/>
			<mass value="0.03647692799740343"/>
			<inertia ixx="0.00045856" ixy="0" ixz="0" iyy="0.00045856" iyz="0" izz="0.000116726"/>
		</inertial>
		<collision>
			<origin rpy="1.57080 -0.78540 -0.78540" xyz="-0.10000 -0.10000 0.00000"/>
			<geometry>
				<capsule length="0.28284" radius="0.08000"/>
			</geometry>
		</collision>
		<visual>
			<origin rpy="1.57080 -0.78540 -0.78540" xyz="-0.10000 -0.10000 0.00000"/>
			<geometry>
				<capsule length="0.28284" radius="0.08000"/>
			</geometry>
		</visual>
	</link>
	<link name="aux_3">
		<inertial>
			<origin rpy="0.00000 -0.00000 0.00000" xyz="-0.10000 -0.10000 0.00000"/>
			<mass value="0.03647692799740343"/>
			<inertia ixx="0.00045856" ixy="0" ixz="0" iyy="0.00045856" iyz="0" izz="0.000116726"/>
		</inertial>
		<collision>
			<origin rpy="1.57080 -0.78540 -0.78540" xyz="-0.10000 -0.10000 0.00000"/>
			<geometry>
				<capsule length="0.28284" radius="0.08000"/>
			</geometry>
		</collision>
		<visual>
			<origin rpy="1.57080 -0.78540 -0.78540" xyz="-0.10000 -0.10000 0.00000"/>
			<geometry>
				<capsule length="0.28284" radius="0.08000"/>
			</geometry>
		</visual>
	</link>
	<link name="left_back_foot">
		<inertial>
			<origin rpy="0.00000 -0.00000 0.00000" xyz="-0.20000 -0.20000 0.00000"/>
			<mass value="0.06491137880161697"/>
			<inertia ixx="0.00235904" ixy="0" ixz="0" iyy="0.00235904" iyz="0" izz="0.000207716"/>
		</inertial>
		<collision>
			<origin rpy="1.57080 -0.78540 -0.78540" xyz="-0.20000 -0.20000 0.00000"/>
			<geometry>
				<capsule length="0.56569" radius="0.08000"/>
			</geometry>
		</collision>
		<visual>
			<origin rpy="1.57080 -0.78540 -0.78540" xyz="-0.20000 -0.20000 0.00000"/>
			<geometry>
				<capsule length="0.56569" radius="0.08000"/>
			</geometry>
		</visual>
	</link>
	<link name="right_back_leg">
		<inertial>
			<origin rpy="0.00000 -0.00000 0.00000" xyz="0.10000 -0.10000 0.00000"/>
			<mass value="0.03647692799740343"/>
			<inertia ixx="0.00045856" ixy="0" ixz="0" iyy="0.00045856" iyz="0" izz="0.000116726"/>
		</inertial>
		<collision>
			<origin rpy="1.57080 0.78540 0.78540" xyz="0.10000 -0.10000 0.00000"/>
			<geometry>
				<capsule length="0.28284" radius="0.08000"/>
			</geometry>
		</collision>
		<visual>
			<origin rpy="1.57080 0.78540 0.78540" xyz="0.10000 -0.10000 0.00000"/>
			<geometry>
				<capsule length="0.28284" radius="0.08000"/>
			</geometry>
		</visual>
	</link>
	<link name="aux_4">
		<inertial>
			<origin rpy="0.00000 -0.00000 0.00000" xyz="0.10000 -0.10000 0.00000"/>
			<mass value="0.03647692799740343"/>
			<inertia ixx="0.00045856" ixy="0" ixz="0" iyy="0.00045856" iyz="0" izz="0.000116726"/>
		</inertial>
		<collision>
			<origin rpy="1.57080 0.78540 0.78540" xyz="0.10000 -0.10000 0.00000"/>
			<geometry>
				<capsule length="0.28284" radius="0.08000"/>
			</geometry>
		</collision>
		<visual>
			<origin rpy="1.57080 0.78540 0.78540" xyz="0.10000 -0.10000 0.00000"/>
			<geometry>
				<capsule length="0.28284" radius="0.08000"/>
			</geometry>
		</visual>
	</link>
	<link name="right_back_foot">
		<inertial>
			<origin rpy="0.00000 -0.00000 0.00000" xyz="0.20000 -0.20000 0.00000"/>
			<mass value="0.06491137880161697"/>
			<inertia ixx="0.00235904" ixy="0" ixz="0" iyy="0.00235904" iyz="0" izz="0.000207716"/>
		</inertial>
		<collision>
			<origin rpy="1.57080 0.78540 0.78540" xyz="0.20000 -0.20000 0.00000"/>
			<geometry>
				<capsule length="0.56569" radius="0.08000"/>
			</geometry>
		</collision>
		<visual>
			<origin rpy="1.57080 0.78540 0.78540" xyz="0.20000 -0.20000 0.00000"/>
			<geometry>
				<capsule length="0.56569" radius="0.08000"/>
			</geometry>
		</visual>
	</link>
	<joint name="hip_1" type="revolute">
		<parent link="torso"/>
		<child link="front_left_leg"/>
		<dynamics damping="1.0" friction="0.0001"/>
		<origin rpy="0.00000 -0.00000 0.00000" xyz="0.20000 0.20000 0.00000"/>
		<axis xyz="0.00000 0.00000 1.00000"/>
	</joint>
	<joint name="ankle_1" type="revolute">
		<parent link="front_left_leg"/>
		<child link="aux_1"/>
		<dynamics damping="1.0" friction="0.0001"/>
		<origin rpy="0.00000 -0.00000 0.00000" xyz="0.20000 0.20000 0.00000"/>
		<axis xyz="-1.00000 1.00000 0.00000"/>
	</joint>
	<joint name="jointfix_0_5" type="fixed">
		<parent link="aux_1"/>
		<child link="front_left_foot"/>
		<dynamics damping="1.0" friction="0.0001"/>
		<origin rpy="0.00000 -0.00000 0.00000" xyz="0.00000 0.00000 0.00000"/>
		<axis xyz="0.00000 0.00000 0.00000"/>
	</joint>
	<joint name="hip_2" type="revolute">
		<parent link="torso"/>
		<child link="front_right_leg"/>
		<dynamics damping="1.0" friction="0.0001"/>
		<origin rpy="0.00000 -0.00000 0.00000" xyz="-0.20000 0.20000 0.00000"/>
		<axis xyz="0.00000 0.00000 1.00000"/>
	</joint>
	<joint name="ankle_2" type="revolute">
		<parent link="front_right_leg"/>
		<child link="aux_2"/>
		<dynamics damping="1.0" friction="0.0001"/>
		<origin rpy="0.00000 -0.00000 0.00000" xyz="-0.20000 0.20000 0.00000"/>
		<axis xyz="1.00000 1.00000 0.00000"/>
	</joint>
	<joint name="jointfix_3_10" type="fixed">
		<parent link="aux_2"/>
		<child link="front_right_foot"/>
		<dynamics damping="1.0" friction="0.0001"/>
		<origin rpy="0.00000 -0.00000 0.00000" xyz="0.00000 0.00000 0.00000"/>
		<axis xyz="0.00000 0.00000 0.00000"/>
	</joint>
	<joint name="hip_3" type="revolute">
		<parent link="torso"/>
		<child link="left_back_leg"/>
		<dynamics damping="1.0" friction="0.0001"/>
		<origin rpy="0.00000 -0.00000 0.00000" xyz="-0.20000 -0.20000 0.00000"/>
		<axis xyz="0.00000 0.00000 1.00000"/>
	</joint>
	<joint name="ankle_3" type="revolute">
		<parent link="left_back_leg"/>
		<child link="aux_3"/>
		<dynamics damping="1.0" friction="0.0001"/>
		<origin rpy="0.00000 -0.00000 0.00000" xyz="-0.20000 -0.20000 0.00000"/>
		<axis xyz="-1.00000 1.00000 0.00000"/>
	</joint>
	<joint name="jointfix_6_15" type="fixed">
		<parent link="aux_3"/>
		<child link="left_back_foot"/>
		<dynamics damping="1.0" friction="0.0001"/>
		<origin rpy="0.00000 -0.00000 0.00000" xyz="0.00000 0.00000 0.00000"/>
		<axis xyz="0.00000 0.00000 0.00000"/>
	</joint>
	<joint name="hip_4" type="revolute">
		<parent link="torso"/>
		<child link="right_back_leg"/>
		<dynamics damping="1.0" friction="0.0001"/>
		<origin rpy="0.00000 -0.00000 0.00000" xyz="0.20000 -0.20000 0.00000"/>
		<axis xyz="0.00000 0.00000 1.00000"/>
	</joint>
	<joint name="ankle_4" type="revolute">
		<parent link="right_back_leg"/>
		<child link="aux_4"/>
		<dynamics damping="1.0" friction="0.0001"/>
		<origin rpy="0.00000 -0.00000 0.00000" xyz="0.20000 -0.20000 0.00000"/>
		<axis xyz="1.00000 1.00000 0.00000"/>
	</joint>
	<joint name="jointfix_9_20" type="fixed">
		<parent link="aux_4"/>
		<child link="right_back_foot"/>
		<dynamics damping="1.0" friction="0.0001"/>
		<origin rpy="0.00000 -0.00000 0.00000" xyz="0.00000 0.00000 0.00000"/>
		<axis xyz="0.00000 0.00000 0.00000"/>
	</joint>
</robot>
