<?xml version="1.0" ?>
<!-- =================================================================================== -->
<!-- |    This document was autogenerated by xacro from  							   | -->
<!-- |    EDITING THIS FILE BY HAND IS NOT RECOMMENDED                                 | -->
<!-- =================================================================================== -->
<robot name="youbot" xmlns:controller="http://playerstage.sourceforge.net/gazebo/xmlschema/#controller" xmlns:interface="http://playerstage.sourceforge.net/gazebo/xmlschema/#interface" xmlns:sensor="http://playerstage.sourceforge.net/gazebo/xmlschema/#sensor">
	&gt;

	<gazebo>
		<plugin filename="libgazebo_ros_control.so" name="gazebo_ros_controller">
			<robotSimType>gazebo_ros_control/DefaultRobotHWSim</robotSimType>
			<legacyModeNS>true</legacyModeNS>
		</plugin>
	</gazebo>
	<material name="youBot/Orange">
		<color rgba="1.0 0.4 0.0 1.0"/>
	</material>
	<material name="youBot/Grey">
		<color rgba="0.7 0.7 0.7 1.0"/>
	</material>
	<material name="youBot/DarkGrey">
		<color rgba="0.3 0.3 0.3 1.0"/>
	</material>
	<material name="youBot/White">
		<color rgba="1.0 1.0 1.0 1.0"/>
	</material>
	<material name="youBot/Black">
		<color rgba="0.0 0.0 0.0 1.0"/>
	</material>
	<material name="youBot/Red">
		<color rgba="1.0 0.0 0.0 1.0"/>
	</material>
	<material name="youBot/Green">
		<color rgba="0.0 1.0 0.0 1.0"/>
	</material>
	<material name="youBot/Blue">
		<color rgba="0.0 0.0 0.8 1.0"/>
	</material>
	<material name="youBot/LightGrey">
		<color rgba="0.82 0.82 0.82 1.0"/>
	</material>
	
	<link name="base_footprint"/>
	<joint name="base_footprint_joint" type="fixed">
		<origin rpy="0 0 0" xyz="0 0 0"/>
		<child link="base_link"/>
		<parent link="base_footprint"/>
	</joint>
	<link name="base_link">
		<inertial>
			<mass value="22.0"/>
			<origin xyz="0 0 0"/>
			<inertia ixx="5.652232699207" ixy="-0.009719934438" ixz="1.293988226423" iyy="5.669473158652" iyz="-0.007379583694" izz="3.683196351726"/>
		</inertial>
		<visual>
			<origin rpy="0 0 0" xyz="0 0 0"/>
			<geometry>
				<mesh filename="meshes/youbot_base/base.dae"/>
			</geometry>
			<material name="youBot/DarkGrey"/>
		</visual>
		<collision>
			<origin rpy="0 0 0" xyz="0 0 0"/>
			<geometry>
				<!--<box size="${base_size_x} ${base_size_y} ${base_size_z}" />-->
				<mesh filename="meshes/youbot_base/base_convex.dae"/>
			</geometry>
		</collision>
	</link>
	<!-- front left wheel -->
	<joint name="caster_joint_fl" type="continuous">
		<origin rpy="0 0 0" xyz="0.228 0.158 -0.034"/>
		<axis xyz="0 0 1"/>
		<limit effort="30" velocity="10"/>
		<dynamics damping="1.0" friction="1.0"/>
		<safety_controller k_velocity="10.0"/>
		<parent link="base_link"/>
		<child link="caster_link_fl"/>
	</joint>
	<link name="caster_link_fl">
		<inertial>
			<mass value="0.1"/>
			<origin xyz="0 0 0"/>
			<inertia ixx="0.012411765597" ixy="-0.000711733678" ixz="0.00050272983" iyy="0.015218160428" iyz="-0.000004273467" izz="0.011763977943"/>
		</inertial>
	</link>
	<joint name="wheel_joint_fl" type="continuous">
		<axis xyz="0 1 0"/>
		<limit effort="30" velocity="10"/>
		<origin rpy="0 0 0" xyz="0.0 0.0 0.0"/>
		<parent link="caster_link_fl"/>
		<dynamics damping="1.0" friction="1.0"/>
		<safety_controller k_velocity="10.0"/>
		<child link="wheel_link_fl"/>
	</joint>
	<link name="wheel_link_fl">
		<inertial>
			<mass value="1.4"/>
			<origin xyz="0 0 0"/>
			<inertia ixx="0.012411765597" ixy="-0.000711733678" ixz="0.00050272983" iyy="0.015218160428" iyz="-0.000004273467" izz="0.011763977943"/>
		</inertial>
		<visual>
			<origin rpy="0 0 0" xyz="0 0 0"/>
			<geometry>
				<mesh filename="meshes/youbot_base/front_left_wheel.dae" />
				<!-- <sphere radius="0.0475"/> -->
			</geometry>
			<material name="youBot/Orange"/>
		</visual>
		<collision>
			<origin rpy="1.5707963267948966 0 0" xyz="0 0 0"/>
			<geometry>
				<cylinder length="0.0475" radius="0.0475"/>
			</geometry>
		</collision>
	</link>
	<!-- front right wheel -->
	<joint name="caster_joint_fr" type="continuous">
		<origin rpy="0 0 0" xyz="0.228 -0.158 -0.034"/>
		<axis xyz="0 0 1"/>
		<limit effort="30" velocity="10"/>
		<dynamics damping="1.0" friction="1.0"/>
		<safety_controller k_velocity="10.0"/>
		<parent link="base_link"/>
		<child link="caster_link_fr"/>
	</joint>
	<link name="caster_link_fr">
		<inertial>
			<mass value="0.1"/>
			<origin xyz="0 0 0"/>
			<inertia ixx="0.012411765597" ixy="-0.000711733678" ixz="0.00050272983" iyy="0.015218160428" iyz="-0.000004273467" izz="0.011763977943"/>
		</inertial>
	</link>
	<joint name="wheel_joint_fr" type="continuous">
		<axis xyz="0 1 0"/>
		<limit effort="30" velocity="10"/>
		<dynamics damping="1.0" friction="1.0"/>
		<safety_controller k_velocity="10.0"/>
		<origin rpy="0 0 0" xyz="0.0 0.0 0.0"/>
		<parent link="caster_link_fr"/>
		<child link="wheel_link_fr"/>
	</joint>
	<link name="wheel_link_fr">
		<inertial>
			<mass value="1.4"/>
			<origin xyz="0 0 0"/>
			<inertia ixx="0.012411765597" ixy="-0.000711733678" ixz="0.00050272983" iyy="0.015218160428" iyz="-0.000004273467" izz="0.011763977943"/>
		</inertial>
		<visual>
			<origin rpy="0 0 0" xyz="0 0 0"/>
			<geometry>
				<mesh filename="meshes/youbot_base/front_right_wheel.dae" />
				<!-- <sphere radius="0.0475"/> -->
			</geometry>
			<material name="youBot/Orange"/>
		</visual>
		<collision>
			<origin rpy="1.5707963267948966 0 0" xyz="0 0 0"/>
			<geometry>
				<cylinder length="0.0475" radius="0.0475"/>
			</geometry>
		</collision>
	</link>
	<!-- back left wheel -->
	<joint name="caster_joint_bl" type="continuous">
		<origin rpy="0 0 0" xyz="-0.228 0.158 -0.034"/>
		<axis xyz="0 0 1"/>
		<limit effort="30" velocity="10"/>
		<dynamics damping="1.0" friction="1.0"/>
		<safety_controller k_velocity="10.0"/>
		<parent link="base_link"/>
		<child link="caster_link_bl"/>
	</joint>
	<link name="caster_link_bl">
		<inertial>
			<mass value="0.1"/>
			<origin xyz="0 0 0"/>
			<inertia ixx="0.012411765597" ixy="-0.000711733678" ixz="0.00050272983" iyy="0.015218160428" iyz="-0.000004273467" izz="0.011763977943"/>
		</inertial>
	</link>
	<joint name="wheel_joint_bl" type="continuous">
		<axis xyz="0 1 0"/>
		<limit effort="30" velocity="10"/>
		<dynamics damping="1.0" friction="1.0"/>
		<safety_controller k_velocity="10.0"/>
		<origin rpy="0 0 0" xyz="0.0 0.0 0.0"/>
		<parent link="caster_link_bl"/>
		<child link="wheel_link_bl"/>
	</joint>
	<link name="wheel_link_bl">
		<inertial>
			<mass value="1.4"/>
			<origin xyz="0 0 0"/>
			<inertia ixx="0.012411765597" ixy="-0.000711733678" ixz="0.00050272983" iyy="0.015218160428" iyz="-0.000004273467" izz="0.011763977943"/>
		</inertial>
		<visual>
			<origin rpy="0 0 0" xyz="0 0 0"/>
			<geometry>
				<mesh filename="meshes/youbot_base/back_left_wheel.dae" />
				<!-- <sphere radius="0.0475"/> -->
			</geometry>
			<material name="youBot/Orange"/>
		</visual>
		<collision>
			<origin rpy="1.5707963267948966 0 0" xyz="0 0 0"/>
			<geometry>
				<cylinder length="0.0475" radius="0.0475"/>
			</geometry>
		</collision>
	</link>
	<!-- back right wheel -->
	<joint name="caster_joint_br" type="continuous">
		<origin rpy="0 0 0" xyz="-0.228 -0.158 -0.034"/>
		<axis xyz="0 0 1"/>
		<limit effort="30" velocity="10"/>
		<dynamics damping="1.0" friction="1.0"/>
		<safety_controller k_velocity="10.0"/>
		<parent link="base_link"/>
		<child link="caster_link_br"/>
	</joint>
	<link name="caster_link_br">
		<inertial>
			<mass value="0.1"/>
			<origin xyz="0 0 0"/>
			<inertia ixx="0.012411765597" ixy="-0.000711733678" ixz="0.00050272983" iyy="0.015218160428" iyz="-0.000004273467" izz="0.011763977943"/>
		</inertial>
	</link>
	<joint name="wheel_joint_br" type="continuous">
		<axis xyz="0 1 0"/>
		<limit effort="30" velocity="10"/>
		<dynamics damping="1.0" friction="1.0"/>
		<safety_controller k_velocity="10.0"/>
		<origin rpy="0 0 0" xyz="0.0 0.0 0.0"/>
		<parent link="caster_link_br"/>
		<child link="wheel_link_br"/>
	</joint>
	<link name="wheel_link_br">
		<inertial>
			<mass value="1.4"/>
			<origin xyz="0 0 0"/>
			<inertia ixx="0.012411765597" ixy="-0.000711733678" ixz="0.00050272983" iyy="0.015218160428" iyz="-0.000004273467" izz="0.011763977943"/>
		</inertial>
		<visual>
			<origin rpy="0 0 0" xyz="0 0 0"/>
			<geometry>
				<mesh filename="meshes/youbot_base/back_right_wheel.dae" />
				<!-- <sphere radius="0.0475"/> -->
			</geometry>
			<material name="youBot/Orange"/>
		</visual>
		<collision>
			<origin rpy="1.5707963267948966 0 0" xyz="0 0 0"/>
			<geometry>
				<cylinder length="0.0475" radius="0.0475"/>
			</geometry>
		</collision>
	</link>
	<gazebo reference="youbot_base">
    </gazebo>
	<!-- front left wheel -->
	<gazebo reference="wheel_link_fl">
		<kp>1000000</kp>
		<kd>100</kd>
	</gazebo>
	<gazebo reference="caster_link_fl">
    </gazebo>
	<!-- front right wheel -->
	<gazebo reference="wheel_link_fr">
		<kp>1000000</kp>
		<kd>100</kd>
	</gazebo>
	<gazebo reference="caster_link_fr">   
    </gazebo>
	<!-- back left wheel -->
	<gazebo reference="wheel_link_bl">
		<kp>1000000</kp>
		<kd>100</kd>
	</gazebo>
	<gazebo reference="caster_link_bl">
    </gazebo>
	<!-- back right wheel -->
	<gazebo reference="wheel_link_br">
		<kp>1000000</kp>
		<kd>100</kd>
	</gazebo>
	<gazebo reference="caster_link_br">
    </gazebo>
	<!-- front left wheel -->
	<transmission name="wheel_trans_fl">
		<type>transmission_interface/SimpleTransmission</type>
		<actuator name="wheel_motor_fl">
			<mechanicalReduction>79.23809523809524</mechanicalReduction>
		</actuator>
		<joint name="wheel_joint_fl">
			<hardwareInterface>hardware_interface/VelocityJointInterface</hardwareInterface>
		</joint>
	</transmission>
	<transmission name="caster_trans_fl">
		<type>transmission_interface/SimpleTransmission</type>
		<actuator name="caster_motor_fl">
			<mechanicalReduction>79.23809523809524</mechanicalReduction>
		</actuator>
		<joint name="caster_joint_fl">
			<hardwareInterface>hardware_interface/VelocityJointInterface</hardwareInterface>
		</joint>
	</transmission>
	<!-- front right wheel -->
	<transmission name="wheel_trans_fr">
		<type>transmission_interface/SimpleTransmission</type>
		<actuator name="wheel_motor_fr">
			<mechanicalReduction>79.23809523809524</mechanicalReduction>
		</actuator>
		<joint name="wheel_joint_fr">
			<hardwareInterface>hardware_interface/VelocityJointInterface</hardwareInterface>
		</joint>
	</transmission>
	<transmission name="caster_trans_fr">
		<type>transmission_interface/SimpleTransmission</type>
		<actuator name="caster_motor_fr">
			<mechanicalReduction>79.23809523809524</mechanicalReduction>
		</actuator>
		<joint name="caster_joint_fr">
			<hardwareInterface>hardware_interface/VelocityJointInterface</hardwareInterface>
		</joint>
	</transmission>
	<!-- back left wheel -->
	<transmission name="wheel_trans_bl">
		<type>transmission_interface/SimpleTransmission</type>
		<actuator name="wheel_motor_bl">
			<mechanicalReduction>79.23809523809524</mechanicalReduction>
		</actuator>
		<joint name="wheel_joint_bl">
			<hardwareInterface>hardware_interface/VelocityJointInterface</hardwareInterface>
		</joint>
	</transmission>
	<transmission name="caster_trans_bl">
		<type>transmission_interface/SimpleTransmission</type>
		<actuator name="caster_motor_bl">
			<mechanicalReduction>79.23809523809524</mechanicalReduction>
		</actuator>
		<joint name="caster_joint_bl">
			<hardwareInterface>hardware_interface/VelocityJointInterface</hardwareInterface>
		</joint>
	</transmission>
	<!-- back right wheel -->
	<transmission name="wheel_trans_br">
		<type>transmission_interface/SimpleTransmission</type>
		<actuator name="wheel_motor_br">
			<mechanicalReduction>79.23809523809524</mechanicalReduction>
		</actuator>
		<joint name="wheel_joint_br">
			<hardwareInterface>hardware_interface/VelocityJointInterface</hardwareInterface>
		</joint>
	</transmission>
	<transmission name="caster_trans_br">
		<type>transmission_interface/SimpleTransmission</type>
		<actuator name="caster_motor_br">
			<mechanicalReduction>79.23809523809524</mechanicalReduction>
		</actuator>
		<joint name="caster_joint_br">
			<hardwareInterface>hardware_interface/VelocityJointInterface</hardwareInterface>
		</joint>
	</transmission>
	<!-- joint between arm_7_link and sdh_palm_link -->
	<joint name="plate_joint" type="fixed">
		<origin rpy="0 0 0" xyz="-0.159 0 0.046"/>
		<parent link="base_link"/>
		<child link="plate_link"/>
	</joint>
	<link name="plate_link">
		<inertial>
			<origin rpy="0 0 0" xyz="0 0 0"/>
			<mass value="2.397"/>
			<inertia ixx="0.01" ixy="0" ixz="0" iyy="0.01" iyz="0" izz="0.01"/>
		</inertial>
		<visual>
			<origin rpy="0 0 0" xyz="0 0 0"/>
			<geometry>
				<mesh filename="meshes/youbot_plate/plate.dae"/>
			</geometry>
			<material name="DarkGrey"/>
		</visual>
		<collision>
			<origin rpy="0 0 0" xyz="0 0 0"/>
			<geometry>
				<mesh filename="meshes/youbot_plate/plate_convex.dae"/>
			</geometry>
		</collision>
	</link>
	<!-- extensions -->
	<!-- joint between base_link and arm_0_link -->
	<joint name="arm_joint_0" type="fixed">
		<origin rpy="0 0 0" xyz="0.143 0 0.046"/>
		<parent link="base_link"/>
		<child link="arm_link_0"/>
	</joint>
	<link name="arm_link_0">
		<inertial>
			<!--<origin xyz="0.023 0 0.006" rpy="0 0 0"/>-->
			<origin rpy="0 0 0" xyz="0 0 0"/>
			<mass value="0.961"/>
			<inertia ixx="0.01" ixy="0" ixz="0" iyy="0.01" iyz="0" izz="0.01"/>
		</inertial>
		<visual>
			<origin rpy="0 0 0" xyz="0 0 0"/>
			<geometry>
				<mesh filename="meshes/youbot_arm/arm0.dae"/>
			</geometry>
			<material name="youBot/DarkGrey"/>
		</visual>
		<collision>
			<!--<origin xyz="0.023 0 0.006" rpy="0 0 0"/>-->
			<origin rpy="0 0 0" xyz="0 0 0"/>
			<geometry>
				<mesh filename="meshes/youbot_arm/arm0_convex.dae"/>
				<!--<cylinder length="0.078" radius="0.093"/>-->
			</geometry>
		</collision>
	</link>
	<!-- joint between arm_0_link and arm_1_link -->
	<joint name="arm_joint_1" type="revolute">
		<origin rpy="0 0 2.9670597283903604" xyz="0.024 0 0.096"/>
		<parent link="arm_link_0"/>
		<child link="arm_link_1"/>
		<axis xyz="0 0 -1"/>
		<!--<calibration rising="${arm_1_ref}" falling="${arm_1_ref}"/>-->
		<dynamics damping="1" friction="0.5"/>
		<!-- damping - N*s/m, N*s*m/rad -->
		<!-- friction - N, N*m -->
		<limit effort="9.5" lower="0" upper="5.899212871740834" velocity="1.5707963267948966"/>
		<!--effort - N, N*m-->
		<!--velocity - m/s, rad/s-->
		<!--safety_controller k_position="20" k_velocity="${9.5/M_PI / 2.0}" soft_lower_limit="${threshold}" soft_upper_limit="${joint_1_limit_soft}" /-->
		<!--k_position N/m, N/rad-->
		<!--k_velocity N*s/m, N*s*m/rad-->
		<!--for details: http://www.ros.org/wiki/pr2_controller_manager/safety_limits-->
	</joint>
	<link name="arm_link_1">
		<inertial>
			<mass value="1.39"/>
			<origin rpy="0 0 0" xyz="0.01489 0.00213 0.00213"/>
			<inertia ixx="0.0029525" ixy="0.0" ixz="0.0" iyy="0.0060091" iyz="0.0" izz="0.0058821"/>
		</inertial>
		<visual>
			<origin rpy="0 0 0" xyz="0 0 0"/>
			<geometry>
				<mesh filename="meshes/youbot_arm/arm1.dae"/>
			</geometry>
			<material name="youBot/Orange"/>
		</visual>
		<collision>
			<!--<origin xyz="0 0 -0.003" rpy="0 0 0" />-->
			<origin rpy="0 0 0" xyz="0 0 0"/>
			<geometry>
				<mesh filename="meshes/youbot_arm/arm1_convex.dae"/>
				<!--<cylinder length="0.102" radius="0.080"/>-->
			</geometry>
		</collision>
	</link>
	<!-- joint between arm_1_link and arm_2_link -->
	<joint name="arm_joint_2" type="revolute">
		<origin rpy="0 -1.1344640137963142 0" xyz="0.033 0 0.019"/>
		<parent link="arm_link_1"/>
		<child link="arm_link_2"/>
		<axis xyz="0 1 0"/>
		<!--<calibration rising="${arm_2_ref}" falling="${arm_2_ref}"/>-->
		<dynamics damping="1" friction="0.5"/>
		<limit effort="9.5" lower="0" upper="2.705260340591211" velocity="1.5707963267948966"/>
		<!--safety_controller k_position="20" k_velocity="${2*9.5/M_PI}" soft_lower_limit="${threshold}" soft_upper_limit="${joint_2_limit_soft}" /-->
	</joint>
	<link name="arm_link_2">
		<inertial>
			<mass value="1.318"/>
			<origin rpy="0 0 0" xyz="0.01053 -0.030699999999999998 0.08597"/>
			<inertia ixx="0.0031145" ixy="0.0" ixz="0.0" iyy="0.0005843" iyz="0.0" izz="0.0031631"/>
		</inertial>
		<visual>
			<origin rpy="0 0 0" xyz="0 -0.032 0.078"/>
			<geometry>
				<mesh filename="meshes/youbot_arm/arm2.dae"/>
			</geometry>
		</visual>
		<collision>
			<!--<origin xyz="0.001 -0.041 0.074" rpy="0 0 0" />-->
			<origin rpy="0 0 0" xyz="0 -0.032 0.078"/>
			<geometry>
				<mesh filename="meshes/youbot_arm/arm2_convex.dae"/>
				<!--<box size="0.074 0.082 0.222"/>-->
			</geometry>
		</collision>
	</link>
	<!-- joint between arm_2_link and arm_3_link -->
	<joint name="arm_joint_3" type="revolute">
		<origin rpy="0 2.548180707911721 0" xyz="0.000 0.000 0.155"/>
		<parent link="arm_link_2"/>
		<child link="arm_link_3"/>
		<axis xyz="0 1 0"/>
		<dynamics damping="1" friction="0.5"/>
		<limit effort="6.0" lower="-5.183627878423159" upper="0" velocity="1.5707963267948966"/>
		<!--safety_controller k_position="20" k_velocity="50" soft_lower_limit="-${joint_3_limit_soft}" soft_upper_limit="-${threshold}" /-->
	</joint>
	<link name="arm_link_3">
		<inertial>
			<mass value="0.821"/>
			<origin rpy="0 0 0" xyz="0.0001 0.0207 0.07107"/>
			<inertia ixx="0.00172767" ixy="0.0" ixz="0.0" iyy="0.00041967" iyz="0.0" izz="0.0018468"/>
		</inertial>
		<visual>
			<origin rpy="0 0 0" xyz="0.000 0.028 0.079"/>
			<geometry>
				<mesh filename="meshes/youbot_arm/arm3.dae"/>
			</geometry>
			<material name="youBot/Orange"/>
		</visual>
		<collision>
			<!--<origin xyz="0.000 0.025 0.067" rpy="0 0 0" />-->
			<origin rpy="0 0 0" xyz="0.000 0.028 0.079"/>
			<geometry>
				<mesh filename="meshes/youbot_arm/arm3_convex.dae"/>
				<!--<box size="0.064 0.054 0.192"/>-->
			</geometry>
		</collision>
	</link>
	<!-- joint between arm_3_link and arm_4_link -->
	<joint name="arm_joint_4" type="revolute">
		<origin rpy="0 -1.7889624832941877 0" xyz="0.000 0.000 0.135"/>
		<parent link="arm_link_3"/>
		<child link="arm_link_4"/>
		<axis xyz="0 1 0"/>
		<!--<calibration rising="${arm_4_ref}" falling="${arm_4_ref}"/>-->
		<dynamics damping="1" friction="0.5"/>
		<limit effort="2.0" lower="0" upper="3.5779249665883754" velocity="1.5707963267948966"/>
		<!--safety_controller k_position="20" k_velocity="100" soft_lower_limit="0" soft_upper_limit="${joint_4_limit_soft}" /-->
	</joint>
	<link name="arm_link_4">
		<inertial>
			<mass value="0.769"/>
			<origin rpy="0 0 0" xyz="0.00011 -0.02 0.05019"/>
			<inertia ixx="0.0006764" ixy="0.0" ixz="0.0" iyy="0.0010573" iyz="0.0" izz="0.0006610"/>
		</inertial>
		<visual>
			<origin rpy="0 0 0" xyz="0 -0.010 0.029"/>
			<geometry>
				<mesh filename="meshes/youbot_arm/arm4.dae"/>
			</geometry>
			<material name="youBot/Orange"/>
		</visual>
		<collision>
			<!--<origin xyz="0 0 0.026" rpy="0 0 0" />-->
			<origin rpy="0 0 0" xyz="0 -0.010 0.029"/>
			<geometry>
				<mesh filename="meshes/youbot_arm/arm4_convex.dae"/>
				<!--<box size="0.058 0.100 0.118"/>-->
			</geometry>
		</collision>
	</link>
	<!-- joint between arm_4_link and arm_5_link -->
	<joint name="arm_joint_5" type="revolute">
		<origin rpy="0 0 2.9234264970905017" xyz="-0.002 0 0.130"/>
		<parent link="arm_link_4"/>
		<child link="arm_link_5"/>
		<axis xyz="0 0 -1"/>
		<!--<calibration rising="${arm_5_ref}" falling="${arm_5_ref}"/>-->
		<dynamics damping="0.5" friction="0.5"/>
		<limit effort="1.0" lower="0" upper="5.8468529941810035" velocity="1.5707963267948966"/>
		<!--safety_controller k_position="20" k_velocity="100" soft_lower_limit="0" soft_upper_limit="${joint_5_limit_soft}" /-->
	</joint>
	<link name="arm_link_5">
		<inertial>
			<mass value="0.687"/>
			<origin rpy="0 0 0" xyz="0.0 0.00115 -0.016829999999999998"/>
			<inertia ixx="0.0001934" ixy="0.0" ixz="0.0" iyy="0.0001602" iyz="0.0" izz="0.0000689"/>
		</inertial>
		<visual>
			<origin rpy="0 0 0" xyz="0.003 0 -0.034"/>
			<geometry>
				<mesh filename="meshes/youbot_arm/arm5.dae"/>
			</geometry>
			<material name="youBot/DarkGrey"/>
		</visual>
		<collision>
			<origin rpy="0 0 0" xyz="0.003 0 -0.034"/>
			<geometry>
				<mesh filename="meshes/youbot_arm/arm5_convex.dae"/>
				<!--<box size="0.054 0.096 0.030"/>-->
			</geometry>
		</collision>
	</link>
	<gazebo reference="arm_link_0">
		<turnGravityOff>false</turnGravityOff>
	</gazebo>
	<gazebo reference="arm_link_1">
		<turnGravityOff>false</turnGravityOff>
	</gazebo>
	<gazebo reference="arm_link_2">
		<turnGravityOff>false</turnGravityOff>
	</gazebo>
	<gazebo reference="arm_link_3">
		<turnGravityOff>false</turnGravityOff>
	</gazebo>
	<gazebo reference="arm_link_4">
		<turnGravityOff>false</turnGravityOff>
	</gazebo>
	<gazebo reference="arm_link_5">
		<turnGravityOff>false</turnGravityOff>
	</gazebo>
	<transmission name="arm_trans_1">
		<type>transmission_interface/SimpleTransmission</type>
		<actuator name="arm_motor_1">
			<mechanicalReduction>1</mechanicalReduction>
		</actuator>
		<joint name="arm_joint_1">
			<hardwareInterface>hardware_interface/EffortJointInterface</hardwareInterface>
		</joint>
	</transmission>
	<transmission name="arm_trans_2">
		<type>transmission_interface/SimpleTransmission</type>
		<actuator name="arm_motor_2">
			<mechanicalReduction>1</mechanicalReduction>
		</actuator>
		<joint name="arm_joint_2">
			<hardwareInterface>hardware_interface/EffortJointInterface</hardwareInterface>
		</joint>
	</transmission>
	<transmission name="arm_trans_3">
		<type>transmission_interface/SimpleTransmission</type>
		<actuator name="arm_motor_3">
			<mechanicalReduction>1</mechanicalReduction>
		</actuator>
		<joint name="arm_joint_3">
			<hardwareInterface>hardware_interface/EffortJointInterface</hardwareInterface>
		</joint>
	</transmission>
	<transmission name="arm_trans_4">
		<type>transmission_interface/SimpleTransmission</type>
		<actuator name="arm_motor_4">
			<mechanicalReduction>1</mechanicalReduction>
		</actuator>
		<joint name="arm_joint_4">
			<hardwareInterface>hardware_interface/EffortJointInterface</hardwareInterface>
		</joint>
	</transmission>
	<transmission name="arm_trans_5">
		<type>transmission_interface/SimpleTransmission</type>
		<actuator name="arm_motor_5">
			<mechanicalReduction>1</mechanicalReduction>
		</actuator>
		<joint name="arm_joint_5">
			<hardwareInterface>hardware_interface/EffortJointInterface</hardwareInterface>
		</joint>
	</transmission>
	<!-- joint between arm_7_link and sdh_palm_link -->
	<joint name="gripper_palm_joint" type="fixed">
		<origin rpy="0 0 0" xyz="0 0 0"/>
		<parent link="arm_link_5"/>
		<child link="gripper_palm_link"/>
	</joint>
	<link name="gripper_palm_link">
		<inertial>
			<origin rpy="0 0 0" xyz="0 0 0"/>
			<mass value="0.1"/>
			<inertia ixx="0.01" ixy="0" ixz="0" iyy="0.01" iyz="0" izz="0.01"/>
		</inertial>
		<visual>
			<origin rpy="0 0 0" xyz="0 0 0"/>
			<geometry>
				<mesh filename="meshes/youbot_gripper/palm.dae"/>
			</geometry>
			<material name="Black"/>
		</visual>
		<collision>
			<origin rpy="0 0 0" xyz="0 0 0"/>
			<geometry>
				<!--<box size="0.050 0.094 0.054"/>-->
				<mesh filename="meshes/youbot_gripper/palm_convex.dae"/>
			</geometry>
		</collision>
	</link>
	<joint name="gripper_finger_joint_l" type="prismatic">
		<origin rpy="0 0 3.141592653589793" xyz="0.004 0.008 0.046"/>
		<parent link="gripper_palm_link"/>
		<child link="gripper_finger_link_l"/>
		<axis xyz="0 -1 0"/>
		<dynamics damping="1.0" friction="1.0"/>
		<limit effort="1" lower="0" upper="0.0115" velocity="0.1"/>
		<safety_controller k_position="20" k_velocity="25" soft_lower_limit="0.001" soft_upper_limit="0.011"/>
	</joint>
	<link name="gripper_finger_link_l">
		<inertial>
			<origin rpy="0 0 0" xyz="0 -0.001 0"/>
			<mass value="0.01"/>
			<inertia ixx="0.01" ixy="0" ixz="0" iyy="0.01" iyz="0" izz="0.01"/>
		</inertial>
		<visual>
			<origin rpy="0 0 0" xyz="0 0 0"/>
			<geometry>
				<mesh filename="meshes/youbot_gripper/finger.dae"/>
			</geometry>
			<material name="Black"/>
		</visual>
		<collision>
			<origin rpy="0 0 0" xyz="0 0 0"/>
			<geometry>
				<!--<box size="0.014 0.020 0.046"/>-->
				<mesh filename="meshes/youbot_gripper/finger_convex.dae"/>
			</geometry>
		</collision>
	</link>
	<joint name="gripper_finger_joint_r" type="prismatic">
		<origin rpy="0 0 0" xyz="0.004 -0.008 0.046"/>
		<parent link="gripper_palm_link"/>
		<child link="gripper_finger_link_r"/>
		<axis xyz="0 -1 0"/>
		<dynamics damping="1.0" friction="1.0"/>
		<limit effort="1" lower="0" upper="0.0115" velocity="0.1"/>
		<safety_controller k_position="20" k_velocity="25" soft_lower_limit="0.001" soft_upper_limit="0.011"/>
	</joint>
	<link name="gripper_finger_link_r">
		<inertial>
			<origin rpy="0 0 0" xyz="0.000 -0.001 0"/>
			<mass value="0.01"/>
			<inertia ixx="0.01" ixy="0" ixz="0" iyy="0.01" iyz="0" izz="0.01"/>
		</inertial>
		<visual>
			<origin rpy="0 0 0" xyz="0 0 0"/>
			<geometry>
				<mesh filename="meshes/youbot_gripper/finger.dae"/>
			</geometry>
			<material name="Black"/>
		</visual>
		<collision>
			<origin rpy="0 0 0" xyz="0.000 0 0"/>
			<geometry>
				<!--<box size="0.014 0.020 0.046"/>-->
				<mesh filename="meshes/youbot_gripper/finger_convex.dae"/>
			</geometry>
		</collision>
	</link>
	<gazebo reference="gripper_palm_link">
		<material>Gazebo/Black</material>
		<turnGravityOff>false</turnGravityOff>
		<selfCollide>true</selfCollide>
	</gazebo>
	<gazebo reference="gripper_finger_l_link">
		<material>Gazebo/Black</material>
		<turnGravityOff>false</turnGravityOff>
		<selfCollide>true</selfCollide>
	</gazebo>
	<gazebo reference="gripper_finger_r_link">
		<material>Gazebo/Black</material>
		<turnGravityOff>false</turnGravityOff>
		<selfCollide>true</selfCollide>
	</gazebo>
	<transmission name="gripper_finger_l_trans">
		<type>transmission_interface/SimpleTransmission</type>
		<actuator name="gripper_finger_l_motor">
			<mechanicalReduction>1</mechanicalReduction>
		</actuator>
		<joint name="gripper_finger_joint_l">
			<hardwareInterface>hardware_interface/EffortJointInterface</hardwareInterface>
		</joint>
	</transmission>
	<transmission name="gripper_finger_r_trans">
		<type>transmission_interface/SimpleTransmission</type>
		<actuator name="gripper_finger_r_motor">
			<mechanicalReduction>1</mechanicalReduction>
		</actuator>
		<joint name="gripper_finger_joint_r">
			<hardwareInterface>hardware_interface/EffortJointInterface</hardwareInterface>
		</joint>
	</transmission>
	<joint name="base_laser_front_hokuyo_urg04_laser_joint" type="fixed">
		<axis xyz="0 1 0"/>
		<origin rpy="0 0 0" xyz="0.3 0 -0.03"/>
		<parent link="base_link"/>
		<child link="base_laser_front_link"/>
	</joint>
	<link name="base_laser_front_link">
		<inertial>
			<mass value="0.16"/>
			<origin rpy="0 0 0" xyz="0 0 0"/>
			<inertia ixx="0.1" ixy="0" ixz="0" iyy="0.1" iyz="0" izz="0.1"/>
		</inertial>
		<visual>
			<origin rpy="0 0 0" xyz="0 0 0"/>
			<geometry>
				<mesh filename="meshes/sensors/hokuyo.dae"/>
			</geometry>
		</visual>
		<collision>
			<origin rpy="0 0 0" xyz="0 0 0"/>
			<geometry>
				<mesh filename="meshes/sensors/hokuyo_convex.dae"/>
			</geometry>
		</collision>
	</link>
	<gazebo reference="base_laser_front_link">
		<sensor name="base_laser_front" type="ray">
			<update_rate>10</update_rate>
			<pose>0 0 0 0 0 0</pose>
			<visualize>false</visualize>
			<ray>
				<scan>
					<horizontal>
						<samples>150</samples>
						<resolution>1.0</resolution>
						<min_angle>-1.57</min_angle>
						<max_angle>1.57</max_angle>
					</horizontal>
				</scan>
				<range>
					<min>0.05</min>
					<max>5.6</max>
					<resolution>0.36</resolution>
				</range>
			</ray>
			<plugin filename="libgazebo_ros_laser.so" name="gazebo_ros_base_laser_front_controller">
				<gaussianNoise>0.005</gaussianNoise>
				<updateRate>10</updateRate>
				<topicName>scan_front</topicName>
				<frameName>/base_laser_front_link</frameName>
			</plugin>
		</sensor>
	</gazebo>
	<link name="camera_tower_link">
		<inertial>
			<mass value="0.5"/>
			<origin rpy="0 0 0" xyz="0 0 -0.245"/>
			<inertia ixx="0.0001" ixy="0" ixz="0" iyy="0.0001" iyz="0" izz="0.0001"/>
		</inertial>
		<visual>
			<origin rpy="0 0 0" xyz="0 0 0.245"/>
			<geometry>
				<box size="0.03 0.03 0.49"/>
			</geometry>
			<material name="youBot/LightGrey"/>
		</visual>
		<collision>
			<origin rpy="0 0 0" xyz="0 0 0.245"/>
			<geometry>
				<box size="0.03 0.03 0.49"/>
			</geometry>
		</collision>
	</link>
	<joint name="camera_tower_joint" type="fixed">
		<origin rpy="0 0 0" xyz="-0.11 0.0 0.03"/>
		<parent link="plate_link"/>
		<child link="camera_tower_link"/>
	</joint>
	<link name="tower_cam3d_foot_link">
		<inertial>
			<mass value="0.05"/>
			<origin rpy="0 0 0" xyz="0 0 0"/>
			<inertia ixx="0.0001" ixy="0" ixz="0" iyy="0.0001" iyz="0" izz="0.0001"/>
		</inertial>
		<visual>
			<origin rpy="1.5707963267948966 0 1.5707963267948966" xyz="0.01 0 0"/>
			<geometry>
				<mesh filename="meshes/sensors/asus_xtion_pro_live_base.dae" scale="0.0004 0.0007 0.001"/>
			</geometry>
			<material name="Black"/>
		</visual>
		<collision>
			<origin rpy="1.5707963267948966 0 1.5707963267948966" xyz="0.01 0 0"/>
			<geometry>
				<mesh filename="meshes/sensors/asus_xtion_pro_live_base.dae" scale="0.0004 0.0007 0.001"/>
			</geometry>
		</collision>
	</link>
	<joint name="tower_cam3d_foot_joint" type="fixed">
		<origin rpy="0 0 0" xyz="0 0 0.49"/>
		<parent link="camera_tower_link"/>
		<child link="tower_cam3d_foot_link"/>
	</joint>
	<link name="tower_cam3d_tilt_link">
		<inertial>
			<mass value="0.01"/>
			<origin rpy="0 0 0" xyz="0 0 0"/>
			<inertia ixx="0.0001" ixy="0" ixz="0" iyy="0.0001" iyz="0" izz="0.0001"/>
		</inertial>
		<visual>
			<origin rpy="0 0 0" xyz="0 0 0.0075"/>
			<geometry>
				<cylinder length="0.025" radius="0.005"/>
			</geometry>
			<material name="Black"/>
		</visual>
		<collision>
			<origin rpy="0 0 0" xyz="0 0 0.0075"/>
			<geometry>
				<cylinder length="0.025" radius="0.005"/>
			</geometry>
			<material name="Black"/>
		</collision>
	</link>
	<joint name="asus_xtion_tilt_joint" type="fixed">
		<parent link="tower_cam3d_foot_link"/>
		<child link="tower_cam3d_tilt_link"/>
		<!--<axis xyz="0 1 0"/>-->
		<origin rpy="0 0.5 0" xyz="0 0 0.0075"/>
		<!--<limit effort="100" lower="-0.541052068" upper="0.541052068" velocity="1.0"/>-->
	</joint>
	<link name="tower_cam3d_camera">
		<inertial>
			<mass value="0.1"/>
			<origin rpy="0 0 0" xyz="0 0 0"/>
			<inertia ixx="0.0001" ixy="0" ixz="0" iyy="0.0001" iyz="0" izz="0.0001"/>
		</inertial>
		<visual>
			<origin rpy="1.5707963267948966 0 1.5707963267948966" xyz="0.02 -0.03 0"/>
			<geometry>
				<mesh filename="meshes/sensors/asus_xtion_pro_live_camera.dae" scale="0.001 0.001 0.001"/>
			</geometry>
			<material name="Black"/>
		</visual>
		<collision>
			<origin rpy="1.5707963267948966 0 1.5707963267948966" xyz="0.02 -0.03 0"/>
			<geometry>
				<mesh filename="meshes/sensors/asus_xtion_pro_live_camera.dae" scale="0.001 0.001 0.001"/>
			</geometry>
		</collision>
	</link>
	<joint name="tower_cam3d_camera_joint" type="fixed">
		<origin rpy="0 0 0" xyz="0 0.03 0.03"/>
		<parent link="tower_cam3d_tilt_link"/>
		<child link="tower_cam3d_camera"/>
	</joint>
	<link name="tower_cam3d_depth_frame">
		<inertial>
			<mass value="0.01"/>
			<origin xyz="0 0 0"/>
			<inertia ixx="0.1" ixy="0" ixz="0" iyy="0.1" iyz="0" izz="0.1"/>
		</inertial>
	</link>
	<joint name="tower_cam3d_depth_joint" type="fixed">
		<parent link="tower_cam3d_camera"/>
		<child link="tower_cam3d_depth_frame"/>
		<origin rpy="0 0 0" xyz="0.03 0.015000000000000003 0"/>
	</joint>
	<link name="tower_cam3d_depth_optical_frame">
		<inertial>
			<mass value="0.01"/>
			<origin xyz="0 0 0"/>
			<inertia ixx="0.1" ixy="0" ixz="0" iyy="0.1" iyz="0" izz="0.1"/>
		</inertial>
	</link>
	<joint name="tower_cam3d_depth_optical_joint" type="fixed">
		<parent link="tower_cam3d_camera"/>
		<child link="tower_cam3d_depth_optical_frame"/>
		<origin rpy="-1.5707963267948966 0 -1.5707963267948966" xyz="0.03 0.015000000000000003 0"/>
	</joint>
	<link name="tower_cam3d_rgb_frame">
		<inertial>
			<mass value="0.01"/>
			<origin xyz="0 0 0"/>
			<inertia ixx="0.1" ixy="0" ixz="0" iyy="0.1" iyz="0" izz="0.1"/>
		</inertial>
	</link>
	<joint name="tower_cam3d_rgb_joint" type="fixed">
		<parent link="tower_cam3d_camera"/>
		<child link="tower_cam3d_rgb_frame"/>
		<origin rpy="0 0 0" xyz="0.03 -0.0049999999999999975 0"/>
	</joint>
	<link name="tower_cam3d_rgb_optical_frame">
		<inertial>
			<mass value="0.01"/>
			<origin xyz="0 0 0"/>
			<inertia ixx="0.1" ixy="0" ixz="0" iyy="0.1" iyz="0" izz="0.1"/>
		</inertial>
	</link>
	<joint name="tower_cam3d_rgb_optical_joint" type="fixed">
		<parent link="tower_cam3d_camera"/>
		<child link="tower_cam3d_rgb_optical_frame"/>
		<origin rpy="-1.5707963267948966 0 -1.5707963267948966" xyz="0.03 -0.0049999999999999975 0"/>
	</joint>
	<link name="tower_cam3d_laser_frame">
		<inertial>
			<mass value="0.01"/>
			<origin xyz="0 0 0"/>
			<inertia ixx="0.1" ixy="0" ixz="0" iyy="0.1" iyz="0" izz="0.1"/>
		</inertial>
	</link>
	<joint name="tower_cam3d_laser_joint" type="fixed">
		<parent link="tower_cam3d_camera"/>
		<child link="tower_cam3d_laser_frame"/>
		<origin rpy="0 0 0" xyz="0.03 -0.05499999999999999 0"/>
	</joint>
	<link name="tower_cam3d_laser_optical_frame">
		<inertial>
			<mass value="0.01"/>
			<origin xyz="0 0 0"/>
			<inertia ixx="0.1" ixy="0" ixz="0" iyy="0.1" iyz="0" izz="0.1"/>
		</inertial>
	</link>
	<joint name="tower_cam3d_laser_optical_joint" type="fixed">
		<parent link="tower_cam3d_camera"/>
		<child link="tower_cam3d_laser_optical_frame"/>
		<origin rpy="1.5707963267948966 0 -1.5707963267948966" xyz="0.03 -0.05499999999999999 0"/>
	</joint>
	<gazebo reference="tower_cam3d_camera">
		<sensor name="tower_cam3d_depth_frame_sensor" type="depth">
			<always_on>true</always_on>
			<update_rate>20.0</update_rate>
			<camera>
				<horizontal_fov>0.9948376736367678</horizontal_fov>
				<image>
					<format>R8G8B8</format>
					<width>640</width>
					<height>480</height>
				</image>
				<clip>
					<near>0.1</near>
					<far>5</far>
				</clip>
			</camera>
			<plugin filename="libgazebo_ros_openni_kinect.so" name="tower_cam3d_depth_frame_controller">
				<baseline>0.2</baseline>
				<alwaysOn>true</alwaysOn>
				<updateRate>20.0</updateRate>
				<cameraName>tower_cam3d_depth</cameraName>
				<imageTopicName>/tower_cam3d/ir/image_raw</imageTopicName>
				<cameraInfoTopicName>/tower_cam3d/ir/camera_info</cameraInfoTopicName>
				<depthImageTopicName>/tower_cam3d/depth/image_raw</depthImageTopicName>
				<depthImageCameraInfoTopicName>/tower_cam3d/depth/camera_info</depthImageCameraInfoTopicName>
				<pointCloudTopicName>/tower_cam3d/depth/points</pointCloudTopicName>
				<frameName>tower_cam3d_depth_optical_frame</frameName>
				<pointCloudCutoff>0.5</pointCloudCutoff>
				<distortionK1>0.00000001</distortionK1>
				<distortionK2>0.00000001</distortionK2>
				<distortionK3>0.00000001</distortionK3>
				<distortionT1>0.00000001</distortionT1>
				<distortionT2>0.00000001</distortionT2>
				<CxPrime>0</CxPrime>
				<Cx>0</Cx>
				<Cy>0</Cy>
				<focalLength>0</focalLength>
				<hackBaseline>0</hackBaseline>
			</plugin>
		</sensor>
		<sensor name="tower_cam3d_rgb_frame_sensor" type="depth">
			<always_on>true</always_on>
			<update_rate>20.0</update_rate>
			<camera>
				<horizontal_fov>0.9948376736367678</horizontal_fov>
				<image>
					<format>R8G8B8</format>
					<width>640</width>
					<height>480</height>
				</image>
				<clip>
					<near>0.1</near>
					<far>5</far>
				</clip>
			</camera>
			<plugin filename="libgazebo_ros_openni_kinect.so" name="tower_cam3d_rgb_frame_controller">
				<baseline>0.2</baseline>
				<alwaysOn>true</alwaysOn>
				<updateRate>20.0</updateRate>
				<cameraName>tower_cam3d_rgb</cameraName>
				<imageTopicName>/tower_cam3d/rgb/image_raw</imageTopicName>
				<cameraInfoTopicName>/tower_cam3d/rgb/camera_info</cameraInfoTopicName>
				<depthImageTopicName>/tower_cam3d/depth_registered/image_raw</depthImageTopicName>
				<depthImageCameraInfoTopicName>/tower_cam3d/depth_registered/camera_info</depthImageCameraInfoTopicName>
				<pointCloudTopicName>/tower_cam3d/depth_registered/points</pointCloudTopicName>
				<frameName>tower_cam3d_rgb_optical_frame</frameName>
				<pointCloudCutoff>0.5</pointCloudCutoff>
				<distortionK1>0.00000001</distortionK1>
				<distortionK2>0.00000001</distortionK2>
				<distortionK3>0.00000001</distortionK3>
				<distortionT1>0.00000001</distortionT1>
				<distortionT2>0.00000001</distortionT2>
				<CxPrime>0</CxPrime>
				<Cx>0</Cx>
				<Cy>0</Cy>
				<focalLength>0</focalLength>
				<hackBaseline>0</hackBaseline>
			</plugin>
		</sensor>
	</gazebo>
</robot>
