<?xml version="1.0" encoding="utf-8"?>
<!-- This URDF was automatically created by SolidWorks to URDF Exporter! Originally created by Stephen Brawner (brawner@gmail.com) 
     Commit Version: 1.5.1-0-g916b5db  Build Version: 1.5.7152.31018
     For more information, please see http://wiki.ros.org/sw_urdf_exporter -->
<robot
  name="hopper_rev05_alt">
  <link
    name="base_link">
    <inertial>
      <origin
        xyz="-0.00408219706898296 0.000379301018318219 0.0170557032108157"
        rpy="0 0 0" />
      <mass
        value="5.59607837933722" />
      <inertia
        ixx="0.00377267223926858"
        ixy="-3.22269145543791E-06"
        ixz="5.32612485392239E-05"
        iyy="0.00604204097244956"
        iyz="8.35702196040584E-06"
        izz="0.00442179153407029" />
    </inertial>
    <visual>
      <origin
        xyz="0 0 0"
        rpy="0 0 0" />
      <geometry>
        <mesh
          filename="package://hopper_rev05_alt/meshes/base_link.STL" />
      </geometry>
      <material
        name="">
        <color
          rgba="0.898039215686275 0.898039215686275 0.898039215686275 1" />
      </material>
    </visual>
    <collision>
      <origin
        xyz="0 0 0"
        rpy="0 0 0" />
      <geometry>
        <mesh
          filename="package://hopper_rev05_alt/meshes/base_link.STL" />
      </geometry>
    </collision>
  </link>
  <link
    name="Link 0">
    <inertial>
      <origin
        xyz="0.0121851264299085 0.0180889013941849 0.00112690392742547"
        rpy="0 0 0" />
      <mass
        value="0.256385566503952" />
      <inertia
        ixx="3.84650100874964E-05"
        ixy="1.5379784060096E-05"
        ixz="-8.48318798628568E-06"
        iyy="0.00017263374747093"
        iyz="1.08260201375488E-06"
        izz="0.000148822440720501" />
    </inertial>
    <visual>
      <origin
        xyz="0 0 0"
        rpy="0 0 0" />
      <geometry>
        <mesh
          filename="package://hopper_rev05_alt/meshes/Link 0.STL" />
      </geometry>
      <material
        name="">
        <color
          rgba="0.898039215686275 0.898039215686275 0.898039215686275 1" />
      </material>
    </visual>
    <collision>
      <origin
        xyz="0 0 0"
        rpy="0 0 0" />
      <geometry>
        <mesh
          filename="package://hopper_rev05_alt/meshes/Link 0.STL" />
      </geometry>
    </collision>
  </link>
  <joint
    name="Joint 0"
    type="revolute">
    <origin
      xyz="0 0 0"
      rpy="0 0.5235987755983 0" />
    <parent
      link="base_link" />
    <child
      link="Link 0" />
    <axis
      xyz="0 -1 0" />
    <limit
      lower="-3.14"
      upper="3.14"
      effort="0"
      velocity="0" />
    <dynamics damping="1.0" />
  </joint>
  <link
    name="Link 1">
    <inertial>
      <origin
        xyz="0.133101645966312 0.00652998365271682 -1.77401555945256E-09"
        rpy="0 0 0" />
      <mass
        value="0.0631473819780702" />
      <inertia
        ixx="2.55548531328563E-06"
        ixy="6.97718053328859E-12"
        ixz="-1.43600149958696E-12"
        iyy="0.000104301911822778"
        iyz="7.22908067849476E-12"
        izz="0.000104301119173831" />
    </inertial>
    <visual>
      <origin
        xyz="0 0 0"
        rpy="0 0 0" />
      <geometry>
        <mesh
          filename="package://hopper_rev05_alt/meshes/Link 1.STL" />
      </geometry>
      <material
        name="">
        <color
          rgba="0.776470588235294 0.756862745098039 0.737254901960784 1" />
      </material>
    </visual>
    <collision>
      <origin
        xyz="0 0 0"
        rpy="0 0 0" />
      <geometry>
        <mesh
          filename="package://hopper_rev05_alt/meshes/Link 1.STL" />
      </geometry>
    </collision>
  </link>
  <joint
    name="Joint 1"
    type="revolute">
    <origin
      xyz="0.1 0 0"
      rpy="-3.1416 1.0768 -3.1416" />
    <parent
      link="Link 0" />
    <child
      link="Link 1" />
    <axis
      xyz="0 -1 0" />
    <limit
      lower="-0.7597"
      upper="1.8295"
      effort="0"
      velocity="0" />
    <dynamics damping="1.0" />
  </joint>
  <link
    name="Link 3">
    <inertial>
      <origin
        xyz="0.00143816546589448 -0.00251001126650875 -0.0148532864362021"
        rpy="0 0 0" />
      <mass
        value="0.124857597760897" />
      <inertia
        ixx="1.60742533641083E-05"
        ixy="-5.54606745564896E-07"
        ixz="1.00368176030359E-06"
        iyy="0.00011650643345049"
        iyz="1.0713067377436E-07"
        izz="0.000112946753437186" />
    </inertial>
    <visual>
      <origin
        xyz="0 0 0"
        rpy="0 0 0" />
      <geometry>
        <mesh
          filename="package://hopper_rev05_alt/meshes/Link 3.STL" />
      </geometry>
      <material
        name="">
        <color
          rgba="1 1 1 1" />
      </material>
    </visual>
    <collision>
      <origin
        xyz="0 0 0"
        rpy="0 0 0" />
      <geometry>
        <mesh
          filename="package://hopper_rev05_alt/meshes/Link 3.STL" />
      </geometry>
    </collision>
  </link>
  <joint
    name="Joint 4"
    type="revolute">
    <origin
      xyz="0.27 0 0"
      rpy="-3.1416 -1.0768 3.1416" />
    <parent
      link="Link 1" />
    <child
      link="Link 3" />
    <axis
      xyz="0 -1 0" />
    <limit
      lower="-1.57"
      upper="1.57"
      effort="0"
      velocity="0" />
    <dynamics damping="1.0" />
  </joint>
  <link
    name="Link 2">
    <inertial>
      <origin
        xyz="0.0389032292366798 -0.0169313659858608 -0.000627148515342592"
        rpy="0 0 0" />
      <mass
        value="0.288845047026487" />
      <inertia
        ixx="3.46488303945479E-05"
        ixy="-3.25958703037608E-07"
        ixz="5.24928694320162E-06"
        iyy="0.000245584749831182"
        iyz="3.01080240182647E-08"
        izz="0.000226676365115679" />
    </inertial>
    <visual>
      <origin
        xyz="0 0 0"
        rpy="0 0 0" />
      <geometry>
        <mesh
          filename="package://hopper_rev05_alt/meshes/Link 2.STL" />
      </geometry>
      <material
        name="">
        <color
          rgba="0.898039215686275 0.898039215686275 0.898039215686275 1" />
      </material>
    </visual>
    <collision>
      <origin
        xyz="0 0 0"
        rpy="0 0 0" />
      <geometry>
        <mesh
          filename="package://hopper_rev05_alt/meshes/Link 2.STL" />
      </geometry>
    </collision>
  </link>
  <joint
    name="Joint 2"
    type="revolute">
    <origin
      xyz="0 0 0"
      rpy="3.1416 0.55323 -3.1416" />
    <parent
      link="base_link" />
    <child
      link="Link 2" />
    <axis
      xyz="0 -1 0" />
    <limit
      lower="-3.14"
      upper="3.14"
      effort="0"
      velocity="0" />
    <dynamics damping="1.0" />
  </joint>
  <link
    name="rw0">
    <inertial>
      <origin
        xyz="-0.0106867499464519 -7.59774464870189E-09 2.70423107084222E-09"
        rpy="0 0 0" />
      <mass
        value="0.715641175075328" />
      <inertia
        ixx="0.00312227321188978"
        ixy="-1.82792561469192E-12"
        ixz="1.2111374518575E-11"
        iyy="0.00158570696597519"
        iyz="7.43838571186844E-09"
        izz="0.00158570710797415" />
    </inertial>
    <visual>
      <origin
        xyz="0 0 0"
        rpy="0 0 0" />
      <geometry>
        <mesh
          filename="package://hopper_rev05_alt/meshes/rw0.STL" />
      </geometry>
      <material
        name="">
        <color
          rgba="0.647058823529412 0.619607843137255 0.588235294117647 1" />
      </material>
    </visual>
    <collision>
      <origin
        xyz="0 0 0"
        rpy="0 0 0" />
      <geometry>
        <mesh
          filename="package://hopper_rev05_alt/meshes/rw0.STL" />
      </geometry>
    </collision>
  </link>
  <joint
    name="joint_rw0"
    type="continuous">
    <origin
      xyz="0.062013 -0.14725 0"
      rpy="3.0307 0 -0.7854" />
    <parent
      link="base_link" />
    <child
      link="rw0" />
    <axis
      xyz="-1 0 0" />
    <dynamics damping="1.0" />
  </joint>
  <link
    name="rw1">
    <inertial>
      <origin
        xyz="-0.0106867499464566 7.59774403114033E-09 -2.704229282776E-09"
        rpy="0 0 0" />
      <mass
        value="0.715641175076257" />
      <inertia
        ixx="0.00312227321188979"
        ixy="1.82792642784355E-12"
        ixz="-1.21113744474242E-11"
        iyy="0.00158570696597532"
        iyz="7.43838570588161E-09"
        izz="0.00158570710797428" />
    </inertial>
    <visual>
      <origin
        xyz="0 0 0"
        rpy="0 0 0" />
      <geometry>
        <mesh
          filename="package://hopper_rev05_alt/meshes/rw1.STL" />
      </geometry>
      <material
        name="">
        <color
          rgba="0.647058823529412 0.619607843137255 0.588235294117647 1" />
      </material>
    </visual>
    <collision>
      <origin
        xyz="0 0 0"
        rpy="0 0 0" />
      <geometry>
        <mesh
          filename="package://hopper_rev05_alt/meshes/rw1.STL" />
      </geometry>
    </collision>
  </link>
  <joint
    name="joint_rw1"
    type="continuous">
    <origin
      xyz="0.063526 0.14877 0"
      rpy="-0.030433 0 0.7854" />
    <parent
      link="base_link" />
    <child
      link="rw1" />
    <axis
      xyz="-1 0 0" />
    <dynamics damping="1.0" />
  </joint>
  <link
    name="rwz">
    <inertial>
      <origin
        xyz="9.05342949220067E-09 -3.16383572118717E-10 -0.0146079871766005"
        rpy="0 0 0" />
      <mass
        value="0.377854494953541" />
      <inertia
        ixx="0.000300958121757203"
        ixy="-4.23471720471975E-12"
        ixz="-6.67153441337645E-12"
        iyy="0.000300957997312782"
        iyz="9.55842379214409E-14"
        izz="0.000578115934214613" />
    </inertial>
    <visual>
      <origin
        xyz="0 0 0"
        rpy="0 0 0" />
      <geometry>
        <mesh
          filename="package://hopper_rev05_alt/meshes/rwz.STL" />
      </geometry>
      <material
        name="">
        <color
          rgba="0.647058823529412 0.619607843137255 0.588235294117647 1" />
      </material>
    </visual>
    <collision>
      <origin
        xyz="0 0 0"
        rpy="0 0 0" />
      <geometry>
        <mesh
          filename="package://hopper_rev05_alt/meshes/rwz.STL" />
      </geometry>
    </collision>
  </link>
  <joint
    name="joint_rwz"
    type="continuous">
    <origin
      xyz="-0.076 0 0.0991000000000001"
      rpy="0 0 -2.35619449019233" />
    <parent
      link="base_link" />
    <child
      link="rwz" />
    <axis
      xyz="0 0 1" />
    <dynamics damping="1.0" />
  </joint>
</robot>