<?xml version="1.0" encoding="utf-8"?>
<!-- This URDF was automatically created by SolidWorks to URDF Exporter! Originally created by Stephen Brawner (brawner@gmail.com)
     Commit Version: 1.5.1-0-g916b5db  Build Version: 1.5.7152.31018
     For more information, please see http://wiki.ros.org/sw_urdf_exporter -->
<robot
  name="rexhopper">


  <link
    name="base_link">
    <inertial>
      <origin
        xyz="-0.0040821970689855 0.000379301018317304 0.0170557032108192"
        rpy="0 0 0" />
      <mass
        value="5.59607837933863" />
      <inertia
        ixx="0.00377267223926865"
        ixy="-3.22269145542781E-06"
        ixz="5.32612485392243E-05"
        iyy="0.00604204097244965"
        iyz="8.35702196039236E-06"
        izz="0.00442179153407034" />
    </inertial>
    <visual>
      <origin
        xyz="0 0 0"
        rpy="0 0 0" />
      <geometry>
        <mesh
          filename="mesh/base_link.obj" />
      </geometry>
      <material
        name="">
        <color
          rgba="0.898039215686275 0.898039215686275 0.898039215686275 1" />
      </material>
    </visual>
    <collision>
      <origin
        xyz="0 0 0"
        rpy="0 0 0" />
      <geometry>
        <mesh
          filename="mesh/base_link.obj" />
      </geometry>
    </collision>
  </link>
  <link
    name="rw1">
    <inertial>
      <origin
        xyz="-0.0106867499464566 7.59774405195701E-09 -2.70422928234232E-09"
        rpy="0 0 0" />
      <mass
        value="0.715641175076257" />
      <inertia
        ixx="0.00312227321188979"
        ixy="1.82792669889409E-12"
        ixz="-1.21113744474242E-11"
        iyy="0.00158570696597532"
        iyz="7.43838570592397E-09"
        izz="0.00158570710797428" />
    </inertial>
    <visual>
      <origin
        xyz="0 0 0"
        rpy="0 0 0" />
      <geometry>
        <mesh
          filename="mesh/rw1.obj" />
      </geometry>
      <material
        name="">
        <color
          rgba="0.647058823529412 0.619607843137255 0.588235294117647 1" />
      </material>
    </visual>
    <collision>
      <origin
        xyz="0 0 0"
        rpy="0 0 0" />
      <geometry>
        <mesh
          filename="mesh/rw1.obj" />
      </geometry>
    </collision>
  </link>
  <joint
    name="joint_rw1"
    type="continuous">
    <origin
      xyz="0.063525686232125 0.148766097461586 0"
      rpy="-0.0304329711040608 0 0.785398163397453" />
    <parent
      link="base_link" />
    <child
      link="rw1" />
    <axis
      xyz="-1 0 0" />
    <dynamics damping="1.0" />
  </joint>
</robot>
