<?xml version="1.0" encoding="utf-8"?>
<!-- This URDF was automatically created by SolidWorks to URDF Exporter! Originally created by Stephen Brawner (brawner@gmail.com)
     Commit Version: 1.5.1-0-g916b5db  Build Version: 1.5.7152.31018
     For more information, please see http://wiki.ros.org/sw_urdf_exporter -->
<robot
  name="rexhopper">

  <loop_joint name="loop_joint" type="continuous">
    <axis xyz="0 -1 0"/>
		<!-- x=[xyz] & q=[rpy] describe tranformation from the parent frame to joint frame  -->
		<!-- parent joint frame -> link1's frame -> joint frame -->
    <link1 link="link1" rpy="0 0 0" xyz="0.81 0 0"/>
		<!-- x=[xyz] & q=[rpy] describe tranformation from the parent frame to joint frame  -->
		<!-- parent joint frame -> link2's frame -> joint frame -->
    <link2 link="link3" rpy="0 0 0" xyz="0.30 0 0"/>
    <dynamics damping="1.0" />
	</loop_joint>

  <link
    name="base_link">
    <inertial>
      <origin
        xyz="-0.0040821970689855 0.000379301018317304 0.0170557032108192"
        rpy="0 0 0" />
      <mass
        value="5.59607837933863" />
      <inertia
        ixx="0.00377267223926865"
        ixy="-3.22269145542781E-06"
        ixz="5.32612485392243E-05"
        iyy="0.00604204097244965"
        iyz="8.35702196039236E-06"
        izz="0.00442179153407034" />
    </inertial>
    <visual>
      <origin
        xyz="0 0 0"
        rpy="0 0 0" />
      <geometry>
        <mesh
          filename="mesh/base_link.obj" />
      </geometry>
      <material
        name="">
        <color
          rgba="0.898039215686275 0.898039215686275 0.898039215686275 1" />
      </material>
    </visual>
    <collision>
      <origin
        xyz="0 0 0"
        rpy="0 0 0" />
      <geometry>
        <mesh
          filename="mesh/base_link.obj" />
      </geometry>
    </collision>
  </link>
  <link
    name="link0">
    <inertial>
      <origin
        xyz="0.0121851264299085 0.0180889013941849 0.00112690392742547"
        rpy="0 0 0" />
      <mass
        value="0.256385566503952" />
      <inertia
        ixx="3.84650100874964E-05"
        ixy="1.5379784060096E-05"
        ixz="-8.48318798628566E-06"
        iyy="0.00017263374747093"
        iyz="1.08260201375488E-06"
        izz="0.000148822440720501" />
    </inertial>
    <visual>
      <origin
        xyz="0 0 0"
        rpy="0 0 0" />
      <geometry>
        <mesh
          filename="mesh/link0.obj" />
      </geometry>
      <material
        name="">
        <color
          rgba="0.898039215686275 0.898039215686275 0.898039215686275 1" />
      </material>
    </visual>
    <collision>
      <origin
        xyz="0 0 0"
        rpy="0 0 0" />
      <geometry>
        <mesh
          filename="mesh/link0.obj" />
      </geometry>
    </collision>
  </link>
  <joint
    name="Joint 0"
    type="revolute">
    <origin
      xyz="0 0 0"
      rpy="0 0.5235987755983 0" />
    <parent
      link="base_link" />
    <child
      link="link0" />
    <axis
      xyz="0 -1 0" />
    <limit
      lower="-3.14"
      upper="3.14"
      effort="0"
      velocity="0" />
    <dynamics damping="1.0" />
  </joint>
  <link
    name="link1">
    <inertial>
      <origin
        xyz="0.133101645966312 0.00652998365271682 -1.77401555945256E-09"
        rpy="0 0 0" />
      <mass
        value="0.0631473819780702" />
      <inertia
        ixx="25.5548531328563E-06"
        ixy="69.7718053328316E-12"
        ixz="-14.3600149958696E-12"
        iyy="00.00104301911822778"
        iyz="72.290806785004E-12"
        izz="00.00104301119173831" />
    </inertial>
    <visual>
      <origin
        xyz="0 0 0"
        rpy="0 0 0" />
      <geometry>
        <mesh
          filename="mesh/link1.obj" />
      </geometry>
      <material
        name="">
        <color
          rgba="0.776470588235294 0.756862745098039 0.737254901960784 1" />
      </material>
    </visual>
    <collision>
      <origin
        xyz="0 0 0"
        rpy="0 0 0" />
      <geometry>
        <mesh
          filename="mesh/link1.obj" />
      </geometry>
    </collision>
  </link>
  <joint
    name="joint1"
    type="revolute">
    <origin
      xyz="0.3 0 0"
      rpy="-3.14159265358979 1.0768315178335 -3.14159265358979" />
    <parent
      link="link0" />
    <child
      link="link1" />
    <axis
      xyz="0 -1 0" />
    <limit
      lower="-0.7597"
      upper="1.8295"
      effort="0"
      velocity="0" />
    <dynamics damping="1.0" />
  </joint>
  <link
    name="link2">
    <inertial>
      <origin
        xyz="0.1167096880913856 -0.0507940980758895 -0.0018814455598843293"
        rpy="0 0 0" />
      <mass
        value="02.88845046277886" />
      <inertia
        ixx="34.6488303623413E-05"
        ixy="-32.5958928897371E-07"
        ixz="52.4928685528962E-06"
        iyy="00.00245584747760095"
        iyz="30.1080375580465E-08"
        izz="00.00226676363063251" />
    </inertial>
    <visual>
      <origin
        xyz="0 0 0"
        rpy="0 0 0" />
      <geometry>
        <mesh
          filename="mesh/link2.obj" />
      </geometry>
      <material
        name="">
        <color
          rgba="0.898039215686275 0.898039215686275 0.898039215686275 1" />
      </material>
    </visual>
    <collision>
      <origin
        xyz="0 0 0"
        rpy="0 0 0" />
      <geometry>
        <mesh
          filename="mesh/link2.obj" />
      </geometry>
    </collision>
  </link>
  <joint
    name="joint2"
    type="revolute">
    <origin
      xyz="0 0 0"
      rpy="3.14159265358979 0.553232742319403 -3.14159265358979" />
    <parent
      link="base_link" />
    <child
      link="link2" />
    <axis
      xyz="0 -1 0" />
    <limit
      lower="-3.14"
      upper="3.14"
      effort="0"
      velocity="0" />
    <dynamics damping="1.0" />
  </joint>
  <link
    name="link3">
    <inertial>
      <origin
        xyz="0.30431451397071 -0.753003204323853 -0.445598580968067"
        rpy="0 0 0" />
      <mass
        value="01.2485760282637" />
      <inertia
        ixx="16.0742534228895E-05"
        ixy="-55.4606266030352E-07"
        ixz="10.0368247557172E-06"
        iyy="00.00116506434688955"
        iyz="10.713044107916E-07"
        izz="00.00112946754183162" />
    </inertial>
    <visual>
      <origin
        xyz="0 0 0"
        rpy="0 0 0" />
      <geometry>
        <mesh
          filename="mesh/link3.obj" />
      </geometry>
      <material
        name="">
        <color
          rgba="1 1 1 1" />
      </material>
    </visual>
    <collision>
      <origin
        xyz="0 0 0"
        rpy="0 0 0" />
      <geometry>
        <mesh
          filename="mesh/link3.obj" />
      </geometry>
    </collision>
  </link>
  <joint
    name="joint3"
    type="revolute">
    <origin
      xyz="0.810000000126657 0 0"
      rpy="-3.14159265358979 -1.07683151743819 3.14159265358979" />
    <parent
      link="link2" />
    <child
      link="link3" />
    <axis
      xyz="0 -1 0" />
    <limit
      lower="-1.8295"
      upper="0.7597"
      effort="0"
      velocity="0" />
    <dynamics damping="1.0" />
  </joint>
  <!-- <link
    name="rw0">
    <inertial>
      <origin
        xyz="-0.010686749946452 -7.59774469033525E-09 2.70423106737278E-09"
        rpy="0 0 0" />
      <mass
        value="0.715641175075329" />
      <inertia
        ixx="0.00312227321188978"
        ixy="-1.82792593995257E-12"
        ixz="1.21113744575886E-11"
        iyy="0.00158570696597519"
        iyz="7.43838571199042E-09"
        izz="0.00158570710797415" />
    </inertial>
    <visual>
      <origin
        xyz="0 0 0"
        rpy="0 0 0" />
      <geometry>
        <mesh
          filename="mesh/rw0.obj" />
      </geometry>
      <material
        name="">
        <color
          rgba="0.647058823529412 0.619607843137255 0.588235294117647 1" />
      </material>
    </visual>
    <collision>
      <origin
        xyz="0 0 0"
        rpy="0 0 0" />
      <geometry>
        <mesh
          filename="mesh/rw0.obj" />
      </geometry>
    </collision>
  </link>
  <joint
    name="joint_rw0"
    type="continuous">
    <origin
      xyz="0.0620132647100599 -0.147253675939521 0"
      rpy="3.03065856040946 0 -0.785398163397452" />
    <parent
      link="base_link" />
    <child
      link="rw0" />
    <axis
      xyz="1 0 0" />
  </joint>
  <link
    name="rw1">
    <inertial>
      <origin
        xyz="-0.0106867499464566 7.59774405195701E-09 -2.70422928234232E-09"
        rpy="0 0 0" />
      <mass
        value="0.715641175076257" />
      <inertia
        ixx="0.00312227321188979"
        ixy="1.82792669889409E-12"
        ixz="-1.21113744474242E-11"
        iyy="0.00158570696597532"
        iyz="7.43838570592397E-09"
        izz="0.00158570710797428" />
    </inertial>
    <visual>
      <origin
        xyz="0 0 0"
        rpy="0 0 0" />
      <geometry>
        <mesh
          filename="mesh/rw1.obj" />
      </geometry>
      <material
        name="">
        <color
          rgba="0.647058823529412 0.619607843137255 0.588235294117647 1" />
      </material>
    </visual>
    <collision>
      <origin
        xyz="0 0 0"
        rpy="0 0 0" />
      <geometry>
        <mesh
          filename="mesh/rw1.obj" />
      </geometry>
    </collision>
  </link>
  <joint
    name="joint_rw1"
    type="continuous">
    <origin
      xyz="0.063525686232125 0.148766097461586 0"
      rpy="-0.0304329711040608 0 0.785398163397453" />
    <parent
      link="base_link" />
    <child
      link="rw1" />
    <axis
      xyz="-1 0 0" />
  </joint>
  <link
    name="rwz">
    <inertial>
      <origin
        xyz="9.05342951995625E-09 -3.16383599874293E-10 -0.0146079871766005"
        rpy="0 0 0" />
      <mass
        value="0.377854494953541" />
      <inertia
        ixx="0.000300958121757203"
        ixy="-4.23471727248239E-12"
        ixz="-6.67153441322859E-12"
        iyy="0.000300957997312782"
        iyz="9.55842377314367E-14"
        izz="0.000578115934214613" />
    </inertial>
    <visual>
      <origin
        xyz="0 0 0"
        rpy="0 0 0" />
      <geometry>
        <mesh
          filename="mesh/rwz.obj" />
      </geometry>
      <material
        name="">
        <color
          rgba="0.647058823529412 0.619607843137255 0.588235294117647 1" />
      </material>
    </visual>
    <collision>
      <origin
        xyz="0 0 0"
        rpy="0 0 0" />
      <geometry>
        <mesh
          filename="mesh/rwz.obj" />
      </geometry>
    </collision>
  </link>
  <joint
    name="joint_rwz"
    type="continuous">
    <origin
      xyz="-0.076 0 0.0991000000000001"
      rpy="0 0 -2.35619449019233" />
    <parent
      link="base_link" />
    <child
      link="rwz" />
    <axis
      xyz="0 0 1" />
  </joint> -->
</robot>
