<?xml version="1.0"?>

<robot name="Fourbar">
	<link name="base_link">
	</link>

  <link name="link1">
    <inertial>
      <origin xyz="0 0 -0.5" rpy="0 0. 0." />
      <mass value="1" />
      <inertia ixx=".0841667" ixy="0" ixz="0" iyy=".0841667" iyz="0" izz=".00166667" />
    </inertial>
    <visual>
      <origin xyz="0 0 -0.5" rpy="0 0. 0." />
      <geometry>
         <!-- <cylinder length="1" radius=".05" /> -->
         <box size=".1 .1 1" />
      </geometry>
      <material name="black">
	       <color rgba="0 0 0 1" />
      </material>
    </visual>
  </link>

  <link name="link2">
    <inertial>
      <origin xyz="0 0 -0.5" rpy="0 0. 0." />
      <mass value="1" />
      <inertia ixx=".0841667" ixy="0" ixz="0" iyy=".0841667" iyz="0" izz=".00166667" />
    </inertial>
    <visual>
      <origin xyz="0 0 -0.5" rpy="0 0. 0." />
      <geometry>
         <box size=".1 .1 1" />
      </geometry>
      <material name="red">
	       <color rgba="1 0 0 1" />
      </material>
    </visual>
  </link>

  <link name="link3">
    <inertial>
      <origin xyz="0 0 -0.5" rpy="0 0. 0." />
      <mass value="1" />
      <inertia ixx=".0841667" ixy="0" ixz="0" iyy=".0841667" iyz="0" izz=".00166667" />
    </inertial>
    <visual>
      <origin xyz="0 0 -0.5" rpy="0 0. 0." />
      <geometry>
         <!-- <cylinder length="1" radius=".05" /> -->
         <box size=".1 .1 1" />
      </geometry>
      <material name="green">
	       <color rgba="0 1 0 1" />
      </material>
    </visual>
  </link>

  <link name="link4">
    <inertial>
      <origin xyz="0 0 -0.5" rpy="0 0. 0." />
      <mass value="1" />
      <inertia ixx=".0841667" ixy="0" ixz="0" iyy=".0841667" iyz="0" izz=".00166667" />
    </inertial>
    <visual>
      <origin xyz="0 0 -0.5" rpy="0 0. 0." />
      <geometry>
         <box size=".1 .1 1" />
      </geometry>
      <material name="blue">
	       <color rgba="0 0 1 1" />
      </material>
    </visual>
  </link>



	<joint name="jointb1" type="continuous">
		<parent link="base_link" />
		<child link="link1" />
		<origin rpy="0.0 0 0" xyz="0 0 0" />
		<axis xyz="1 0 0" />
	</joint>

  <joint name="joint12" type="continuous">
		<parent link="link1" />
		<child link="link2" />
		<origin rpy="0.0 0 0" xyz="0 0 -1" />
		<axis xyz="1 0 0" />
	</joint>

  <joint name="jointb3" type="continuous">
		<parent link="base_link" />
		<child link="link3" />
		<origin rpy="-0.0 0 0" xyz="0 0 0" />
		<axis xyz="1 0 0" />
	</joint>

  <joint name="joint34" type="continuous">
		<parent link="link3" />
		<child link="link4" />
		<origin rpy="-0.0 0 0" xyz="0 0 -1" />
		<axis xyz="1 0 0" />
	</joint>

	<loop_joint name="joint24" type="continuous">
    <axis xyz="1 0 0"/>
		<!-- x=[xyz] & q=[rpy] describe tranformation from the parent frame to joint frame  -->
		<!-- parent joint frame -> link1's frame -> joint frame -->
    <link1 link="link2" rpy="0 0 0" xyz="0 0 -1.0"/>
		<!-- x=[xyz] & q=[rpy] describe tranformation from the parent frame to joint frame  -->
		<!-- parent joint frame -> link2's frame -> joint frame -->
    <link2 link="link4" rpy="0 0 0" xyz="0 0 -1.0"/>
	</loop_joint>
</robot>
